Workbook

Sheet Как пользоваться
A1: Как пользоваться
A2: Наименование, количество, стоимость. Дальше либо срок службы в годах, либо сколько раз в месяц.
A4: Что | B4: Зачем
A5: Покупка | B5: Срок службы (лет). В год = стоимость × количество ÷ срок ÷ делим.
A6: Продукты и секции | B6: Период: неделя / месяц / год. В год = стоимость × количество × 52 / 12 / 1.
A7: Делим = 1 | B7: Целиком на этого ребёнка.
A8: Делим = 3 | B8: Общее на семью.
A9: Строки | B9: Внутри блока по алфавиту.

Sheet Сводка
A1: Сводка — один ребёнок
A4: Блок | B4: В год, ₽ | C4: В месяц, ₽
A5: Аксессуары покупки | B5: ='Аксессуары покупки'!H21 | C5: ='Аксессуары покупки'!I21
A6: Бельё покупки | B6: ='Бельё покупки'!H11 | C6: ='Бельё покупки'!I11
A7: Верхняя одежда покупки | B7: ='Верхняя одежда покупки'!H11 | C7: ='Верхняя одежда покупки'!I11
A8: Комната покупки | B8: ='Комната покупки'!H25 | C8: ='Комната покупки'!I25
A9: Оборудование покупки | B9: ='Оборудование покупки'!H15 | C9: ='Оборудование покупки'!I15
A10: Обувь покупки | B10: ='Обувь покупки'!H14 | C10: ='Обувь покупки'!I14
A11: Одежда второго слоя покупки | B11: ='Одежда второго слоя покупки'!H19 | C11: ='Одежда второго слоя покупки'!I19
A12: Предметы личного пользования по | B12: ='Предметы личного пользования по'!H22 | C12: ='Предметы личного пользования по'!I22
A13: Продукты питания покупки | B13: ='Продукты питания покупки'!H7 | C13: ='Продукты питания покупки'!I7
A14: Спорт и досуг покупки | B14: ='Спорт и досуг покупки'!H22 | C14: ='Спорт и досуг покупки'!I22
A15: Школьные принадлежности покупки | B15: ='Школьные принадлежности покупки'!H37 | C15: ='Школьные принадлежности покупки'!I37
A16: Лекарства | B16: ='Лекарства'!H14 | C16: ='Лекарства'!I14
A17: Медицинские услуги | B17: ='Медицинские услуги'!H7 | C17: ='Медицинские услуги'!I7
A18: Карманные расходы | B18: ='Карманные расходы'!G7 | C18: ='Карманные расходы'!H7
A19: Оборудование расходы | B19: ='Оборудование расходы'!G7 | C19: ='Оборудование расходы'!H7
A20: Образование расходы | B20: ='Образование расходы'!G10 | C20: ='Образование расходы'!H10
A21: Праздники расходы | B21: ='Праздники расходы'!G14 | C21: ='Праздники расходы'!H14
A22: Хобби и развлечения расходы | B22: ='Хобби и развлечения расходы'!G12 | C22: ='Хобби и развлечения расходы'!H12
A23: Бытовая косметика покупки | B23: ='Бытовая косметика покупки'!H12 | C23: ='Бытовая косметика покупки'!I12
A24: Бытовая посуда покупки | B24: ='Бытовая посуда покупки'!H23 | C24: ='Бытовая посуда покупки'!I23
A25: Бытовая техника покупки | B25: ='Бытовая техника покупки'!H20 | C25: ='Бытовая техника покупки'!I20
A26: Мебель и хозяйство покупки | B26: ='Мебель и хозяйство покупки'!H18 | C26: ='Мебель и хозяйство покупки'!I18
A27: Праздники покупки | B27: ='Праздники покупки'!H9 | C27: ='Праздники покупки'!I9
A28: Аренда и коммунальные платежи р | B28: ='Аренда и коммунальные платежи р'!F11 | C28: ='Аренда и коммунальные платежи р'!G11
A29: Хобби и развлечения расходы 2 | B29: ='Хобби и развлечения расходы 2'!G9 | C29: ='Хобби и развлечения расходы 2'!H9
A30: Транспорт расходы | B30: ='Транспорт расходы'!F15 | C30: ='Транспорт расходы'!G15
A31: СОДЕРЖАНИЕ РЕБЁНКА | B31: =SUM(B5:B30) | C31: =SUM(C5:C30)

Sheet Группы диаграммы
A1: Группы диаграммы
A2: Расход на диаграмме и блоки, которые в него входят.
A4: Расход | B4: Состав блоков
A5: Одежда, обувь и аксессуары | B5: Бельё; Одежда второго слоя; Верхняя одежда; Обувь; Аксессуары
A6: Комната и оборудование | B6: Комната; Оборудование
A7: Предметы личного пользования | B7: Предметы личного пользования
A8: Продукты питания | B8: Продукты питания
A9: Спорт и досуг | B9: Спорт и досуг
A10: Школьные принадлежности | B10: Школьные принадлежности
A11: Лекарства | B11: Лекарства
A12: Медицинские услуги | B12: Медицинские услуги
A13: Карманные | B13: Карманные
A14: Оборудование | B14: Оборудование
A15: Образование | B15: Образование
... A25: Транспорт | B25: Транспорт

Sheet В школу
A1: В школу
A2: Все строки с назначением «в школу». Кружки и секции сюда не входят.
A4: № | B4: Блок | C4: Наименование | D4: Количество | E4: Стоимость | F4: Срок службы (лет) | G4: В год, ₽ | H4: В месяц, ₽
A5: 1 | B5: Аксессуары | C5: Галстук | D5: 1 | E5: 299 | F5: 2 | G5: =IF(ISNUMBER(F5),IF(F5=0,0,E5*IF(D5=0,1,D5)/F5),IF(F5="неделя",E5*IF(D5=0,1,D5)*52,IF(F5="месяц",E5*IF(D5=0,1,D5)*12,E5*IF(D5=0,1,D5)))) | H5: =IF(G5=0,0,G5/12)
A6: 2 | B6: Аксессуары | C6: Ремень | D6: 1 | E6: 399 | F6: 2 | G6: =IF(ISNUMBER(F6),IF(F6=0,0,E6*IF(D6=0,1,D6)/F6),IF(F6="неделя",E6*IF(D6=0,1,D6)*52,IF(F6="месяц",E6*IF(D6=0,1,D6)*12,E6*IF(D6=0,1,D6)))) | H6: =IF(G6=0,0,G6/12)
A7: 3 | B7: Аксессуары | C7: Рюкзак школьный | D7: 1 | E7: 3499 | F7: 3 | G7: =IF(ISNUMBER(F7),IF(F7=0,0,E7*IF(D7=0,1,D7)/F7),IF(F7="неделя",E7*IF(D7=0,1,D7)*52,IF(F7="месяц",E7*IF(D7=0,1,D7)*12,E7*IF(D7=0,1,D7)))) | H7: =IF(G7=0,0,G7/12)
A8: 4 | B8: Аксессуары | C8: Сумка для обуви | D8: 1 | E8: 269 | F8: 2 | G8: =IF(ISNUMBER(F8),IF(F8=0,0,E8*IF(D8=0,1,D8)/F8),IF(F8="неделя",E8*IF(D8=0,1,D8)*52,IF(F8="месяц",E8*IF(D8=0,1,D8)*12,E8*IF(D8=0,1,D8)))) | H8: =IF(G8=0,0,G8/12)
A9: 5 | B9: Аксессуары | C9: Сумка для формы | D9: 1 | E9: 319 | F9: 2 | G9: =IF(ISNUMBER(F9),IF(F9=0,0,E9*IF(D9=0,1,D9)/F9),IF(F9="неделя",E9*IF(D9=0,1,D9)*52,IF(F9="месяц",E9*IF(D9=0,1,D9)*12,E9*IF(D9=0,1,D9)))) | H9: =IF(G9=0,0,G9/12)
A10: 6 | B10: Обувь | C10: Сменная обувь | D10: 1 | E10: 1800 | F10: 1 | G10: =IF(ISNUMBER(F10),IF(F10=0,0,E10*IF(D10=0,1,D10)/F10),IF(F10="неделя",E10*IF(D10=0,1,D10)*52,IF(F10="месяц",E10*IF(D10=0,1,D10)*12,E10*IF(D10=0,1,D10)))) | H10: =IF(G10=0,0,G10/12)
A11: 7 | B11: Одежда второго слоя | C11: Брюки школьные | D11: 2 | E11: 2000 | F11: 2 | G11: =IF(ISNUMBER(F11),IF(F11=0,0,E11*IF(D11=0,1,D11)/F11),IF(F11="неделя",E11*IF(D11=0,1,D11)*52,IF(F11="месяц",E11*IF(D11=0,1,D11)*12,E11*IF(D11=0,1,D11)))) | H11: =IF(G11=0,0,G11/12)
A12: 8 | B12: Одежда второго слоя | C12: Джемпер школьный | D12: 1 | E12: 1399 | F12: 2 | G12: =IF(ISNUMBER(F12),IF(F12=0,0,E12*IF(D12=0,1,D12)/F12),IF(F12="неделя",E12*IF(D12=0,1,D12)*52,IF(F12="месяц",E12*IF(D12=0,1,D12)*12,E12*IF(D12=0,1,D12)))) | H12: =IF(G12=0,0,G12/12)
A13: 9 | B13: Одежда второго слоя | C13: Жилет школьный | D13: 1 | E13: 999 | F13: 2 | G13: =IF(ISNUMBER(F13),IF(F13=0,0,E13*IF(D13=0,1,D13)/F13),IF(F13="неделя",E13*IF(D13=0,1,D13)*52,IF(F13="месяц",E13*IF(D13=0,1,D13)*12,E13*IF(D13=0,1,D13)))) | H13: =IF(G13=0,0,G13/12)
A14: 10 | B14: Одежда второго слоя | C14: Рубашка школьная | D14: 2 | E14: 2000 | F14: 1 | G14: =IF(ISNUMBER(F14),IF(F14=0,0,E14*IF(D14=0,1,D14)/F14),IF(F14="неделя",E14*IF(D14=0,1,D14)*52,IF(F14="месяц",E14*IF(D14=0,1,D14)*12,E14*IF(D14=0,1,D14)))) | H14: =IF(G14=0,0,G14/12)
A15: 11 | B15: Спорт и досуг | C15: Спортивная форма школьная | D15: 1 | E15: 1999 | F15: 2 | G15: =IF(ISNUMBER(F15),IF(F15=0,0,E15*IF(D15=0,1,D15)/F15),IF(F15="неделя",E15*IF(D15=0,1,D15)*52,IF(F15="месяц",E15*IF(D15=0,1,D15)*12,E15*IF(D15=0,1,D15)))) | H15: =IF(G15=0,0,G15/12)
A16: 12 | B16: Школьные принадлежности | C16: Альбом для рисования | D16: 1 | E16: 89 | F16: 1 | G16: =IF(ISNUMBER(F16),IF(F16=0,0,E16*IF(D16=0,1,D16)/F16),IF(F16="неделя",E16*IF(D16=0,1,D16)*52,IF(F16="месяц",E16*IF(D16=0,1,D16)*12,E16*IF(D16=0,1,D16)))) | H16: =IF(G16=0,0,G16/12)
... A46: 42 | B46: Школьные принадлежности | C46: Цветная бумага | D46: 1 | E46: 69 | F46: 1 | G46: =IF(ISNUMBER(F46),IF(F46=0,0,E46*IF(D46=0,1,D46)/F46),IF(F46="неделя",E46*IF(D46=0,1,D46)*52,IF(F46="месяц",E46*IF(D46=0,1,D46)*12,E46*IF(D46=0,1,D46)))) | H46: =IF(G46=0,0,G46/12)
A48: Итого: в школу | G48: =G5+G6+G7+G8+G9+G10+G11+G12+G13+G14+G15+G16+G17+G18+G19+G20+G21+G22+G23+G24+G25+G26+G27+G28+G29+G30+G31+G32+G33+G34+G35+G36+G37+G38+G39+G40+G41+G42+G43+G44+G45+G46 | H48: =IF(G48=0,0,G48/12)

Sheet Аксессуары покупки
A1: Аксессуары
A2: Покупки — ссылка на товар и срок службы. Частое — период. Платежи — без ссылки.
A4: № | B4: Наименование | C4: Назначение | D4: Количество | E4: Ссылка | F4: Стоимость | G4: Срок службы (лет) | H4: В год, ₽ | I4: В месяц, ₽
A5: 1 | B5: Бейсболка | C5: — | D5: 2 | E5: https://www.detmir.ru/search/results/?qt=%D0%B1%D0%B5%D0%B9%D1%81%D0%B1%D0%BE%D0%BB%D0%BA%D0%B0 | F5: 399 | G5: 2 | H5: =IF(ISNUMBER(G5),IF(G5=0,0,F5*IF(D5=0,1,D5)/G5),IF(G5="неделя",F5*IF(D5=0,1,D5)*52,IF(G5="месяц",F5*IF(D5=0,1,D5)*12,F5*IF(D5=0,1,D5)))) | I5: =IF(H5=0,0,H5/12)
A6: 2 | B6: Галстук | C6: в школу | D6: 1 | E6: https://www.detmir.ru/catalog/index/name/neckties/ | F6: 299 | G6: 2 | H6: =IF(ISNUMBER(G6),IF(G6=0,0,F6*IF(D6=0,1,D6)/G6),IF(G6="неделя",F6*IF(D6=0,1,D6)*52,IF(G6="месяц",F6*IF(D6=0,1,D6)*12,F6*IF(D6=0,1,D6)))) | I6: =IF(H6=0,0,H6/12)
A7: 3 | B7: Зонт или дождевик | C7: — | D7: 1 | E7: https://www.detmir.ru/search/results/?qt=%D0%B4%D0%BE%D0%B6%D0%B4%D0%B5%D0%B2%D0%B8%D0%BA%20%D0%B4%D0%B5%D1%82%D1%81%D0%BA%D0%B8%D0%B9 | F7: 699 | G7: 2 | H7: =IF(ISNUMBER(G7),IF(G7=0,0,F7*IF(D7=0,1,D7)/G7),IF(G7="неделя",F7*IF(D7=0,1,D7)*52,IF(G7="месяц",F7*IF(D7=0,1,D7)*12,F7*IF(D7=0,1,D7)))) | I7: =IF(H7=0,0,H7/12)
A8: 4 | B8: Перчатки зимние | C8: — | D8: 1 | E8: https://www.detmir.ru/search/results/?qt=%D0%BF%D0%B5%D1%80%D1%87%D0%B0%D1%82%D0%BA%D0%B8%20%D0%B7%D0%B8%D0%BC%D0%BD%D0%B8%D0%B5 | F8: 599 | G8: 2 | H8: =IF(ISNUMBER(G8),IF(G8=0,0,F8*IF(D8=0,1,D8)/G8),IF(G8="неделя",F8*IF(D8=0,1,D8)*52,IF(G8="месяц",F8*IF(D8=0,1,D8)*12,F8*IF(D8=0,1,D8)))) | I8: =IF(H8=0,0,H8/12)
A9: 5 | B9: Перчатки осенние | C9: — | D9: 1 | E9: https://www.detmir.ru/search/results/?qt=%D0%BF%D0%B5%D1%80%D1%87%D0%B0%D1%82%D0%BA%D0%B8 | F9: 399 | G9: 2 | H9: =IF(ISNUMBER(G9),IF(G9=0,0,F9*IF(D9=0,1,D9)/G9),IF(G9="неделя",F9*IF(D9=0,1,D9)*52,IF(G9="месяц",F9*IF(D9=0,1,D9)*12,F9*IF(D9=0,1,D9)))) | I9: =IF(H9=0,0,H9/12)
A10: 6 | B10: Ремень | C10: в школу | D10: 1 | E10: https://www.detmir.ru/catalog/index/name/straps/pol-malchik/ | F10: 399 | G10: 2 | H10: =IF(ISNUMBER(G10),IF(G10=0,0,F10*IF(D10=0,1,D10)/G10),IF(G10="неделя",F10*IF(D10=0,1,D10)*52,IF(G10="месяц",F10*IF(D10=0,1,D10)*12,F10*IF(D10=0,1,D10)))) | I10: =IF(H10=0,0,H10/12)
A11: 7 | B11: Рюкзак школьный | C11: в школу | D11: 1 | E11: https://www.detmir.ru/product/index/id/6391235/ | F11: 3499 | G11: 3 | H11: =IF(ISNUMBER(G11),IF(G11=0,0,F11*IF(D11=0,1,D11)/G11),IF(G11="неделя",F11*IF(D11=0,1,D11)*52,IF(G11="месяц",F11*IF(D11=0,1,D11)*12,F11*IF(D11=0,1,D11)))) | I11: =IF(H11=0,0,H11/12)
A12: 8 | B12: Солнечные очки | C12: — | D12: 1 | E12: https://www.detmir.ru/search/results/?qt=PlayToday%20%D0%BE%D1%87%D0%BA%D0%B8 | F12: 799 | G12: 2 | H12: =IF(ISNUMBER(G12),IF(G12=0,0,F12*IF(D12=0,1,D12)/G12),IF(G12="неделя",F12*IF(D12=0,1,D12)*52,IF(G12="месяц",F12*IF(D12=0,1,D12)*12,F12*IF(D12=0,1,D12)))) | I12: =IF(H12=0,0,H12/12)
A13: 9 | B13: Сумка для коньков | C13: — | D13: 1 | E13: https://www.detmir.ru/search/results/?qt=%D1%81%D1%83%D0%BC%D0%BA%D0%B0%20%D0%B4%D0%BB%D1%8F%20%D0%BA%D0%BE%D0%BD%D1%8C%D0%BA%D0%BE%D0%B2 | F13: 1100 | G13: 3 | H13: =IF(ISNUMBER(G13),IF(G13=0,0,F13*IF(D13=0,1,D13)/G13),IF(G13="неделя",F13*IF(D13=0,1,D13)*52,IF(G13="месяц",F13*IF(D13=0,1,D13)*12,F13*IF(D13=0,1,D13)))) | I13: =IF(H13=0,0,H13/12)
A14: 10 | B14: Сумка для обуви | C14: в школу | D14: 1 | E14: https://www.detmir.ru/product/index/id/6622893/ | F14: 269 | G14: 2 | H14: =IF(ISNUMBER(G14),IF(G14=0,0,F14*IF(D14=0,1,D14)/G14),IF(G14="неделя",F14*IF(D14=0,1,D14)*52,IF(G14="месяц",F14*IF(D14=0,1,D14)*12,F14*IF(D14=0,1,D14)))) | I14: =IF(H14=0,0,H14/12)
A15: 11 | B15: Сумка для самбо | C15: — | D15: 1 | E15: https://www.detmir.ru/search/results/?qt=%D1%81%D0%BF%D0%BE%D1%80%D1%82%D0%B8%D0%B2%D0%BD%D0%B0%D1%8F%20%D1%81%D1%83%D0%BC%D0%BA%D0%B0 | F15: 1499 | G15: 3 | H15: =IF(ISNUMBER(G15),IF(G15=0,0,F15*IF(D15=0,1,D15)/G15),IF(G15="неделя",F15*IF(D15=0,1,D15)*52,IF(G15="месяц",F15*IF(D15=0,1,D15)*12,F15*IF(D15=0,1,D15)))) | I15: =IF(H15=0,0,H15/12)
A16: 12 | B16: Сумка для формы | C16: в школу | D16: 1 | E16: https://www.detmir.ru/product/index/id/6037286/ | F16: 319 | G16: 2 | H16: =IF(ISNUMBER(G16),IF(G16=0,0,F16*IF(D16=0,1,D16)/G16),IF(G16="неделя",F16*IF(D16=0,1,D16)*52,IF(G16="месяц",F16*IF(D16=0,1,D16)*12,F16*IF(D16=0,1,D16)))) | I16: =IF(H16=0,0,H16/12)
... A19: 15 | B19: Шарф | C19: — | D19: 1 | E19: https://www.detmir.ru/search/results/?qt=%D1%88%D0%B0%D1%80%D1%84 | F19: 399 | G19: 2 | H19: =IF(ISNUMBER(G19),IF(G19=0,0,F19*IF(D19=0,1,D19)/G19),IF(G19="неделя",F19*IF(D19=0,1,D19)*52,IF(G19="месяц",F19*IF(D19=0,1,D19)*12,F19*IF(D19=0,1,D19)))) | I19: =IF(H19=0,0,H19/12)
A21: Итого: Аксессуары | H21: =H5+H6+H7+H8+H9+H10+H11+H12+H13+H14+H15+H16+H17+H18+H19 | I21: =IF(H21=0,0,H21/12)

Sheet Бельё покупки
A1: Бельё
A2: Покупки — ссылка на товар и срок службы. Частое — период. Платежи — без ссылки.
A4: № | B4: Наименование | C4: Назначение | D4: Количество | E4: Ссылка | F4: Стоимость | G4: Срок службы (лет) | H4: В год, ₽ | I4: В месяц, ₽
A5: 1 | B5: Майка | C5: — | D5: 5 | E5: https://www.detmir.ru/product/index/id/6733145/ | F5: 399 | G5: 1 | H5: =IF(ISNUMBER(G5),IF(G5=0,0,F5*IF(D5=0,1,D5)/G5),IF(G5="неделя",F5*IF(D5=0,1,D5)*52,IF(G5="месяц",F5*IF(D5=0,1,D5)*12,F5*IF(D5=0,1,D5)))) | I5: =IF(H5=0,0,H5/12)
A6: 2 | B6: Носки обычные, набор 5 пар | C6: — | D6: 1 | E6: https://www.detmir.ru/product/index/id/6550049/ | F6: 399 | G6: 1 | H6: =IF(ISNUMBER(G6),IF(G6=0,0,F6*IF(D6=0,1,D6)/G6),IF(G6="неделя",F6*IF(D6=0,1,D6)*52,IF(G6="месяц",F6*IF(D6=0,1,D6)*12,F6*IF(D6=0,1,D6)))) | I6: =IF(H6=0,0,H6/12)
A7: 3 | B7: Носки утеплённые | C7: — | D7: 2 | E7: https://www.detmir.ru/search/results/?qt=%D0%BD%D0%BE%D1%81%D0%BA%D0%B8%20%D0%B7%D0%B8%D0%BC%D0%BD%D0%B8%D0%B5%20%D0%B4%D0%B5%D1%82%D1%81%D0%BA%D0%B8%D0%B5 | F7: 399 | G7: 1 | H7: =IF(ISNUMBER(G7),IF(G7=0,0,F7*IF(D7=0,1,D7)/G7),IF(G7="неделя",F7*IF(D7=0,1,D7)*52,IF(G7="месяц",F7*IF(D7=0,1,D7)*12,F7*IF(D7=0,1,D7)))) | I7: =IF(H7=0,0,H7/12)
A8: 4 | B8: Термобельё, комплект | C8: — | D8: 1 | E8: https://www.detmir.ru/search/results/?qt=%D1%82%D0%B5%D1%80%D0%BC%D0%BE%D0%B1%D0%B5%D0%BB%D1%8C%D0%B5 | F8: 1499 | G8: 1 | H8: =IF(ISNUMBER(G8),IF(G8=0,0,F8*IF(D8=0,1,D8)/G8),IF(G8="неделя",F8*IF(D8=0,1,D8)*52,IF(G8="месяц",F8*IF(D8=0,1,D8)*12,F8*IF(D8=0,1,D8)))) | I8: =IF(H8=0,0,H8/12)
A9: 5 | B9: Трусы, набор 5 шт. | C9: — | D9: 1 | E9: https://www.detmir.ru/product/index/id/7072737/ | F9: 799 | G9: 1 | H9: =IF(ISNUMBER(G9),IF(G9=0,0,F9*IF(D9=0,1,D9)/G9),IF(G9="неделя",F9*IF(D9=0,1,D9)*52,IF(G9="месяц",F9*IF(D9=0,1,D9)*12,F9*IF(D9=0,1,D9)))) | I9: =IF(H9=0,0,H9/12)
A11: Итого: Бельё | H11: =H5+H6+H7+H8+H9 | I11: =IF(H11=0,0,H11/12)

Sheet Верхняя одежда покупки
A1: Верхняя одежда
A2: Покупки — ссылка на товар и срок службы. Частое — период. Платежи — без ссылки.
A4: № | B4: Наименование | C4: Назначение | D4: Количество | E4: Ссылка | F4: Стоимость | G4: Срок службы (лет) | H4: В год, ₽ | I4: В месяц, ₽
A5: 1 | B5: Ветровка | C5: — | D5: 1 | E5: https://www.detmir.ru/product/index/id/6022408/ | F5: 1299 | G5: 2 | H5: =IF(ISNUMBER(G5),IF(G5=0,0,F5*IF(D5=0,1,D5)/G5),IF(G5="неделя",F5*IF(D5=0,1,D5)*52,IF(G5="месяц",F5*IF(D5=0,1,D5)*12,F5*IF(D5=0,1,D5)))) | I5: =IF(H5=0,0,H5/12)
A6: 2 | B6: Куртка зимняя | C6: — | D6: 2 | E6: https://www.detmir.ru/product/index/id/7061634/ | F6: 4292 | G6: 2 | H6: =IF(ISNUMBER(G6),IF(G6=0,0,F6*IF(D6=0,1,D6)/G6),IF(G6="неделя",F6*IF(D6=0,1,D6)*52,IF(G6="месяц",F6*IF(D6=0,1,D6)*12,F6*IF(D6=0,1,D6)))) | I6: =IF(H6=0,0,H6/12)
A7: 3 | B7: Куртка осенняя | C7: — | D7: 1 | E7: https://www.wildberries.ru/brands/orby | F7: 2199 | G7: 2 | H7: =IF(ISNUMBER(G7),IF(G7=0,0,F7*IF(D7=0,1,D7)/G7),IF(G7="неделя",F7*IF(D7=0,1,D7)*52,IF(G7="месяц",F7*IF(D7=0,1,D7)*12,F7*IF(D7=0,1,D7)))) | I7: =IF(H7=0,0,H7/12)
A8: 4 | B8: Куртка осенняя утеплённая | C8: — | D8: 1 | E8: https://www.detmir.ru/search/results/?qt=%D0%BA%D1%83%D1%80%D1%82%D0%BA%D0%B0%20%D0%BE%D1%81%D0%B5%D0%BD%D0%BD%D1%8F%D1%8F%20%D1%83%D1%82%D0%B5%D0%BF%D0%BB%D0%B5%D0%BD%D0%BD%D0%B0%D1%8F%20%D0%BC%D0%B0%D0%BB%D1%8C%D1%87%D0%B8%D0%BA | F8: 2999 | G8: 2 | H8: =IF(ISNUMBER(G8),IF(G8=0,0,F8*IF(D8=0,1,D8)/G8),IF(G8="неделя",F8*IF(D8=0,1,D8)*52,IF(G8="месяц",F8*IF(D8=0,1,D8)*12,F8*IF(D8=0,1,D8)))) | I8: =IF(H8=0,0,H8/12)
A9: 5 | B9: Штаны утеплённые | C9: — | D9: 1 | E9: https://www.detmir.ru/search/results/?qt=%D1%88%D1%82%D0%B0%D0%BD%D1%8B%20%D1%83%D1%82%D0%B5%D0%BF%D0%BB%D0%B5%D0%BD%D0%BD%D1%8B%D0%B5 | F9: 2499 | G9: 2 | H9: =IF(ISNUMBER(G9),IF(G9=0,0,F9*IF(D9=0,1,D9)/G9),IF(G9="неделя",F9*IF(D9=0,1,D9)*52,IF(G9="месяц",F9*IF(D9=0,1,D9)*12,F9*IF(D9=0,1,D9)))) | I9: =IF(H9=0,0,H9/12)
A11: Итого: Верхняя одежда | H11: =H5+H6+H7+H8+H9 | I11: =IF(H11=0,0,H11/12)

Sheet Комната покупки
A1: Комната
A2: Покупки — ссылка на товар и срок службы. Частое — период. Платежи — без ссылки.
A4: № | B4: Наименование | C4: Назначение | D4: Количество | E4: Ссылка | F4: Стоимость | G4: Срок службы (лет) | H4: В год, ₽ | I4: В месяц, ₽
A5: 1 | B5: Вуаль / тюль | C5: — | D5: 1 | E5: https://leroymerlin.ru/catalogue/tyul/ | F5: 1200 | G5: 5 | H5: =IF(ISNUMBER(G5),IF(G5=0,0,F5*IF(D5=0,1,D5)/G5),IF(G5="неделя",F5*IF(D5=0,1,D5)*52,IF(G5="месяц",F5*IF(D5=0,1,D5)*12,F5*IF(D5=0,1,D5)))) | I5: =IF(H5=0,0,H5/12)
A6: 2 | B6: Ковёр на пол | C6: — | D6: 1 | E6: https://leroymerlin.ru/catalogue/kovry/ | F6: 4000 | G6: 5 | H6: =IF(ISNUMBER(G6),IF(G6=0,0,F6*IF(D6=0,1,D6)/G6),IF(G6="неделя",F6*IF(D6=0,1,D6)*52,IF(G6="месяц",F6*IF(D6=0,1,D6)*12,F6*IF(D6=0,1,D6)))) | I6: =IF(H6=0,0,H6/12)
A7: 3 | B7: Контейнер для игрушек | C7: — | D7: 1 | E7: https://www.detmir.ru/search/results/?qt=%D0%BA%D0%BE%D0%BD%D1%82%D0%B5%D0%B9%D0%BD%D0%B5%D1%80%20%D0%B4%D0%BB%D1%8F%20%D0%B8%D0%B3%D1%80%D1%83%D1%88%D0%B5%D0%BA | F7: 2500 | G7: 3 | H7: =IF(ISNUMBER(G7),IF(G7=0,0,F7*IF(D7=0,1,D7)/G7),IF(G7="неделя",F7*IF(D7=0,1,D7)*52,IF(G7="месяц",F7*IF(D7=0,1,D7)*12,F7*IF(D7=0,1,D7)))) | I7: =IF(H7=0,0,H7/12)
A8: 4 | B8: Кресло компьютерное | C8: — | D8: 1 | E8: https://www.detmir.ru/search/results/?qt=%D0%BA%D1%80%D0%B5%D1%81%D0%BB%D0%BE | F8: 4499 | G8: 5 | H8: =IF(ISNUMBER(G8),IF(G8=0,0,F8*IF(D8=0,1,D8)/G8),IF(G8="неделя",F8*IF(D8=0,1,D8)*52,IF(G8="месяц",F8*IF(D8=0,1,D8)*12,F8*IF(D8=0,1,D8)))) | I8: =IF(H8=0,0,H8/12)
A9: 5 | B9: Кресло-мешок | C9: — | D9: 1 | E9: https://www.detmir.ru/search/results/?qt=%D0%BA%D1%80%D0%B5%D1%81%D0%BB%D0%BE-%D0%BC%D0%B5%D1%88%D0%BE%D0%BA | F9: 5500 | G9: 3 | H9: =IF(ISNUMBER(G9),IF(G9=0,0,F9*IF(D9=0,1,D9)/G9),IF(G9="неделя",F9*IF(D9=0,1,D9)*52,IF(G9="месяц",F9*IF(D9=0,1,D9)*12,F9*IF(D9=0,1,D9)))) | I9: =IF(H9=0,0,H9/12)
A10: 6 | B10: Кровать-машинка | C10: — | D10: 1 | E10: https://www.avito.ru/ | F10: 30000 | G10: 3 | H10: =IF(ISNUMBER(G10),IF(G10=0,0,F10*IF(D10=0,1,D10)/G10),IF(G10="неделя",F10*IF(D10=0,1,D10)*52,IF(G10="месяц",F10*IF(D10=0,1,D10)*12,F10*IF(D10=0,1,D10)))) | I10: =IF(H10=0,0,H10/12)
A11: 7 | B11: Матрас 80×180 | C11: — | D11: 1 | E11: https://ormatek.com/catalog/matrasy/80x180/ | F11: 8000 | G11: 8 | H11: =IF(ISNUMBER(G11),IF(G11=0,0,F11*IF(D11=0,1,D11)/G11),IF(G11="неделя",F11*IF(D11=0,1,D11)*52,IF(G11="месяц",F11*IF(D11=0,1,D11)*12,F11*IF(D11=0,1,D11)))) | I11: =IF(H11=0,0,H11/12)
A12: 8 | B12: Настольная лампа | C12: — | D12: 1 | E12: https://www.detmir.ru/search/results/?qt=%D0%BB%D0%B0%D0%BC%D0%BF%D0%B0 | F12: 1299 | G12: 3 | H12: =IF(ISNUMBER(G12),IF(G12=0,0,F12*IF(D12=0,1,D12)/G12),IF(G12="неделя",F12*IF(D12=0,1,D12)*52,IF(G12="месяц",F12*IF(D12=0,1,D12)*12,F12*IF(D12=0,1,D12)))) | I12: =IF(H12=0,0,H12/12)
A13: 9 | B13: Ночник у кровати | C13: — | D13: 1 | E13: https://www.detmir.ru/search/results/?qt=%D0%BD%D0%BE%D1%87%D0%BD%D0%B8%D0%BA | F13: 899 | G13: 3 | H13: =IF(ISNUMBER(G13),IF(G13=0,0,F13*IF(D13=0,1,D13)/G13),IF(G13="неделя",F13*IF(D13=0,1,D13)*52,IF(G13="месяц",F13*IF(D13=0,1,D13)*12,F13*IF(D13=0,1,D13)))) | I13: =IF(H13=0,0,H13/12)
A14: 10 | B14: Одеяло | C14: — | D14: 1 | E14: https://www.detmir.ru/search/results/?qt=%D0%BE%D0%B4%D0%B5%D1%8F%D0%BB%D0%BE | F14: 1500 | G14: 3 | H14: =IF(ISNUMBER(G14),IF(G14=0,0,F14*IF(D14=0,1,D14)/G14),IF(G14="неделя",F14*IF(D14=0,1,D14)*52,IF(G14="месяц",F14*IF(D14=0,1,D14)*12,F14*IF(D14=0,1,D14)))) | I14: =IF(H14=0,0,H14/12)
A15: 11 | B15: Плед / покрывало | C15: — | D15: 1 | E15: https://www.detmir.ru/search/results/?qt=%D0%BF%D0%BB%D0%B5%D0%B4 | F15: 1999 | G15: 3 | H15: =IF(ISNUMBER(G15),IF(G15=0,0,F15*IF(D15=0,1,D15)/G15),IF(G15="неделя",F15*IF(D15=0,1,D15)*52,IF(G15="месяц",F15*IF(D15=0,1,D15)*12,F15*IF(D15=0,1,D15)))) | I15: =IF(H15=0,0,H15/12)
A16: 12 | B16: Подушка | C16: — | D16: 1 | E16: https://www.detmir.ru/search/results/?qt=%D0%BF%D0%BE%D0%B4%D1%83%D1%88%D0%BA%D0%B0 | F16: 800 | G16: 3 | H16: =IF(ISNUMBER(G16),IF(G16=0,0,F16*IF(D16=0,1,D16)/G16),IF(G16="неделя",F16*IF(D16=0,1,D16)*52,IF(G16="месяц",F16*IF(D16=0,1,D16)*12,F16*IF(D16=0,1,D16)))) | I16: =IF(H16=0,0,H16/12)
... A23: 19 | B23: Штора | C23: — | D23: 2 | E23: https://leroymerlin.ru/catalogue/shtory/ | F23: 1200 | G23: 5 | H23: =IF(ISNUMBER(G23),IF(G23=0,0,F23*IF(D23=0,1,D23)/G23),IF(G23="неделя",F23*IF(D23=0,1,D23)*52,IF(G23="месяц",F23*IF(D23=0,1,D23)*12,F23*IF(D23=0,1,D23)))) | I23: =IF(H23=0,0,H23/12)
A25: Итого: Комната | H25: =H5+H6+H7+H8+H9+H10+H11+H12+H13+H14+H15+H16+H17+H18+H19+H20+H21+H22+H23 | I25: =IF(H25=0,0,H25/12)

Sheet Оборудование покупки
A1: Оборудование
A2: Покупки — ссылка на товар и срок службы. Частое — период. Платежи — без ссылки.
A4: № | B4: Наименование | C4: Назначение | D4: Количество | E4: Ссылка | F4: Стоимость | G4: Срок службы (лет) | H4: В год, ₽ | I4: В месяц, ₽
A5: 1 | B5: Клавиатура | C5: — | D5: 1 | E5: https://www.dns-shop.ru/catalog/17a8a40216404e77/klaviatury/ | F5: 1499 | G5: 4 | H5: =IF(ISNUMBER(G5),IF(G5=0,0,F5*IF(D5=0,1,D5)/G5),IF(G5="неделя",F5*IF(D5=0,1,D5)*52,IF(G5="месяц",F5*IF(D5=0,1,D5)*12,F5*IF(D5=0,1,D5)))) | I5: =IF(H5=0,0,H5/12)
A6: 2 | B6: Коврик для мыши | C6: — | D6: 1 | E6: https://www.dns-shop.ru/catalog/17a9f9e316404e77/kovriki-dlya-myshi/ | F6: 299 | G6: 2 | H6: =IF(ISNUMBER(G6),IF(G6=0,0,F6*IF(D6=0,1,D6)/G6),IF(G6="неделя",F6*IF(D6=0,1,D6)*52,IF(G6="месяц",F6*IF(D6=0,1,D6)*12,F6*IF(D6=0,1,D6)))) | I6: =IF(H6=0,0,H6/12)
A7: 3 | B7: Колонки | C7: — | D7: 1 | E7: https://www.dns-shop.ru/catalog/17a8914916404e77/kompyuternaya-akustika/ | F7: 1499 | G7: 4 | H7: =IF(ISNUMBER(G7),IF(G7=0,0,F7*IF(D7=0,1,D7)/G7),IF(G7="неделя",F7*IF(D7=0,1,D7)*52,IF(G7="месяц",F7*IF(D7=0,1,D7)*12,F7*IF(D7=0,1,D7)))) | I7: =IF(H7=0,0,H7/12)
A8: 4 | B8: Микрофон | C8: — | D8: 1 | E8: https://www.dns-shop.ru/catalog/17a89bdd16404e77/mikrofoni/ | F8: 1299 | G8: 4 | H8: =IF(ISNUMBER(G8),IF(G8=0,0,F8*IF(D8=0,1,D8)/G8),IF(G8="неделя",F8*IF(D8=0,1,D8)*52,IF(G8="месяц",F8*IF(D8=0,1,D8)*12,F8*IF(D8=0,1,D8)))) | I8: =IF(H8=0,0,H8/12)
A9: 5 | B9: Монитор | C9: — | D9: 1 | E9: https://www.dns-shop.ru/catalog/17a8943716404e77/monitory/ | F9: 8999 | G9: 4 | H9: =IF(ISNUMBER(G9),IF(G9=0,0,F9*IF(D9=0,1,D9)/G9),IF(G9="неделя",F9*IF(D9=0,1,D9)*52,IF(G9="месяц",F9*IF(D9=0,1,D9)*12,F9*IF(D9=0,1,D9)))) | I9: =IF(H9=0,0,H9/12)
A10: 6 | B10: Мышь | C10: — | D10: 1 | E10: https://www.dns-shop.ru/catalog/17a8a4d816404e77/myshi/ | F10: 799 | G10: 4 | H10: =IF(ISNUMBER(G10),IF(G10=0,0,F10*IF(D10=0,1,D10)/G10),IF(G10="неделя",F10*IF(D10=0,1,D10)*52,IF(G10="месяц",F10*IF(D10=0,1,D10)*12,F10*IF(D10=0,1,D10)))) | I10: =IF(H10=0,0,H10/12)
A11: 7 | B11: Наушники | C11: — | D11: 1 | E11: https://www.detmir.ru/search/results/?qt=%D0%BD%D0%B0%D1%83%D1%88%D0%BD%D0%B8%D0%BA%D0%B8 | F11: 1999 | G11: 4 | H11: =IF(ISNUMBER(G11),IF(G11=0,0,F11*IF(D11=0,1,D11)/G11),IF(G11="неделя",F11*IF(D11=0,1,D11)*52,IF(G11="месяц",F11*IF(D11=0,1,D11)*12,F11*IF(D11=0,1,D11)))) | I11: =IF(H11=0,0,H11/12)
A12: 8 | B12: Системный блок | C12: — | D12: 1 | E12: https://www.avito.ru/ | F12: 23000 | G12: 4 | H12: =IF(ISNUMBER(G12),IF(G12=0,0,F12*IF(D12=0,1,D12)/G12),IF(G12="неделя",F12*IF(D12=0,1,D12)*52,IF(G12="месяц",F12*IF(D12=0,1,D12)*12,F12*IF(D12=0,1,D12)))) | I12: =IF(H12=0,0,H12/12)
A13: 9 | B13: Смартфон | C13: — | D13: 1 | E13: https://www.avito.ru/ | F13: 5000 | G13: 1 | H13: =IF(ISNUMBER(G13),IF(G13=0,0,F13*IF(D13=0,1,D13)/G13),IF(G13="неделя",F13*IF(D13=0,1,D13)*52,IF(G13="месяц",F13*IF(D13=0,1,D13)*12,F13*IF(D13=0,1,D13)))) | I13: =IF(H13=0,0,H13/12)
A15: Итого: Оборудование | H15: =H5+H6+H7+H8+H9+H10+H11+H12+H13 | I15: =IF(H15=0,0,H15/12)

Sheet Обувь покупки
A1: Обувь
A2: Покупки — ссылка на товар и срок службы. Частое — период. Платежи — без ссылки.
A4: № | B4: Наименование | C4: Назначение | D4: Количество | E4: Ссылка | F4: Стоимость | G4: Срок службы (лет) | H4: В год, ₽ | I4: В месяц, ₽
A5: 1 | B5: Ботинки зимние | C5: — | D5: 1 | E5: https://www.detmir.ru/catalog/index/name/botinki_m/sezon_oio-zima/ | F5: 3999 | G5: 1 | H5: =IF(ISNUMBER(G5),IF(G5=0,0,F5*IF(D5=0,1,D5)/G5),IF(G5="неделя",F5*IF(D5=0,1,D5)*52,IF(G5="месяц",F5*IF(D5=0,1,D5)*12,F5*IF(D5=0,1,D5)))) | I5: =IF(H5=0,0,H5/12)
A6: 2 | B6: Ботинки осенние утеплённые | C6: — | D6: 1 | E6: https://www.detmir.ru/catalog/index/name/botinki_m/sezon_oio-demisezon/ | F6: 2999 | G6: 1 | H6: =IF(ISNUMBER(G6),IF(G6=0,0,F6*IF(D6=0,1,D6)/G6),IF(G6="неделя",F6*IF(D6=0,1,D6)*52,IF(G6="месяц",F6*IF(D6=0,1,D6)*12,F6*IF(D6=0,1,D6)))) | I6: =IF(H6=0,0,H6/12)
A7: 3 | B7: Кроссовки | C7: — | D7: 1 | E7: https://www.detmir.ru/product/index/id/7076432/ | F7: 2499 | G7: 1 | H7: =IF(ISNUMBER(G7),IF(G7=0,0,F7*IF(D7=0,1,D7)/G7),IF(G7="неделя",F7*IF(D7=0,1,D7)*52,IF(G7="месяц",F7*IF(D7=0,1,D7)*12,F7*IF(D7=0,1,D7)))) | I7: =IF(H7=0,0,H7/12)
A8: 4 | B8: Сандалии летние | C8: — | D8: 1 | E8: https://www.detmir.ru/catalog/index/name/shoes_for_boys/brand/4112/ | F8: 999 | G8: 1 | H8: =IF(ISNUMBER(G8),IF(G8=0,0,F8*IF(D8=0,1,D8)/G8),IF(G8="неделя",F8*IF(D8=0,1,D8)*52,IF(G8="месяц",F8*IF(D8=0,1,D8)*12,F8*IF(D8=0,1,D8)))) | I8: =IF(H8=0,0,H8/12)
A9: 5 | B9: Сланцы летние | C9: — | D9: 1 | E9: https://www.detmir.ru/search/results/?qt=%D1%81%D0%BB%D0%B0%D0%BD%D1%86%D1%8B | F9: 499 | G9: 1 | H9: =IF(ISNUMBER(G9),IF(G9=0,0,F9*IF(D9=0,1,D9)/G9),IF(G9="неделя",F9*IF(D9=0,1,D9)*52,IF(G9="месяц",F9*IF(D9=0,1,D9)*12,F9*IF(D9=0,1,D9)))) | I9: =IF(H9=0,0,H9/12)
A10: 6 | B10: Сменная обувь | C10: в школу | D10: 1 | E10: https://www.sportmaster.ru/catalog/deti/obuv/krossovki_kedy/ | F10: 1800 | G10: 1 | H10: =IF(ISNUMBER(G10),IF(G10=0,0,F10*IF(D10=0,1,D10)/G10),IF(G10="неделя",F10*IF(D10=0,1,D10)*52,IF(G10="месяц",F10*IF(D10=0,1,D10)*12,F10*IF(D10=0,1,D10)))) | I10: =IF(H10=0,0,H10/12)
A11: 7 | B11: Тапочки домашние | C11: — | D11: 1 | E11: https://www.detmir.ru/search/results/?qt=%D1%82%D0%B0%D0%BF%D0%BE%D1%87%D0%BA%D0%B8 | F11: 599 | G11: 1 | H11: =IF(ISNUMBER(G11),IF(G11=0,0,F11*IF(D11=0,1,D11)/G11),IF(G11="неделя",F11*IF(D11=0,1,D11)*52,IF(G11="месяц",F11*IF(D11=0,1,D11)*12,F11*IF(D11=0,1,D11)))) | I11: =IF(H11=0,0,H11/12)
A12: 8 | B12: Туфли праздничные | C12: — | D12: 1 | E12: https://www.detmir.ru/product/index/id/7077779/ | F12: 1599 | G12: 1 | H12: =IF(ISNUMBER(G12),IF(G12=0,0,F12*IF(D12=0,1,D12)/G12),IF(G12="неделя",F12*IF(D12=0,1,D12)*52,IF(G12="месяц",F12*IF(D12=0,1,D12)*12,F12*IF(D12=0,1,D12)))) | I12: =IF(H12=0,0,H12/12)
A14: Итого: Обувь | H14: =H5+H6+H7+H8+H9+H10+H11+H12 | I14: =IF(H14=0,0,H14/12)

Sheet Одежда второго слоя покупки
A1: Одежда второго слоя
A2: Покупки — ссылка на товар и срок службы. Частое — период. Платежи — без ссылки.
A4: № | B4: Наименование | C4: Назначение | D4: Количество | E4: Ссылка | F4: Стоимость | G4: Срок службы (лет) | H4: В год, ₽ | I4: В месяц, ₽
A5: 1 | B5: Брюки праздничные | C5: — | D5: 1 | E5: https://www.detmir.ru/product/index/id/7069209/ | F5: 1299 | G5: 1 | H5: =IF(ISNUMBER(G5),IF(G5=0,0,F5*IF(D5=0,1,D5)/G5),IF(G5="неделя",F5*IF(D5=0,1,D5)*52,IF(G5="месяц",F5*IF(D5=0,1,D5)*12,F5*IF(D5=0,1,D5)))) | I5: =IF(H5=0,0,H5/12)
A6: 2 | B6: Брюки школьные | C6: в школу | D6: 2 | E6: https://www.wildberries.ru/catalog/13454614/detail.aspx | F6: 2000 | G6: 2 | H6: =IF(ISNUMBER(G6),IF(G6=0,0,F6*IF(D6=0,1,D6)/G6),IF(G6="неделя",F6*IF(D6=0,1,D6)*52,IF(G6="месяц",F6*IF(D6=0,1,D6)*12,F6*IF(D6=0,1,D6)))) | I6: =IF(H6=0,0,H6/12)
A7: 3 | B7: Джемпер школьный | C7: в школу | D7: 1 | E7: https://www.detmir.ru/product/index/id/7065088/ | F7: 1399 | G7: 2 | H7: =IF(ISNUMBER(G7),IF(G7=0,0,F7*IF(D7=0,1,D7)/G7),IF(G7="неделя",F7*IF(D7=0,1,D7)*52,IF(G7="месяц",F7*IF(D7=0,1,D7)*12,F7*IF(D7=0,1,D7)))) | I7: =IF(H7=0,0,H7/12)
A8: 4 | B8: Джинсы | C8: — | D8: 2 | E8: https://www.detmir.ru/catalog/index/name/detskaya_odezhda/brand/4112/ | F8: 799 | G8: 2 | H8: =IF(ISNUMBER(G8),IF(G8=0,0,F8*IF(D8=0,1,D8)/G8),IF(G8="неделя",F8*IF(D8=0,1,D8)*52,IF(G8="месяц",F8*IF(D8=0,1,D8)*12,F8*IF(D8=0,1,D8)))) | I8: =IF(H8=0,0,H8/12)
A9: 5 | B9: Домашний костюм | C9: — | D9: 2 | E9: https://www.detmir.ru/search/results/?qt=%D0%B4%D0%BE%D0%BC%D0%B0%D1%88%D0%BD%D0%B8%D0%B9%20%D0%BA%D0%BE%D1%81%D1%82%D1%8E%D0%BC | F9: 1499 | G9: 2 | H9: =IF(ISNUMBER(G9),IF(G9=0,0,F9*IF(D9=0,1,D9)/G9),IF(G9="неделя",F9*IF(D9=0,1,D9)*52,IF(G9="месяц",F9*IF(D9=0,1,D9)*12,F9*IF(D9=0,1,D9)))) | I9: =IF(H9=0,0,H9/12)
A10: 6 | B10: Жилет школьный | C10: в школу | D10: 1 | E10: https://www.detmir.ru/product/index/id/7065103/ | F10: 999 | G10: 2 | H10: =IF(ISNUMBER(G10),IF(G10=0,0,F10*IF(D10=0,1,D10)/G10),IF(G10="неделя",F10*IF(D10=0,1,D10)*52,IF(G10="месяц",F10*IF(D10=0,1,D10)*12,F10*IF(D10=0,1,D10)))) | I10: =IF(H10=0,0,H10/12)
A11: 7 | B11: Пиджак праздничный | C11: — | D11: 1 | E11: https://www.detmir.ru/product/index/id/6643629/ | F11: 2399 | G11: 1 | H11: =IF(ISNUMBER(G11),IF(G11=0,0,F11*IF(D11=0,1,D11)/G11),IF(G11="неделя",F11*IF(D11=0,1,D11)*52,IF(G11="месяц",F11*IF(D11=0,1,D11)*12,F11*IF(D11=0,1,D11)))) | I11: =IF(H11=0,0,H11/12)
A12: 8 | B12: Рубашка праздничная | C12: — | D12: 1 | E12: https://orby.ru/c/shkolnaya-forma-dlya-malchikov/ | F12: 2000 | G12: 1 | H12: =IF(ISNUMBER(G12),IF(G12=0,0,F12*IF(D12=0,1,D12)/G12),IF(G12="неделя",F12*IF(D12=0,1,D12)*52,IF(G12="месяц",F12*IF(D12=0,1,D12)*12,F12*IF(D12=0,1,D12)))) | I12: =IF(H12=0,0,H12/12)
A13: 9 | B13: Рубашка школьная | C13: в школу | D13: 2 | E13: https://orby.ru/c/shkolnaya-forma-dlya-malchikov/ | F13: 2000 | G13: 1 | H13: =IF(ISNUMBER(G13),IF(G13=0,0,F13*IF(D13=0,1,D13)/G13),IF(G13="неделя",F13*IF(D13=0,1,D13)*52,IF(G13="месяц",F13*IF(D13=0,1,D13)*12,F13*IF(D13=0,1,D13)))) | I13: =IF(H13=0,0,H13/12)
A14: 10 | B14: Свитер | C14: — | D14: 2 | E14: https://www.detmir.ru/search/results/?qt=%D1%81%D0%B2%D0%B8%D1%82%D0%B5%D1%80 | F14: 1199 | G14: 2 | H14: =IF(ISNUMBER(G14),IF(G14=0,0,F14*IF(D14=0,1,D14)/G14),IF(G14="неделя",F14*IF(D14=0,1,D14)*52,IF(G14="месяц",F14*IF(D14=0,1,D14)*12,F14*IF(D14=0,1,D14)))) | I14: =IF(H14=0,0,H14/12)
A15: 11 | B15: Футболка | C15: — | D15: 2 | E15: https://www.wildberries.ru/brands/playtoday | F15: 599 | G15: 1 | H15: =IF(ISNUMBER(G15),IF(G15=0,0,F15*IF(D15=0,1,D15)/G15),IF(G15="неделя",F15*IF(D15=0,1,D15)*52,IF(G15="месяц",F15*IF(D15=0,1,D15)*12,F15*IF(D15=0,1,D15)))) | I15: =IF(H15=0,0,H15/12)
A16: 12 | B16: Худи | C16: — | D16: 2 | E16: https://www.wildberries.ru/brands/playtoday | F16: 1799 | G16: 2 | H16: =IF(ISNUMBER(G16),IF(G16=0,0,F16*IF(D16=0,1,D16)/G16),IF(G16="неделя",F16*IF(D16=0,1,D16)*52,IF(G16="месяц",F16*IF(D16=0,1,D16)*12,F16*IF(D16=0,1,D16)))) | I16: =IF(H16=0,0,H16/12)
A17: 13 | B17: Шорты летние | C17: — | D17: 2 | E17: https://www.wildberries.ru/brands/playtoday | F17: 899 | G17: 1 | H17: =IF(ISNUMBER(G17),IF(G17=0,0,F17*IF(D17=0,1,D17)/G17),IF(G17="неделя",F17*IF(D17=0,1,D17)*52,IF(G17="месяц",F17*IF(D17=0,1,D17)*12,F17*IF(D17=0,1,D17)))) | I17: =IF(H17=0,0,H17/12)
A19: Итого: Одежда второго слоя | H19: =H5+H6+H7+H8+H9+H10+H11+H12+H13+H14+H15+H16+H17 | I19: =IF(H19=0,0,H19/12)

Sheet Предметы личного пользования по
A1: Предметы личного пользования
A2: Покупки — ссылка на товар и срок службы. Частое — период. Платежи — без ссылки.
A4: № | B4: Наименование | C4: Назначение | D4: Количество | E4: Ссылка | F4: Стоимость | G4: Срок службы (лет) | H4: В год, ₽ | I4: В месяц, ₽
A5: 1 | B5: Вилка | C5: — | D5: 1 | E5: https://www.detmir.ru/search/results/?qt=%D0%B2%D0%B8%D0%BB%D0%BA%D0%B0%20%D0%B4%D0%B5%D1%82%D1%81%D0%BA%D0%B0%D1%8F | F5: 49 | G5: 3 | H5: =IF(ISNUMBER(G5),IF(G5=0,0,F5*IF(D5=0,1,D5)/G5),IF(G5="неделя",F5*IF(D5=0,1,D5)*52,IF(G5="месяц",F5*IF(D5=0,1,D5)*12,F5*IF(D5=0,1,D5)))) | I5: =IF(H5=0,0,H5/12)
A6: 2 | B6: Влажные салфетки | C6: — | D6: 12 | E6: https://magnit.ru/catalog?q=%D0%B2%D0%BB%D0%B0%D0%B6%D0%BD%D1%8B%D0%B5%20%D1%81%D0%B0%D0%BB%D1%84%D0%B5%D1%82%D0%BA%D0%B8 | F6: 89 | G6: 1 | H6: =IF(ISNUMBER(G6),IF(G6=0,0,F6*IF(D6=0,1,D6)/G6),IF(G6="неделя",F6*IF(D6=0,1,D6)*52,IF(G6="месяц",F6*IF(D6=0,1,D6)*12,F6*IF(D6=0,1,D6)))) | I6: =IF(H6=0,0,H6/12)
A7: 3 | B7: Зубная паста R.O.C.S. | C7: — | D7: 6 | E7: https://www.okeydostavka.ru/webapp/wcs/stores/servlet/SearchDisplay?searchTerm=R.O.C.S. | F7: 399 | G7: 1 | H7: =IF(ISNUMBER(G7),IF(G7=0,0,F7*IF(D7=0,1,D7)/G7),IF(G7="неделя",F7*IF(D7=0,1,D7)*52,IF(G7="месяц",F7*IF(D7=0,1,D7)*12,F7*IF(D7=0,1,D7)))) | I7: =IF(H7=0,0,H7/12)
A8: 4 | B8: Зубная щётка | C8: — | D8: 2 | E8: https://www.detmir.ru/search/results/?qt=%D0%B7%D1%83%D0%B1%D0%BD%D0%B0%D1%8F%20%D1%89%D0%B5%D1%82%D0%BA%D0%B0%20%D0%B4%D0%B5%D1%82%D1%81%D0%BA%D0%B0%D1%8F | F8: 149 | G8: 1 | H8: =IF(ISNUMBER(G8),IF(G8=0,0,F8*IF(D8=0,1,D8)/G8),IF(G8="неделя",F8*IF(D8=0,1,D8)*52,IF(G8="месяц",F8*IF(D8=0,1,D8)*12,F8*IF(D8=0,1,D8)))) | I8: =IF(H8=0,0,H8/12)
A9: 5 | B9: Ложка столовая | C9: — | D9: 1 | E9: https://www.detmir.ru/search/results/?qt=%D0%BB%D0%BE%D0%B6%D0%BA%D0%B0%20%D0%B4%D0%B5%D1%82%D1%81%D0%BA%D0%B0%D1%8F | F9: 49 | G9: 3 | H9: =IF(ISNUMBER(G9),IF(G9=0,0,F9*IF(D9=0,1,D9)/G9),IF(G9="неделя",F9*IF(D9=0,1,D9)*52,IF(G9="месяц",F9*IF(D9=0,1,D9)*12,F9*IF(D9=0,1,D9)))) | I9: =IF(H9=0,0,H9/12)
A10: 6 | B10: Ложка чайная | C10: — | D10: 1 | E10: https://www.detmir.ru/search/results/?qt=%D0%BB%D0%BE%D0%B6%D0%BA%D0%B0%20%D1%87%D0%B0%D0%B9%D0%BD%D0%B0%D1%8F%20%D0%B4%D0%B5%D1%82%D1%81%D0%BA%D0%B0%D1%8F | F10: 39 | G10: 3 | H10: =IF(ISNUMBER(G10),IF(G10=0,0,F10*IF(D10=0,1,D10)/G10),IF(G10="неделя",F10*IF(D10=0,1,D10)*52,IF(G10="месяц",F10*IF(D10=0,1,D10)*12,F10*IF(D10=0,1,D10)))) | I10: =IF(H10=0,0,H10/12)
A11: 7 | B11: Молочко для тела | C11: — | D11: 1 | E11: https://magnit.ru/catalog?q=%D0%BC%D0%BE%D0%BB%D0%BE%D1%87%D0%BA%D0%BE%20%D0%B4%D0%BB%D1%8F%20%D1%82%D0%B5%D0%BB%D0%B0%20%D0%B4%D0%B5%D1%82%D1%81%D0%BA%D0%BE%D0%B5 | F11: 299 | G11: 1 | H11: =IF(ISNUMBER(G11),IF(G11=0,0,F11*IF(D11=0,1,D11)/G11),IF(G11="неделя",F11*IF(D11=0,1,D11)*52,IF(G11="месяц",F11*IF(D11=0,1,D11)*12,F11*IF(D11=0,1,D11)))) | I11: =IF(H11=0,0,H11/12)
A12: 8 | B12: Мочалка | C12: — | D12: 1 | E12: https://www.detmir.ru/search/results/?qt=%D0%BC%D0%BE%D1%87%D0%B0%D0%BB%D0%BA%D0%B0 | F12: 199 | G12: 1 | H12: =IF(ISNUMBER(G12),IF(G12=0,0,F12*IF(D12=0,1,D12)/G12),IF(G12="неделя",F12*IF(D12=0,1,D12)*52,IF(G12="месяц",F12*IF(D12=0,1,D12)*12,F12*IF(D12=0,1,D12)))) | I12: =IF(H12=0,0,H12/12)
A13: 9 | B13: Полотенце банное | C13: — | D13: 1 | E13: https://www.detmir.ru/search/results/?qt=%D0%BF%D0%BE%D0%BB%D0%BE%D1%82%D0%B5%D0%BD%D1%86%D0%B5%20%D0%B1%D0%B0%D0%BD%D0%BD%D0%BE%D0%B5 | F13: 699 | G13: 1 | H13: =IF(ISNUMBER(G13),IF(G13=0,0,F13*IF(D13=0,1,D13)/G13),IF(G13="неделя",F13*IF(D13=0,1,D13)*52,IF(G13="месяц",F13*IF(D13=0,1,D13)*12,F13*IF(D13=0,1,D13)))) | I13: =IF(H13=0,0,H13/12)
A14: 10 | B14: Полотенце для лица | C14: — | D14: 2 | E14: https://www.detmir.ru/search/results/?qt=%D0%BF%D0%BE%D0%BB%D0%BE%D1%82%D0%B5%D0%BD%D1%86%D0%B5%20%D0%B4%D0%BB%D1%8F%20%D0%BB%D0%B8%D1%86%D0%B0 | F14: 349 | G14: 1 | H14: =IF(ISNUMBER(G14),IF(G14=0,0,F14*IF(D14=0,1,D14)/G14),IF(G14="неделя",F14*IF(D14=0,1,D14)*52,IF(G14="месяц",F14*IF(D14=0,1,D14)*12,F14*IF(D14=0,1,D14)))) | I14: =IF(H14=0,0,H14/12)
A15: 11 | B15: Тарелка глубокая | C15: — | D15: 1 | E15: https://www.detmir.ru/search/results/?qt=%D1%82%D0%B0%D1%80%D0%B5%D0%BB%D0%BA%D0%B0%20%D0%B4%D0%B5%D1%82%D1%81%D0%BA%D0%B0%D1%8F | F15: 149 | G15: 3 | H15: =IF(ISNUMBER(G15),IF(G15=0,0,F15*IF(D15=0,1,D15)/G15),IF(G15="неделя",F15*IF(D15=0,1,D15)*52,IF(G15="месяц",F15*IF(D15=0,1,D15)*12,F15*IF(D15=0,1,D15)))) | I15: =IF(H15=0,0,H15/12)
A16: 12 | B16: Тарелка плоская | C16: — | D16: 1 | E16: https://www.detmir.ru/search/results/?qt=%D1%82%D0%B0%D1%80%D0%B5%D0%BB%D0%BA%D0%B0%20%D0%B4%D0%B5%D1%82%D1%81%D0%BA%D0%B0%D1%8F | F16: 149 | G16: 3 | H16: =IF(ISNUMBER(G16),IF(G16=0,0,F16*IF(D16=0,1,D16)/G16),IF(G16="неделя",F16*IF(D16=0,1,D16)*52,IF(G16="месяц",F16*IF(D16=0,1,D16)*12,F16*IF(D16=0,1,D16)))) | I16: =IF(H16=0,0,H16/12)
... A20: 16 | B20: Шейкер / бутылка | C20: — | D20: 1 | E20: https://www.detmir.ru/search/results/?qt=%D0%B1%D1%83%D1%82%D1%8B%D0%BB%D0%BA%D0%B0 | F20: 499 | G20: 2 | H20: =IF(ISNUMBER(G20),IF(G20=0,0,F20*IF(D20=0,1,D20)/G20),IF(G20="неделя",F20*IF(D20=0,1,D20)*52,IF(G20="месяц",F20*IF(D20=0,1,D20)*12,F20*IF(D20=0,1,D20)))) | I20: =IF(H20=0,0,H20/12)
A22: Итого: Предметы личного пользования | H22: =H5+H6+H7+H8+H9+H10+H11+H12+H13+H14+H15+H16+H17+H18+H19+H20 | I22: =IF(H22=0,0,H22/12)

Sheet Продукты питания покупки
A1: Продукты питания
A2: Покупки — ссылка на товар и срок службы. Частое — период. Платежи — без ссылки.
A4: № | B4: Наименование | C4: Назначение | D4: Количество | E4: Ссылка | F4: Стоимость | G4: Период | H4: В год, ₽ | I4: В месяц, ₽
A5: 1 | B5: Продукты на ребёнка | C5: — | D5: 1 | E5: https://magnit.ru/ | F5: 20000 | G5: месяц | H5: =IF(ISNUMBER(G5),IF(G5=0,0,F5*IF(D5=0,1,D5)/G5),IF(G5="неделя",F5*IF(D5=0,1,D5)*52,IF(G5="месяц",F5*IF(D5=0,1,D5)*12,F5*IF(D5=0,1,D5)))) | I5: =IF(H5=0,0,H5/12)
A7: Итого: Продукты питания | H7: =H5 | I7: =IF(H7=0,0,H7/12)

Sheet Спорт и досуг покупки
A1: Спорт и досуг
A2: Покупки — ссылка на товар и срок службы. Частое — период. Платежи — без ссылки.
A4: № | B4: Наименование | C4: Назначение | D4: Количество | E4: Ссылка | F4: Стоимость | G4: Срок службы (лет) | H4: В год, ₽ | I4: В месяц, ₽
A5: 1 | B5: Борцовка самбо | C5: — | D5: 1 | E5: https://rocky-shop.ru/ekipirovka-dlya-edinoborstv/kurtka-dlya-sambo-green-hill-junior-rostovki-160-190-sm-10032.html | F5: 3690 | G5: 2 | H5: =IF(ISNUMBER(G5),IF(G5=0,0,F5*IF(D5=0,1,D5)/G5),IF(G5="неделя",F5*IF(D5=0,1,D5)*52,IF(G5="месяц",F5*IF(D5=0,1,D5)*12,F5*IF(D5=0,1,D5)))) | I5: =IF(H5=0,0,H5/12)
A6: 2 | B6: Бустер автомобильный | C6: — | D6: 1 | E6: https://www.detmir.ru/search/results/?qt=%D0%B1%D1%83%D1%81%D1%82%D0%B5%D1%80%20%D0%B0%D0%B2%D1%82%D0%BE%D0%BC%D0%BE%D0%B1%D0%B8%D0%BB%D1%8C%D0%BD%D1%8B%D0%B9 | F6: 1999 | G6: 7 | H6: =IF(ISNUMBER(G6),IF(G6=0,0,F6*IF(D6=0,1,D6)/G6),IF(G6="неделя",F6*IF(D6=0,1,D6)*52,IF(G6="месяц",F6*IF(D6=0,1,D6)*12,F6*IF(D6=0,1,D6)))) | I6: =IF(H6=0,0,H6/12)
A7: 3 | B7: Велосипед Stern 24" | C7: — | D7: 1 | E7: https://market.yandex.ru/search?text=%D0%B2%D0%B5%D0%BB%D0%BE%D1%81%D0%B8%D0%BF%D0%B5%D0%B4%20Stern%2024 | F7: 27999 | G7: 5 | H7: =IF(ISNUMBER(G7),IF(G7=0,0,F7*IF(D7=0,1,D7)/G7),IF(G7="неделя",F7*IF(D7=0,1,D7)*52,IF(G7="месяц",F7*IF(D7=0,1,D7)*12,F7*IF(D7=0,1,D7)))) | I7: =IF(H7=0,0,H7/12)
A8: 4 | B8: Гантель | C8: — | D8: 2 | E8: https://www.detmir.ru/search/results/?qt=%D0%B3%D0%B0%D0%BD%D1%82%D0%B5%D0%BB%D0%B8%20%D0%B4%D0%B5%D1%82%D1%81%D0%BA%D0%B8%D0%B5 | F8: 365 | G8: 3 | H8: =IF(ISNUMBER(G8),IF(G8=0,0,F8*IF(D8=0,1,D8)/G8),IF(G8="неделя",F8*IF(D8=0,1,D8)*52,IF(G8="месяц",F8*IF(D8=0,1,D8)*12,F8*IF(D8=0,1,D8)))) | I8: =IF(H8=0,0,H8/12)
A9: 5 | B9: Защита голени | C9: — | D9: 1 | E9: https://karate.ru/shop/catalog/407-perchatki-mma-sinie-kozhzamenitel-combat-sambo-green-hill/ | F9: 2190 | G9: 2 | H9: =IF(ISNUMBER(G9),IF(G9=0,0,F9*IF(D9=0,1,D9)/G9),IF(G9="неделя",F9*IF(D9=0,1,D9)*52,IF(G9="месяц",F9*IF(D9=0,1,D9)*12,F9*IF(D9=0,1,D9)))) | I9: =IF(H9=0,0,H9/12)
A10: 6 | B10: Коньки | C10: — | D10: 1 | E10: https://www.detmir.ru/search/results/?qt=%D0%BA%D0%BE%D0%BD%D1%8C%D0%BA%D0%B8 | F10: 2999 | G10: 1 | H10: =IF(ISNUMBER(G10),IF(G10=0,0,F10*IF(D10=0,1,D10)/G10),IF(G10="неделя",F10*IF(D10=0,1,D10)*52,IF(G10="месяц",F10*IF(D10=0,1,D10)*12,F10*IF(D10=0,1,D10)))) | I10: =IF(H10=0,0,H10/12)
A11: 7 | B11: Ласты | C11: — | D11: 1 | E11: https://www.detmir.ru/search/results/?qt=%D0%BB%D0%B0%D1%81%D1%82%D1%8B%20%D0%B4%D0%B5%D1%82%D1%81%D0%BA%D0%B8%D0%B5 | F11: 999 | G11: 2 | H11: =IF(ISNUMBER(G11),IF(G11=0,0,F11*IF(D11=0,1,D11)/G11),IF(G11="неделя",F11*IF(D11=0,1,D11)*52,IF(G11="месяц",F11*IF(D11=0,1,D11)*12,F11*IF(D11=0,1,D11)))) | I11: =IF(H11=0,0,H11/12)
A12: 8 | B12: Мяч футбольный | C12: — | D12: 1 | E12: https://www.detmir.ru/search/results/?qt=%D0%BC%D1%8F%D1%87%20%D1%84%D1%83%D1%82%D0%B1%D0%BE%D0%BB%D1%8C%D0%BD%D1%8B%D0%B9 | F12: 799 | G12: 2 | H12: =IF(ISNUMBER(G12),IF(G12=0,0,F12*IF(D12=0,1,D12)/G12),IF(G12="неделя",F12*IF(D12=0,1,D12)*52,IF(G12="месяц",F12*IF(D12=0,1,D12)*12,F12*IF(D12=0,1,D12)))) | I12: =IF(H12=0,0,H12/12)
A13: 9 | B13: Надувной круг | C13: — | D13: 1 | E13: https://www.detmir.ru/search/results/?qt=%D0%BD%D0%B0%D0%B4%D1%83%D0%B2%D0%BD%D0%BE%D0%B9%20%D0%BA%D1%80%D1%83%D0%B3 | F13: 599 | G13: 2 | H13: =IF(ISNUMBER(G13),IF(G13=0,0,F13*IF(D13=0,1,D13)/G13),IF(G13="неделя",F13*IF(D13=0,1,D13)*52,IF(G13="месяц",F13*IF(D13=0,1,D13)*12,F13*IF(D13=0,1,D13)))) | I13: =IF(H13=0,0,H13/12)
A14: 10 | B14: Перчатки для самбо | C14: — | D14: 1 | E14: https://dantesport.ru/product_info.php?products_id=1207 | F14: 2990 | G14: 2 | H14: =IF(ISNUMBER(G14),IF(G14=0,0,F14*IF(D14=0,1,D14)/G14),IF(G14="неделя",F14*IF(D14=0,1,D14)*52,IF(G14="месяц",F14*IF(D14=0,1,D14)*12,F14*IF(D14=0,1,D14)))) | I14: =IF(H14=0,0,H14/12)
A15: 11 | B15: Плавки | C15: — | D15: 1 | E15: https://www.detmir.ru/catalog/index/name/plavki/ | F15: 599 | G15: 1 | H15: =IF(ISNUMBER(G15),IF(G15=0,0,F15*IF(D15=0,1,D15)/G15),IF(G15="неделя",F15*IF(D15=0,1,D15)*52,IF(G15="месяц",F15*IF(D15=0,1,D15)*12,F15*IF(D15=0,1,D15)))) | I15: =IF(H15=0,0,H15/12)
A16: 12 | B16: Полотенце для плавания | C16: — | D16: 1 | E16: https://www.detmir.ru/search/results/?qt=%D0%BF%D0%BE%D0%BB%D0%BE%D1%82%D0%B5%D0%BD%D1%86%D0%B5%20%D0%BF%D0%BB%D0%B0%D0%B2%D0%B0%D0%BD%D0%B8%D0%B5 | F16: 499 | G16: 1 | H16: =IF(ISNUMBER(G16),IF(G16=0,0,F16*IF(D16=0,1,D16)/G16),IF(G16="неделя",F16*IF(D16=0,1,D16)*52,IF(G16="месяц",F16*IF(D16=0,1,D16)*12,F16*IF(D16=0,1,D16)))) | I16: =IF(H16=0,0,H16/12)
... A20: 16 | B20: Шорты для самбо | C20: — | D20: 1 | E20: https://rocky-shop.ru/ekipirovka-dlya-edinoborstv/detskie-bortscovki-dlya-sambo-green-hill-triumf-odobreny-fias-27458.html | F20: 1990 | G20: 2 | H20: =IF(ISNUMBER(G20),IF(G20=0,0,F20*IF(D20=0,1,D20)/G20),IF(G20="неделя",F20*IF(D20=0,1,D20)*52,IF(G20="месяц",F20*IF(D20=0,1,D20)*12,F20*IF(D20=0,1,D20)))) | I20: =IF(H20=0,0,H20/12)
A22: Итого: Спорт и досуг | H22: =H5+H6+H7+H8+H9+H10+H11+H12+H13+H14+H15+H16+H17+H18+H19+H20 | I22: =IF(H22=0,0,H22/12)

Sheet Школьные принадлежности покупки
A1: Школьные принадлежности
A2: Покупки — ссылка на товар и срок службы. Частое — период. Платежи — без ссылки.
A4: № | B4: Наименование | C4: Назначение | D4: Количество | E4: Ссылка | F4: Стоимость | G4: Срок службы (лет) | H4: В год, ₽ | I4: В месяц, ₽
A5: 1 | B5: Альбом для рисования | C5: в школу | D5: 1 | E5: https://www.detmir.ru/search/results/?qt=%D0%B0%D0%BB%D1%8C%D0%B1%D0%BE%D0%BC | F5: 89 | G5: 1 | H5: =IF(ISNUMBER(G5),IF(G5=0,0,F5*IF(D5=0,1,D5)/G5),IF(G5="неделя",F5*IF(D5=0,1,D5)*52,IF(G5="месяц",F5*IF(D5=0,1,D5)*12,F5*IF(D5=0,1,D5)))) | I5: =IF(H5=0,0,H5/12)
A6: 2 | B6: Готовальня | C6: в школу | D6: 1 | E6: https://www.detmir.ru/catalog/index/name/cyrkuli/tip_cherchenie-gotovalnya/ | F6: 349 | G6: 1 | H6: =IF(ISNUMBER(G6),IF(G6=0,0,F6*IF(D6=0,1,D6)/G6),IF(G6="неделя",F6*IF(D6=0,1,D6)*52,IF(G6="месяц",F6*IF(D6=0,1,D6)*12,F6*IF(D6=0,1,D6)))) | I6: =IF(H6=0,0,H6/12)
A7: 3 | B7: Гуашь 12 цв. | C7: в школу | D7: 1 | E7: https://www.detmir.ru/product/index/id/6430833/ | F7: 239 | G7: 1 | H7: =IF(ISNUMBER(G7),IF(G7=0,0,F7*IF(D7=0,1,D7)/G7),IF(G7="неделя",F7*IF(D7=0,1,D7)*52,IF(G7="месяц",F7*IF(D7=0,1,D7)*12,F7*IF(D7=0,1,D7)))) | I7: =IF(H7=0,0,H7/12)
A8: 4 | B8: Дневник | C8: в школу | D8: 1 | E8: https://www.detmir.ru/product/index/id/6462321/ | F8: 329 | G8: 1 | H8: =IF(ISNUMBER(G8),IF(G8=0,0,F8*IF(D8=0,1,D8)/G8),IF(G8="неделя",F8*IF(D8=0,1,D8)*52,IF(G8="месяц",F8*IF(D8=0,1,D8)*12,F8*IF(D8=0,1,D8)))) | I8: =IF(H8=0,0,H8/12)
A9: 5 | B9: Доска для пластилина | C9: в школу | D9: 1 | E9: https://www.detmir.ru/search/results/?qt=%D0%B4%D0%BE%D1%81%D0%BA%D0%B0%20%D0%B4%D0%BB%D1%8F%20%D0%BB%D0%B5%D0%BF%D0%BA%D0%B8 | F9: 49 | G9: 1 | H9: =IF(ISNUMBER(G9),IF(G9=0,0,F9*IF(D9=0,1,D9)/G9),IF(G9="неделя",F9*IF(D9=0,1,D9)*52,IF(G9="месяц",F9*IF(D9=0,1,D9)*12,F9*IF(D9=0,1,D9)))) | I9: =IF(H9=0,0,H9/12)
A10: 6 | B10: Закладки | C10: в школу | D10: 3 | E10: https://www.detmir.ru/search/results/?qt=%D0%B7%D0%B0%D0%BA%D0%BB%D0%B0%D0%B4%D0%BA%D0%B8%20%D0%B4%D0%BB%D1%8F%20%D0%BA%D0%BD%D0%B8%D0%B3 | F10: 39 | G10: 1 | H10: =IF(ISNUMBER(G10),IF(G10=0,0,F10*IF(D10=0,1,D10)/G10),IF(G10="неделя",F10*IF(D10=0,1,D10)*52,IF(G10="месяц",F10*IF(D10=0,1,D10)*12,F10*IF(D10=0,1,D10)))) | I10: =IF(H10=0,0,H10/12)
A11: 7 | B11: Карандаш простой HB | C11: в школу | D11: 10 | E11: https://www.detmir.ru/search/results/?qt=%D0%BA%D0%B0%D1%80%D0%B0%D0%BD%D0%B4%D0%B0%D1%88%20HB | F11: 20 | G11: 1 | H11: =IF(ISNUMBER(G11),IF(G11=0,0,F11*IF(D11=0,1,D11)/G11),IF(G11="неделя",F11*IF(D11=0,1,D11)*52,IF(G11="месяц",F11*IF(D11=0,1,D11)*12,F11*IF(D11=0,1,D11)))) | I11: =IF(H11=0,0,H11/12)
A12: 8 | B12: Карандаши цветные 36 | C12: в школу | D12: 2 | E12: https://www.detmir.ru/product/index/id/6016009/ | F12: 328 | G12: 1 | H12: =IF(ISNUMBER(G12),IF(G12=0,0,F12*IF(D12=0,1,D12)/G12),IF(G12="неделя",F12*IF(D12=0,1,D12)*52,IF(G12="месяц",F12*IF(D12=0,1,D12)*12,F12*IF(D12=0,1,D12)))) | I12: =IF(H12=0,0,H12/12)
A13: 9 | B13: Картон цветной | C13: в школу | D13: 1 | E13: https://www.detmir.ru/search/results/?qt=%D0%BA%D0%B0%D1%80%D1%82%D0%BE%D0%BD%20%D1%86%D0%B2%D0%B5%D1%82%D0%BD%D0%BE%D0%B9 | F13: 89 | G13: 1 | H13: =IF(ISNUMBER(G13),IF(G13=0,0,F13*IF(D13=0,1,D13)/G13),IF(G13="неделя",F13*IF(D13=0,1,D13)*52,IF(G13="месяц",F13*IF(D13=0,1,D13)*12,F13*IF(D13=0,1,D13)))) | I13: =IF(H13=0,0,H13/12)
A14: 10 | B14: Клей ПВА | C14: в школу | D14: 2 | E14: https://www.detmir.ru/search/results/?qt=%D0%BA%D0%BB%D0%B5%D0%B9%20%D0%9F%D0%92%D0%90 | F14: 79 | G14: 1 | H14: =IF(ISNUMBER(G14),IF(G14=0,0,F14*IF(D14=0,1,D14)/G14),IF(G14="неделя",F14*IF(D14=0,1,D14)*52,IF(G14="месяц",F14*IF(D14=0,1,D14)*12,F14*IF(D14=0,1,D14)))) | I14: =IF(H14=0,0,H14/12)
A15: 11 | B15: Клей-карандаш | C15: в школу | D15: 2 | E15: https://www.detmir.ru/search/results/?qt=%D0%BA%D0%BB%D0%B5%D0%B9-%D0%BA%D0%B0%D1%80%D0%B0%D0%BD%D0%B4%D0%B0%D1%88 | F15: 59 | G15: 1 | H15: =IF(ISNUMBER(G15),IF(G15=0,0,F15*IF(D15=0,1,D15)/G15),IF(G15="неделя",F15*IF(D15=0,1,D15)*52,IF(G15="месяц",F15*IF(D15=0,1,D15)*12,F15*IF(D15=0,1,D15)))) | I15: =IF(H15=0,0,H15/12)
A16: 12 | B16: Корректор | C16: в школу | D16: 2 | E16: https://www.detmir.ru/search/results/?qt=%D0%BA%D0%BE%D1%80%D1%80%D0%B5%D0%BA%D1%82%D0%BE%D1%80%20%D1%88%D0%BA%D0%BE%D0%BB%D1%8C%D0%BD%D1%8B%D0%B9 | F16: 59 | G16: 1 | H16: =IF(ISNUMBER(G16),IF(G16=0,0,F16*IF(D16=0,1,D16)/G16),IF(G16="неделя",F16*IF(D16=0,1,D16)*52,IF(G16="месяц",F16*IF(D16=0,1,D16)*12,F16*IF(D16=0,1,D16)))) | I16: =IF(H16=0,0,H16/12)
... A35: 31 | B35: Цветная бумага | C35: в школу | D35: 1 | E35: https://www.detmir.ru/search/results/?qt=%D1%86%D0%B2%D0%B5%D1%82%D0%BD%D0%B0%D1%8F%20%D0%B1%D1%83%D0%BC%D0%B0%D0%B3%D0%B0 | F35: 69 | G35: 1 | H35: =IF(ISNUMBER(G35),IF(G35=0,0,F35*IF(D35=0,1,D35)/G35),IF(G35="неделя",F35*IF(D35=0,1,D35)*52,IF(G35="месяц",F35*IF(D35=0,1,D35)*12,F35*IF(D35=0,1,D35)))) | I35: =IF(H35=0,0,H35/12)
A37: Итого: Школьные принадлежности | H37: =H5+H6+H7+H8+H9+H10+H11+H12+H13+H14+H15+H16+H17+H18+H19+H20+H21+H22+H23+H24+H25+H26+H27+H28+H29+H30+H31+H32+H33+H34+H35 | I37: =IF(H37=0,0,H37/12)

Sheet Лекарства
A1: Лекарства
A2: Покупки — ссылка на товар и срок службы. Частое — период. Платежи — без ссылки.
A4: № | B4: Наименование | C4: Назначение | D4: Количество | E4: Ссылка | F4: Стоимость | G4: Период | H4: В год, ₽ | I4: В месяц, ₽
A5: 1 | B5: Долфин | C5: — | D5: 1 | E5: https://www.eapteka.ru/goods/id215357/ | F5: 548 | G5: год | H5: =IF(ISNUMBER(G5),IF(G5=0,0,F5*IF(D5=0,1,D5)/G5),IF(G5="неделя",F5*IF(D5=0,1,D5)*52,IF(G5="месяц",F5*IF(D5=0,1,D5)*12,F5*IF(D5=0,1,D5)))) | I5: =IF(H5=0,0,H5/12)
A6: 2 | B6: Йод | C6: — | D6: 1 | E6: https://www.eapteka.ru/search/?q=%D0%B9%D0%BE%D0%B4 | F6: 59 | G6: год | H6: =IF(ISNUMBER(G6),IF(G6=0,0,F6*IF(D6=0,1,D6)/G6),IF(G6="неделя",F6*IF(D6=0,1,D6)*52,IF(G6="месяц",F6*IF(D6=0,1,D6)*12,F6*IF(D6=0,1,D6)))) | I6: =IF(H6=0,0,H6/12)
A7: 3 | B7: Макмирор | C7: — | D7: 9 | E7: https://apteka.magnit.ru/product/7000001484-makmiror_tabletki_200mg_20sht | F7: 1470 | G7: год | H7: =IF(ISNUMBER(G7),IF(G7=0,0,F7*IF(D7=0,1,D7)/G7),IF(G7="неделя",F7*IF(D7=0,1,D7)*52,IF(G7="месяц",F7*IF(D7=0,1,D7)*12,F7*IF(D7=0,1,D7)))) | I7: =IF(H7=0,0,H7/12)
A8: 4 | B8: Називин, 1 флакон | C8: — | D8: 1 | E8: https://www.eapteka.ru/search/?q=%D0%BD%D0%B0%D0%B7%D0%B8%D0%B2%D0%B8%D0%BD | F8: 340 | G8: год | H8: =IF(ISNUMBER(G8),IF(G8=0,0,F8*IF(D8=0,1,D8)/G8),IF(G8="неделя",F8*IF(D8=0,1,D8)*52,IF(G8="месяц",F8*IF(D8=0,1,D8)*12,F8*IF(D8=0,1,D8)))) | I8: =IF(H8=0,0,H8/12)
A9: 5 | B9: Перекись водорода | C9: — | D9: 1 | E9: https://www.eapteka.ru/search/?q=%D0%BF%D0%B5%D1%80%D0%B5%D0%BA%D0%B8%D1%81%D1%8C%20%D0%B2%D0%BE%D0%B4%D0%BE%D1%80%D0%BE%D0%B4%D0%B0 | F9: 45 | G9: год | H9: =IF(ISNUMBER(G9),IF(G9=0,0,F9*IF(D9=0,1,D9)/G9),IF(G9="неделя",F9*IF(D9=0,1,D9)*52,IF(G9="месяц",F9*IF(D9=0,1,D9)*12,F9*IF(D9=0,1,D9)))) | I9: =IF(H9=0,0,H9/12)
A10: 6 | B10: Пирантел жидкий | C10: — | D10: 2 | E10: https://www.eapteka.ru/search/?q=%D0%BF%D0%B8%D1%80%D0%B0%D0%BD%D1%82%D0%B5%D0%BB%20%D1%81%D1%83%D1%81%D0%BF%D0%B5%D0%BD%D0%B7%D0%B8%D1%8F | F10: 140 | G10: год | H10: =IF(ISNUMBER(G10),IF(G10=0,0,F10*IF(D10=0,1,D10)/G10),IF(G10="неделя",F10*IF(D10=0,1,D10)*52,IF(G10="месяц",F10*IF(D10=0,1,D10)*12,F10*IF(D10=0,1,D10)))) | I10: =IF(H10=0,0,H10/12)
A11: 7 | B11: Пластыри | C11: — | D11: 1 | E11: https://www.eapteka.ru/search/?q=%D0%BF%D0%BB%D0%B0%D1%81%D1%82%D1%8B%D1%80%D1%8C | F11: 99 | G11: год | H11: =IF(ISNUMBER(G11),IF(G11=0,0,F11*IF(D11=0,1,D11)/G11),IF(G11="неделя",F11*IF(D11=0,1,D11)*52,IF(G11="месяц",F11*IF(D11=0,1,D11)*12,F11*IF(D11=0,1,D11)))) | I11: =IF(H11=0,0,H11/12)
A12: 8 | B12: Ушные капли | C12: — | D12: 1 | E12: https://www.eapteka.ru/search/?q=%D1%83%D1%88%D0%BD%D1%8B%D0%B5%20%D0%BA%D0%B0%D0%BF%D0%BB%D0%B8 | F12: 300 | G12: год | H12: =IF(ISNUMBER(G12),IF(G12=0,0,F12*IF(D12=0,1,D12)/G12),IF(G12="неделя",F12*IF(D12=0,1,D12)*52,IF(G12="месяц",F12*IF(D12=0,1,D12)*12,F12*IF(D12=0,1,D12)))) | I12: =IF(H12=0,0,H12/12)
A14: Итого: Лекарства | H14: =H5+H6+H7+H8+H9+H10+H11+H12 | I14: =IF(H14=0,0,H14/12)

Sheet Медицинские услуги
A1: Медицинские услуги
A2: Покупки — ссылка на товар и срок службы. Частое — период. Платежи — без ссылки.
A4: № | B4: Наименование | C4: Назначение | D4: Количество | E4: Ссылка | F4: Стоимость | G4: Период | H4: В год, ₽ | I4: В месяц, ₽
A5: 1 | B5: Лечение зуба | C5: — | D5: 1 | F5: 6000 | G5: год | H5: =IF(ISNUMBER(G5),IF(G5=0,0,F5*IF(D5=0,1,D5)/G5),IF(G5="неделя",F5*IF(D5=0,1,D5)*52,IF(G5="месяц",F5*IF(D5=0,1,D5)*12,F5*IF(D5=0,1,D5)))) | I5: =IF(H5=0,0,H5/12)
A7: Итого: Медицинские услуги | H7: =H5 | I7: =IF(H7=0,0,H7/12)

Sheet Карманные расходы
A1: Карманные
A2: Покупки — ссылка на товар и срок службы. Частое — период. Платежи — без ссылки.
A4: № | B4: Наименование | C4: Назначение | D4: Количество | E4: Стоимость | F4: Период | G4: В год, ₽ | H4: В месяц, ₽
A5: 1 | B5: Карманные расходы | C5: — | D5: 1 | E5: 1000 | F5: неделя | G5: =IF(ISNUMBER(F5),IF(F5=0,0,E5*IF(D5=0,1,D5)/F5),IF(F5="неделя",E5*IF(D5=0,1,D5)*52,IF(F5="месяц",E5*IF(D5=0,1,D5)*12,E5*IF(D5=0,1,D5)))) | H5: =IF(G5=0,0,G5/12)
A7: Итого: Карманные | G7: =G5 | H7: =IF(G7=0,0,G7/12)

Sheet Оборудование расходы
A1: Оборудование
A2: Покупки — ссылка на товар и срок службы. Частое — период. Платежи — без ссылки.
A4: № | B4: Наименование | C4: Назначение | D4: Количество | E4: Стоимость | F4: Период | G4: В год, ₽ | H4: В месяц, ₽
A5: 1 | B5: Оплата мобильного | C5: — | D5: 1 | E5: 300 | F5: месяц | G5: =IF(ISNUMBER(F5),IF(F5=0,0,E5*IF(D5=0,1,D5)/F5),IF(F5="неделя",E5*IF(D5=0,1,D5)*52,IF(F5="месяц",E5*IF(D5=0,1,D5)*12,E5*IF(D5=0,1,D5)))) | H5: =IF(G5=0,0,G5/12)
A7: Итого: Оборудование | G7: =G5 | H7: =IF(G7=0,0,G7/12)

Sheet Образование расходы
A1: Образование
A2: Покупки — ссылка на товар и срок службы. Частое — период. Платежи — без ссылки.
A4: № | B4: Наименование | C4: Назначение | D4: Количество | E4: Стоимость | F4: Срок службы (лет) | G4: В год, ₽ | H4: В месяц, ₽
A5: 1 | B5: Курс английского, Language Secret | C5: — | D5: 12 | E5: 3440 | F5: 1 | G5: =IF(ISNUMBER(F5),IF(F5=0,0,E5*IF(D5=0,1,D5)/F5),IF(F5="неделя",E5*IF(D5=0,1,D5)*52,IF(F5="месяц",E5*IF(D5=0,1,D5)*12,E5*IF(D5=0,1,D5)))) | H5: =IF(G5=0,0,G5/12)
A6: 2 | B6: Питание в школе | C6: — | D6: 170 | E6: 100 | F6: 1 | G6: =IF(ISNUMBER(F6),IF(F6=0,0,E6*IF(D6=0,1,D6)/F6),IF(F6="неделя",E6*IF(D6=0,1,D6)*52,IF(F6="месяц",E6*IF(D6=0,1,D6)*12,E6*IF(D6=0,1,D6)))) | H6: =IF(G6=0,0,G6/12)
A7: 3 | B7: Платный курс (школа) | C7: — | D7: 12 | E7: 300 | F7: 1 | G7: =IF(ISNUMBER(F7),IF(F7=0,0,E7*IF(D7=0,1,D7)/F7),IF(F7="неделя",E7*IF(D7=0,1,D7)*52,IF(F7="месяц",E7*IF(D7=0,1,D7)*12,E7*IF(D7=0,1,D7)))) | H7: =IF(G7=0,0,G7/12)
A8: 4 | B8: Взносы в школу | C8: — | D8: 1 | E8: 3000 | F8: 1 | G8: =IF(ISNUMBER(F8),IF(F8=0,0,E8*IF(D8=0,1,D8)/F8),IF(F8="неделя",E8*IF(D8=0,1,D8)*52,IF(F8="месяц",E8*IF(D8=0,1,D8)*12,E8*IF(D8=0,1,D8)))) | H8: =IF(G8=0,0,G8/12)
A10: Итого: Образование | G10: =G5+G6+G7+G8 | H10: =IF(G10=0,0,G10/12)

Sheet Праздники расходы
A1: Праздники
A2: Покупки — ссылка на товар и срок службы. Частое — период. Платежи — без ссылки.
A4: № | B4: Наименование | C4: Назначение | D4: Количество | E4: Стоимость | F4: Срок службы (лет) | G4: В год, ₽ | H4: В месяц, ₽
A5: 1 | B5: Букет учителю | C5: — | D5: 1 | E5: 2000 | F5: 1 | G5: =IF(ISNUMBER(F5),IF(F5=0,0,E5*IF(D5=0,1,D5)/F5),IF(F5="неделя",E5*IF(D5=0,1,D5)*52,IF(F5="месяц",E5*IF(D5=0,1,D5)*12,E5*IF(D5=0,1,D5)))) | H5: =IF(G5=0,0,G5/12)
A6: 2 | B6: Выпускной | C6: — | D6: 1 | E6: 10000 | F6: 5 | G6: =IF(ISNUMBER(F6),IF(F6=0,0,E6*IF(D6=0,1,D6)/F6),IF(F6="неделя",E6*IF(D6=0,1,D6)*52,IF(F6="месяц",E6*IF(D6=0,1,D6)*12,E6*IF(D6=0,1,D6)))) | H6: =IF(G6=0,0,G6/12)
A7: 3 | B7: День рождения: подарок | C7: — | D7: 1 | E7: 5000 | F7: 1 | G7: =IF(ISNUMBER(F7),IF(F7=0,0,E7*IF(D7=0,1,D7)/F7),IF(F7="неделя",E7*IF(D7=0,1,D7)*52,IF(F7="месяц",E7*IF(D7=0,1,D7)*12,E7*IF(D7=0,1,D7)))) | H7: =IF(G7=0,0,G7/12)
A8: 4 | B8: День рождения: стол | C8: — | D8: 1 | E8: 5000 | F8: 1 | G8: =IF(ISNUMBER(F8),IF(F8=0,0,E8*IF(D8=0,1,D8)/F8),IF(F8="неделя",E8*IF(D8=0,1,D8)*52,IF(F8="месяц",E8*IF(D8=0,1,D8)*12,E8*IF(D8=0,1,D8)))) | H8: =IF(G8=0,0,G8/12)
A9: 5 | B9: Новый год: подарок ребёнку | C9: — | D9: 1 | E9: 5000 | F9: 1 | G9: =IF(ISNUMBER(F9),IF(F9=0,0,E9*IF(D9=0,1,D9)/F9),IF(F9="неделя",E9*IF(D9=0,1,D9)*52,IF(F9="месяц",E9*IF(D9=0,1,D9)*12,E9*IF(D9=0,1,D9)))) | H9: =IF(G9=0,0,G9/12)
A10: 6 | B10: Подарок на 23 февраля | C10: — | D10: 1 | E10: 2000 | F10: 1 | G10: =IF(ISNUMBER(F10),IF(F10=0,0,E10*IF(D10=0,1,D10)/F10),IF(F10="неделя",E10*IF(D10=0,1,D10)*52,IF(F10="месяц",E10*IF(D10=0,1,D10)*12,E10*IF(D10=0,1,D10)))) | H10: =IF(G10=0,0,G10/12)
A11: 7 | B11: Поездки и мероприятия школы | C11: — | D11: 12 | E11: 500 | F11: 1 | G11: =IF(ISNUMBER(F11),IF(F11=0,0,E11*IF(D11=0,1,D11)/F11),IF(F11="неделя",E11*IF(D11=0,1,D11)*52,IF(F11="месяц",E11*IF(D11=0,1,D11)*12,E11*IF(D11=0,1,D11)))) | H11: =IF(G11=0,0,G11/12)
A12: 8 | B12: Хотелочки | C12: — | D12: 12 | E12: 2000 | F12: 1 | G12: =IF(ISNUMBER(F12),IF(F12=0,0,E12*IF(D12=0,1,D12)/F12),IF(F12="неделя",E12*IF(D12=0,1,D12)*52,IF(F12="месяц",E12*IF(D12=0,1,D12)*12,E12*IF(D12=0,1,D12)))) | H12: =IF(G12=0,0,G12/12)
A14: Итого: Праздники | G14: =G5+G6+G7+G8+G9+G10+G11+G12 | H14: =IF(G14=0,0,G14/12)

Sheet Хобби и развлечения расходы
A1: Хобби и развлечения
A2: Покупки — ссылка на товар и срок службы. Частое — период. Платежи — без ссылки.
A4: № | B4: Наименование | C4: Назначение | D4: Количество | E4: Стоимость | F4: Период | G4: В год, ₽ | H4: В месяц, ₽
A5: 1 | B5: Абонемент Олимпия Спорт | C5: — | D5: 1 | E5: 36000 | F5: год | G5: =IF(ISNUMBER(F5),IF(F5=0,0,E5*IF(D5=0,1,D5)/F5),IF(F5="неделя",E5*IF(D5=0,1,D5)*52,IF(F5="месяц",E5*IF(D5=0,1,D5)*12,E5*IF(D5=0,1,D5)))) | H5: =IF(G5=0,0,G5/12)
A6: 2 | B6: Бургер Кинг / кафе | C6: — | D6: 1 | E6: 1100 | F6: неделя | G6: =IF(ISNUMBER(F6),IF(F6=0,0,E6*IF(D6=0,1,D6)/F6),IF(F6="неделя",E6*IF(D6=0,1,D6)*52,IF(F6="месяц",E6*IF(D6=0,1,D6)*12,E6*IF(D6=0,1,D6)))) | H6: =IF(G6=0,0,G6/12)
A7: 3 | B7: Зоопарк | C7: — | D7: 1 | E7: 375 | F7: год | G7: =IF(ISNUMBER(F7),IF(F7=0,0,E7*IF(D7=0,1,D7)/F7),IF(F7="неделя",E7*IF(D7=0,1,D7)*52,IF(F7="месяц",E7*IF(D7=0,1,D7)*12,E7*IF(D7=0,1,D7)))) | H7: =IF(G7=0,0,G7/12)
A8: 4 | B8: Кино | C8: — | D8: 1 | E8: 570 | F8: месяц | G8: =IF(ISNUMBER(F8),IF(F8=0,0,E8*IF(D8=0,1,D8)/F8),IF(F8="неделя",E8*IF(D8=0,1,D8)*52,IF(F8="месяц",E8*IF(D8=0,1,D8)*12,E8*IF(D8=0,1,D8)))) | H8: =IF(G8=0,0,G8/12)
A9: 5 | B9: Поход в цирк | C9: — | D9: 1 | E9: 2250 | F9: год | G9: =IF(ISNUMBER(F9),IF(F9=0,0,E9*IF(D9=0,1,D9)/F9),IF(F9="неделя",E9*IF(D9=0,1,D9)*52,IF(F9="месяц",E9*IF(D9=0,1,D9)*12,E9*IF(D9=0,1,D9)))) | H9: =IF(G9=0,0,G9/12)
A10: 6 | B10: Секция самбо | C10: — | D10: 1 | E10: 4000 | F10: месяц | G10: =IF(ISNUMBER(F10),IF(F10=0,0,E10*IF(D10=0,1,D10)/F10),IF(F10="неделя",E10*IF(D10=0,1,D10)*52,IF(F10="месяц",E10*IF(D10=0,1,D10)*12,E10*IF(D10=0,1,D10)))) | H10: =IF(G10=0,0,G10/12)
A12: Итого: Хобби и развлечения | G12: =G5+G6+G7+G8+G9+G10 | H12: =IF(G12=0,0,G12/12)

Sheet Бытовая косметика покупки
A1: Бытовая косметика
A2: Покупки — ссылка на товар и срок службы. Частое — период. Платежи — без ссылки.
A4: № | B4: Наименование | C4: Назначение | D4: Количество | E4: Ссылка | F4: Стоимость | G4: Период | H4: В год, ₽ | I4: В месяц, ₽
A5: 1 | B5: Ariel Color 6 кг | C5: — | D5: 6 | E5: https://magnit.ru/catalog?q=ariel%20color%206 | F5: 1399 | G5: год | H5: =IF(ISNUMBER(G5),IF(G5=0,0,F5*IF(D5=0,1,D5)/G5),IF(G5="неделя",F5*IF(D5=0,1,D5)*52,IF(G5="месяц",F5*IF(D5=0,1,D5)*12,F5*IF(D5=0,1,D5)))) | I5: =IF(H5=0,0,H5/12)
A6: 2 | B6: Lenor ополаскиватель | C6: — | D6: 6 | E6: https://magnit.ru/catalog?q=lenor | F6: 349 | G6: год | H6: =IF(ISNUMBER(G6),IF(G6=0,0,F6*IF(D6=0,1,D6)/G6),IF(G6="неделя",F6*IF(D6=0,1,D6)*52,IF(G6="месяц",F6*IF(D6=0,1,D6)*12,F6*IF(D6=0,1,D6)))) | I6: =IF(H6=0,0,H6/12)
A7: 3 | B7: Ватные диски | C7: — | D7: 1 | E7: https://magnit.ru/catalog?q=%D0%B2%D0%B0%D1%82%D0%BD%D1%8B%D0%B5%20%D0%B4%D0%B8%D1%81%D0%BA%D0%B8 | F7: 99 | G7: месяц | H7: =IF(ISNUMBER(G7),IF(G7=0,0,F7*IF(D7=0,1,D7)/G7),IF(G7="неделя",F7*IF(D7=0,1,D7)*52,IF(G7="месяц",F7*IF(D7=0,1,D7)*12,F7*IF(D7=0,1,D7)))) | I7: =IF(H7=0,0,H7/12)
A8: 4 | B8: Ватные палочки | C8: — | D8: 1 | E8: https://magnit.ru/catalog?q=%D0%B2%D0%B0%D1%82%D0%BD%D1%8B%D0%B5%20%D0%BF%D0%B0%D0%BB%D0%BE%D1%87%D0%BA%D0%B8 | F8: 89 | G8: месяц | H8: =IF(ISNUMBER(G8),IF(G8=0,0,F8*IF(D8=0,1,D8)/G8),IF(G8="неделя",F8*IF(D8=0,1,D8)*52,IF(G8="месяц",F8*IF(D8=0,1,D8)*12,F8*IF(D8=0,1,D8)))) | I8: =IF(H8=0,0,H8/12)
A9: 5 | B9: Мыло туалетное | C9: — | D9: 1 | E9: https://magnit.ru/catalog?q=%D0%BC%D1%8B%D0%BB%D0%BE%20%D1%82%D1%83%D0%B0%D0%BB%D0%B5%D1%82%D0%BD%D0%BE%D0%B5 | F9: 120 | G9: месяц | H9: =IF(ISNUMBER(G9),IF(G9=0,0,F9*IF(D9=0,1,D9)/G9),IF(G9="неделя",F9*IF(D9=0,1,D9)*52,IF(G9="месяц",F9*IF(D9=0,1,D9)*12,F9*IF(D9=0,1,D9)))) | I9: =IF(H9=0,0,H9/12)
A11: Итого семья | H11: =H5+H6+H7+H8+H9 | I11: =IF(H11=0,0,H11/12)
A12: Итого на ребёнка (÷3) | H12: =H11/3 | I12: =I11/3

Sheet Бытовая посуда покупки
A1: Бытовая посуда
A2: Покупки — ссылка на товар и срок службы. Частое — период. Платежи — без ссылки.
A4: № | B4: Наименование | C4: Назначение | D4: Количество | E4: Ссылка | F4: Стоимость | G4: Срок / период | H4: В год, ₽ | I4: В месяц, ₽
