Workbook

Sheet Как пользоваться
A1: Как пользоваться
A2: Наименование, количество, стоимость. Дальше либо срок службы в годах, либо сколько раз в месяц.
A4: Что | B4: Зачем
A5: Покупка | B5: Срок службы (лет). В год = стоимость × количество ÷ срок ÷ делим.
A6: Продукты и секции | B6: Период: неделя / месяц / год. В год = стоимость × количество × 52 / 12 / 1.
A7: Делим = 1 | B7: Целиком на этого ребёнка.
A8: Делим = 3 | B8: Общее на семью.
A9: Строки | B9: Внутри блока по алфавиту.

Sheet Сводка
A1: Сводка — один ребёнок
A4: Блок | B4: В год, ₽ | C4: В месяц, ₽
A5: Аксессуары покупки | B5: ='Аксессуары покупки'!G16 | C5: ='Аксессуары покупки'!H16
A6: Бельё покупки | B6: ='Бельё покупки'!G11 | C6: ='Бельё покупки'!H11
A7: Верхняя одежда покупки | B7: ='Верхняя одежда покупки'!G11 | C7: ='Верхняя одежда покупки'!H11
A8: Комната покупки | B8: ='Комната покупки'!G25 | C8: ='Комната покупки'!H25
A9: Оборудование покупки | B9: ='Оборудование покупки'!G15 | C9: ='Оборудование покупки'!H15
A10: Обувь покупки | B10: ='Обувь покупки'!G13 | C10: ='Обувь покупки'!H13
A11: Одежда второго слоя покупки | B11: ='Одежда второго слоя покупки'!G15 | C11: ='Одежда второго слоя покупки'!H15
A12: Предметы личного пользования по | B12: ='Предметы личного пользования по'!G22 | C12: ='Предметы личного пользования по'!H22
A13: Продукты питания покупки | B13: ='Продукты питания покупки'!G7 | C13: ='Продукты питания покупки'!H7
A14: Спорт и досуг покупки | B14: ='Спорт и досуг покупки'!G21 | C14: ='Спорт и досуг покупки'!H21
A15: Школа и образование покупки | B15: ='Школа и образование покупки'!G52 | C15: ='Школа и образование покупки'!H52
A16: Лекарства | B16: ='Лекарства'!G14 | C16: ='Лекарства'!H14
A17: Медицинские услуги | B17: ='Медицинские услуги'!G7 | C17: ='Медицинские услуги'!H7
A18: Карманные расходы | B18: ='Карманные расходы'!F7 | C18: ='Карманные расходы'!G7
A19: Оборудование расходы | B19: ='Оборудование расходы'!F7 | C19: ='Оборудование расходы'!G7
A20: Праздники расходы | B20: ='Праздники расходы'!F14 | C20: ='Праздники расходы'!G14
A21: Хобби и развлечения расходы | B21: ='Хобби и развлечения расходы'!F12 | C21: ='Хобби и развлечения расходы'!G12
A22: Бытовая косметика покупки | B22: ='Бытовая косметика покупки'!G12 | C22: ='Бытовая косметика покупки'!H12
A23: Бытовая посуда покупки | B23: ='Бытовая посуда покупки'!G23 | C23: ='Бытовая посуда покупки'!H23
A24: Бытовая техника покупки | B24: ='Бытовая техника покупки'!G20 | C24: ='Бытовая техника покупки'!H20
A25: Мебель и хозяйство покупки | B25: ='Мебель и хозяйство покупки'!G18 | C25: ='Мебель и хозяйство покупки'!H18
A26: Праздники покупки | B26: ='Праздники покупки'!G9 | C26: ='Праздники покупки'!H9
A27: Аренда и коммунальные платежи р | B27: ='Аренда и коммунальные платежи р'!E11 | C27: ='Аренда и коммунальные платежи р'!F11
A28: Хобби и развлечения расходы 2 | B28: ='Хобби и развлечения расходы 2'!F9 | C28: ='Хобби и развлечения расходы 2'!G9
A29: Транспорт расходы | B29: ='Транспорт расходы'!E15 | C29: ='Транспорт расходы'!F15
A30: СОДЕРЖАНИЕ РЕБЁНКА | B30: =SUM(B5:B29) | C30: =SUM(C5:C29)

Sheet Группы диаграммы
A1: Группы диаграммы
A2: Расход на диаграмме и блоки, которые в него входят.
A4: Расход | B4: Состав блоков
A5: Одежда, обувь и аксессуары | B5: Бельё; Одежда второго слоя; Верхняя одежда; Обувь; Аксессуары
A6: Комната и оборудование | B6: Комната; Оборудование
A7: Предметы личного пользования | B7: Предметы личного пользования
A8: Продукты питания | B8: Продукты питания
A9: Спорт и досуг | B9: Спорт и досуг
A10: Школа и образование | B10: Школа и образование
A11: Лекарства | B11: Лекарства
A12: Медицинские услуги | B12: Медицинские услуги
A13: Карманные | B13: Карманные
A14: Оборудование | B14: Оборудование
A15: Праздники | B15: Праздники
... A24: Транспорт | B24: Транспорт

Sheet Аксессуары покупки
A1: Аксессуары
A2: Покупки — ссылка на товар и срок службы. Частое — период. Платежи — без ссылки.
A4: № | B4: Наименование | C4: Количество | D4: Ссылка | E4: Стоимость | F4: Срок службы (лет) | G4: В год, ₽ | H4: В месяц, ₽
A5: 1 | B5: Бейсболка | C5: 2 | D5: https://www.detmir.ru/search/results/?qt=%D0%B1%D0%B5%D0%B9%D1%81%D0%B1%D0%BE%D0%BB%D0%BA%D0%B0 | E5: 399 | F5: 2 | G5: =IF(ISNUMBER(F5),IF(F5=0,0,E5*IF(C5=0,1,C5)/F5),IF(F5="неделя",E5*IF(C5=0,1,C5)*52,IF(F5="месяц",E5*IF(C5=0,1,C5)*12,E5*IF(C5=0,1,C5)))) | H5: =IF(G5=0,0,G5/12)
A6: 2 | B6: Зонт или дождевик | C6: 1 | D6: https://www.detmir.ru/search/results/?qt=%D0%B4%D0%BE%D0%B6%D0%B4%D0%B5%D0%B2%D0%B8%D0%BA%20%D0%B4%D0%B5%D1%82%D1%81%D0%BA%D0%B8%D0%B9 | E6: 699 | F6: 2 | G6: =IF(ISNUMBER(F6),IF(F6=0,0,E6*IF(C6=0,1,C6)/F6),IF(F6="неделя",E6*IF(C6=0,1,C6)*52,IF(F6="месяц",E6*IF(C6=0,1,C6)*12,E6*IF(C6=0,1,C6)))) | H6: =IF(G6=0,0,G6/12)
A7: 3 | B7: Перчатки зимние | C7: 1 | D7: https://www.detmir.ru/search/results/?qt=%D0%BF%D0%B5%D1%80%D1%87%D0%B0%D1%82%D0%BA%D0%B8%20%D0%B7%D0%B8%D0%BC%D0%BD%D0%B8%D0%B5 | E7: 599 | F7: 2 | G7: =IF(ISNUMBER(F7),IF(F7=0,0,E7*IF(C7=0,1,C7)/F7),IF(F7="неделя",E7*IF(C7=0,1,C7)*52,IF(F7="месяц",E7*IF(C7=0,1,C7)*12,E7*IF(C7=0,1,C7)))) | H7: =IF(G7=0,0,G7/12)
A8: 4 | B8: Перчатки осенние | C8: 1 | D8: https://www.detmir.ru/search/results/?qt=%D0%BF%D0%B5%D1%80%D1%87%D0%B0%D1%82%D0%BA%D0%B8 | E8: 399 | F8: 2 | G8: =IF(ISNUMBER(F8),IF(F8=0,0,E8*IF(C8=0,1,C8)/F8),IF(F8="неделя",E8*IF(C8=0,1,C8)*52,IF(F8="месяц",E8*IF(C8=0,1,C8)*12,E8*IF(C8=0,1,C8)))) | H8: =IF(G8=0,0,G8/12)
A9: 5 | B9: Солнечные очки | C9: 1 | D9: https://www.detmir.ru/search/results/?qt=PlayToday%20%D0%BE%D1%87%D0%BA%D0%B8 | E9: 799 | F9: 2 | G9: =IF(ISNUMBER(F9),IF(F9=0,0,E9*IF(C9=0,1,C9)/F9),IF(F9="неделя",E9*IF(C9=0,1,C9)*52,IF(F9="месяц",E9*IF(C9=0,1,C9)*12,E9*IF(C9=0,1,C9)))) | H9: =IF(G9=0,0,G9/12)
A10: 6 | B10: Сумка для коньков | C10: 1 | D10: https://www.detmir.ru/search/results/?qt=%D1%81%D1%83%D0%BC%D0%BA%D0%B0%20%D0%B4%D0%BB%D1%8F%20%D0%BA%D0%BE%D0%BD%D1%8C%D0%BA%D0%BE%D0%B2 | E10: 1100 | F10: 3 | G10: =IF(ISNUMBER(F10),IF(F10=0,0,E10*IF(C10=0,1,C10)/F10),IF(F10="неделя",E10*IF(C10=0,1,C10)*52,IF(F10="месяц",E10*IF(C10=0,1,C10)*12,E10*IF(C10=0,1,C10)))) | H10: =IF(G10=0,0,G10/12)
A11: 7 | B11: Сумка для самбо | C11: 1 | D11: https://www.detmir.ru/search/results/?qt=%D1%81%D0%BF%D0%BE%D1%80%D1%82%D0%B8%D0%B2%D0%BD%D0%B0%D1%8F%20%D1%81%D1%83%D0%BC%D0%BA%D0%B0 | E11: 1499 | F11: 3 | G11: =IF(ISNUMBER(F11),IF(F11=0,0,E11*IF(C11=0,1,C11)/F11),IF(F11="неделя",E11*IF(C11=0,1,C11)*52,IF(F11="месяц",E11*IF(C11=0,1,C11)*12,E11*IF(C11=0,1,C11)))) | H11: =IF(G11=0,0,G11/12)
A12: 8 | B12: Шапка зимняя | C12: 1 | D12: https://www.detmir.ru/search/results/?qt=%D1%88%D0%B0%D0%BF%D0%BA%D0%B0%20%D0%B7%D0%B8%D0%BC%D0%BD%D1%8F%D1%8F | E12: 699 | F12: 2 | G12: =IF(ISNUMBER(F12),IF(F12=0,0,E12*IF(C12=0,1,C12)/F12),IF(F12="неделя",E12*IF(C12=0,1,C12)*52,IF(F12="месяц",E12*IF(C12=0,1,C12)*12,E12*IF(C12=0,1,C12)))) | H12: =IF(G12=0,0,G12/12)
A13: 9 | B13: Шапка осенняя | C13: 1 | D13: https://www.detmir.ru/search/results/?qt=%D1%88%D0%B0%D0%BF%D0%BA%D0%B0%20%D0%BE%D1%81%D0%B5%D0%BD%D0%BD%D1%8F%D1%8F | E13: 499 | F13: 2 | G13: =IF(ISNUMBER(F13),IF(F13=0,0,E13*IF(C13=0,1,C13)/F13),IF(F13="неделя",E13*IF(C13=0,1,C13)*52,IF(F13="месяц",E13*IF(C13=0,1,C13)*12,E13*IF(C13=0,1,C13)))) | H13: =IF(G13=0,0,G13/12)
A14: 10 | B14: Шарф | C14: 1 | D14: https://www.detmir.ru/search/results/?qt=%D1%88%D0%B0%D1%80%D1%84 | E14: 399 | F14: 2 | G14: =IF(ISNUMBER(F14),IF(F14=0,0,E14*IF(C14=0,1,C14)/F14),IF(F14="неделя",E14*IF(C14=0,1,C14)*52,IF(F14="месяц",E14*IF(C14=0,1,C14)*12,E14*IF(C14=0,1,C14)))) | H14: =IF(G14=0,0,G14/12)
A16: Итого: Аксессуары | G16: =G5+G6+G7+G8+G9+G10+G11+G12+G13+G14 | H16: =IF(G16=0,0,G16/12)

Sheet Бельё покупки
A1: Бельё
A2: Покупки — ссылка на товар и срок службы. Частое — период. Платежи — без ссылки.
A4: № | B4: Наименование | C4: Количество | D4: Ссылка | E4: Стоимость | F4: Срок службы (лет) | G4: В год, ₽ | H4: В месяц, ₽
A5: 1 | B5: Майка | C5: 5 | D5: https://www.detmir.ru/product/index/id/6733145/ | E5: 399 | F5: 1 | G5: =IF(ISNUMBER(F5),IF(F5=0,0,E5*IF(C5=0,1,C5)/F5),IF(F5="неделя",E5*IF(C5=0,1,C5)*52,IF(F5="месяц",E5*IF(C5=0,1,C5)*12,E5*IF(C5=0,1,C5)))) | H5: =IF(G5=0,0,G5/12)
A6: 2 | B6: Носки обычные, набор 5 пар | C6: 1 | D6: https://www.detmir.ru/product/index/id/6550049/ | E6: 399 | F6: 1 | G6: =IF(ISNUMBER(F6),IF(F6=0,0,E6*IF(C6=0,1,C6)/F6),IF(F6="неделя",E6*IF(C6=0,1,C6)*52,IF(F6="месяц",E6*IF(C6=0,1,C6)*12,E6*IF(C6=0,1,C6)))) | H6: =IF(G6=0,0,G6/12)
A7: 3 | B7: Носки утеплённые | C7: 2 | D7: https://www.detmir.ru/search/results/?qt=%D0%BD%D0%BE%D1%81%D0%BA%D0%B8%20%D0%B7%D0%B8%D0%BC%D0%BD%D0%B8%D0%B5%20%D0%B4%D0%B5%D1%82%D1%81%D0%BA%D0%B8%D0%B5 | E7: 399 | F7: 1 | G7: =IF(ISNUMBER(F7),IF(F7=0,0,E7*IF(C7=0,1,C7)/F7),IF(F7="неделя",E7*IF(C7=0,1,C7)*52,IF(F7="месяц",E7*IF(C7=0,1,C7)*12,E7*IF(C7=0,1,C7)))) | H7: =IF(G7=0,0,G7/12)
A8: 4 | B8: Термобельё, комплект | C8: 1 | D8: https://www.detmir.ru/search/results/?qt=%D1%82%D0%B5%D1%80%D0%BC%D0%BE%D0%B1%D0%B5%D0%BB%D1%8C%D0%B5 | E8: 1499 | F8: 1 | G8: =IF(ISNUMBER(F8),IF(F8=0,0,E8*IF(C8=0,1,C8)/F8),IF(F8="неделя",E8*IF(C8=0,1,C8)*52,IF(F8="месяц",E8*IF(C8=0,1,C8)*12,E8*IF(C8=0,1,C8)))) | H8: =IF(G8=0,0,G8/12)
A9: 5 | B9: Трусы, набор 5 шт. | C9: 1 | D9: https://www.detmir.ru/product/index/id/7072737/ | E9: 799 | F9: 1 | G9: =IF(ISNUMBER(F9),IF(F9=0,0,E9*IF(C9=0,1,C9)/F9),IF(F9="неделя",E9*IF(C9=0,1,C9)*52,IF(F9="месяц",E9*IF(C9=0,1,C9)*12,E9*IF(C9=0,1,C9)))) | H9: =IF(G9=0,0,G9/12)
A11: Итого: Бельё | G11: =G5+G6+G7+G8+G9 | H11: =IF(G11=0,0,G11/12)

Sheet Верхняя одежда покупки
A1: Верхняя одежда
A2: Покупки — ссылка на товар и срок службы. Частое — период. Платежи — без ссылки.
A4: № | B4: Наименование | C4: Количество | D4: Ссылка | E4: Стоимость | F4: Срок службы (лет) | G4: В год, ₽ | H4: В месяц, ₽
A5: 1 | B5: Ветровка | C5: 1 | D5: https://www.detmir.ru/product/index/id/6022408/ | E5: 1299 | F5: 2 | G5: =IF(ISNUMBER(F5),IF(F5=0,0,E5*IF(C5=0,1,C5)/F5),IF(F5="неделя",E5*IF(C5=0,1,C5)*52,IF(F5="месяц",E5*IF(C5=0,1,C5)*12,E5*IF(C5=0,1,C5)))) | H5: =IF(G5=0,0,G5/12)
A6: 2 | B6: Куртка зимняя | C6: 2 | D6: https://www.detmir.ru/product/index/id/7061634/ | E6: 4292 | F6: 2 | G6: =IF(ISNUMBER(F6),IF(F6=0,0,E6*IF(C6=0,1,C6)/F6),IF(F6="неделя",E6*IF(C6=0,1,C6)*52,IF(F6="месяц",E6*IF(C6=0,1,C6)*12,E6*IF(C6=0,1,C6)))) | H6: =IF(G6=0,0,G6/12)
A7: 3 | B7: Куртка осенняя | C7: 1 | D7: https://www.wildberries.ru/brands/orby | E7: 2199 | F7: 2 | G7: =IF(ISNUMBER(F7),IF(F7=0,0,E7*IF(C7=0,1,C7)/F7),IF(F7="неделя",E7*IF(C7=0,1,C7)*52,IF(F7="месяц",E7*IF(C7=0,1,C7)*12,E7*IF(C7=0,1,C7)))) | H7: =IF(G7=0,0,G7/12)
A8: 4 | B8: Куртка осенняя утеплённая | C8: 1 | D8: https://www.detmir.ru/search/results/?qt=%D0%BA%D1%83%D1%80%D1%82%D0%BA%D0%B0%20%D0%BE%D1%81%D0%B5%D0%BD%D0%BD%D1%8F%D1%8F%20%D1%83%D1%82%D0%B5%D0%BF%D0%BB%D0%B5%D0%BD%D0%BD%D0%B0%D1%8F%20%D0%BC%D0%B0%D0%BB%D1%8C%D1%87%D0%B8%D0%BA | E8: 2999 | F8: 2 | G8: =IF(ISNUMBER(F8),IF(F8=0,0,E8*IF(C8=0,1,C8)/F8),IF(F8="неделя",E8*IF(C8=0,1,C8)*52,IF(F8="месяц",E8*IF(C8=0,1,C8)*12,E8*IF(C8=0,1,C8)))) | H8: =IF(G8=0,0,G8/12)
A9: 5 | B9: Штаны утеплённые | C9: 1 | D9: https://www.detmir.ru/search/results/?qt=%D1%88%D1%82%D0%B0%D0%BD%D1%8B%20%D1%83%D1%82%D0%B5%D0%BF%D0%BB%D0%B5%D0%BD%D0%BD%D1%8B%D0%B5 | E9: 2499 | F9: 2 | G9: =IF(ISNUMBER(F9),IF(F9=0,0,E9*IF(C9=0,1,C9)/F9),IF(F9="неделя",E9*IF(C9=0,1,C9)*52,IF(F9="месяц",E9*IF(C9=0,1,C9)*12,E9*IF(C9=0,1,C9)))) | H9: =IF(G9=0,0,G9/12)
A11: Итого: Верхняя одежда | G11: =G5+G6+G7+G8+G9 | H11: =IF(G11=0,0,G11/12)

Sheet Комната покупки
A1: Комната
A2: Покупки — ссылка на товар и срок службы. Частое — период. Платежи — без ссылки.
A4: № | B4: Наименование | C4: Количество | D4: Ссылка | E4: Стоимость | F4: Срок службы (лет) | G4: В год, ₽ | H4: В месяц, ₽
A5: 1 | B5: Вуаль / тюль | C5: 1 | D5: https://leroymerlin.ru/catalogue/tyul/ | E5: 1200 | F5: 5 | G5: =IF(ISNUMBER(F5),IF(F5=0,0,E5*IF(C5=0,1,C5)/F5),IF(F5="неделя",E5*IF(C5=0,1,C5)*52,IF(F5="месяц",E5*IF(C5=0,1,C5)*12,E5*IF(C5=0,1,C5)))) | H5: =IF(G5=0,0,G5/12)
A6: 2 | B6: Ковёр на пол | C6: 1 | D6: https://leroymerlin.ru/catalogue/kovry/ | E6: 4000 | F6: 5 | G6: =IF(ISNUMBER(F6),IF(F6=0,0,E6*IF(C6=0,1,C6)/F6),IF(F6="неделя",E6*IF(C6=0,1,C6)*52,IF(F6="месяц",E6*IF(C6=0,1,C6)*12,E6*IF(C6=0,1,C6)))) | H6: =IF(G6=0,0,G6/12)
A7: 3 | B7: Контейнер для игрушек | C7: 1 | D7: https://www.detmir.ru/search/results/?qt=%D0%BA%D0%BE%D0%BD%D1%82%D0%B5%D0%B9%D0%BD%D0%B5%D1%80%20%D0%B4%D0%BB%D1%8F%20%D0%B8%D0%B3%D1%80%D1%83%D1%88%D0%B5%D0%BA | E7: 2500 | F7: 3 | G7: =IF(ISNUMBER(F7),IF(F7=0,0,E7*IF(C7=0,1,C7)/F7),IF(F7="неделя",E7*IF(C7=0,1,C7)*52,IF(F7="месяц",E7*IF(C7=0,1,C7)*12,E7*IF(C7=0,1,C7)))) | H7: =IF(G7=0,0,G7/12)
A8: 4 | B8: Кресло компьютерное | C8: 1 | D8: https://www.detmir.ru/search/results/?qt=%D0%BA%D1%80%D0%B5%D1%81%D0%BB%D0%BE | E8: 4499 | F8: 5 | G8: =IF(ISNUMBER(F8),IF(F8=0,0,E8*IF(C8=0,1,C8)/F8),IF(F8="неделя",E8*IF(C8=0,1,C8)*52,IF(F8="месяц",E8*IF(C8=0,1,C8)*12,E8*IF(C8=0,1,C8)))) | H8: =IF(G8=0,0,G8/12)
A9: 5 | B9: Кресло-мешок | C9: 1 | D9: https://www.detmir.ru/search/results/?qt=%D0%BA%D1%80%D0%B5%D1%81%D0%BB%D0%BE-%D0%BC%D0%B5%D1%88%D0%BE%D0%BA | E9: 5500 | F9: 3 | G9: =IF(ISNUMBER(F9),IF(F9=0,0,E9*IF(C9=0,1,C9)/F9),IF(F9="неделя",E9*IF(C9=0,1,C9)*52,IF(F9="месяц",E9*IF(C9=0,1,C9)*12,E9*IF(C9=0,1,C9)))) | H9: =IF(G9=0,0,G9/12)
A10: 6 | B10: Кровать-машинка | C10: 1 | D10: https://www.avito.ru/ | E10: 30000 | F10: 3 | G10: =IF(ISNUMBER(F10),IF(F10=0,0,E10*IF(C10=0,1,C10)/F10),IF(F10="неделя",E10*IF(C10=0,1,C10)*52,IF(F10="месяц",E10*IF(C10=0,1,C10)*12,E10*IF(C10=0,1,C10)))) | H10: =IF(G10=0,0,G10/12)
A11: 7 | B11: Матрас 80×180 | C11: 1 | D11: https://ormatek.com/catalog/matrasy/80x180/ | E11: 8000 | F11: 8 | G11: =IF(ISNUMBER(F11),IF(F11=0,0,E11*IF(C11=0,1,C11)/F11),IF(F11="неделя",E11*IF(C11=0,1,C11)*52,IF(F11="месяц",E11*IF(C11=0,1,C11)*12,E11*IF(C11=0,1,C11)))) | H11: =IF(G11=0,0,G11/12)
A12: 8 | B12: Настольная лампа | C12: 1 | D12: https://www.detmir.ru/search/results/?qt=%D0%BB%D0%B0%D0%BC%D0%BF%D0%B0 | E12: 1299 | F12: 3 | G12: =IF(ISNUMBER(F12),IF(F12=0,0,E12*IF(C12=0,1,C12)/F12),IF(F12="неделя",E12*IF(C12=0,1,C12)*52,IF(F12="месяц",E12*IF(C12=0,1,C12)*12,E12*IF(C12=0,1,C12)))) | H12: =IF(G12=0,0,G12/12)
A13: 9 | B13: Ночник у кровати | C13: 1 | D13: https://www.detmir.ru/search/results/?qt=%D0%BD%D0%BE%D1%87%D0%BD%D0%B8%D0%BA | E13: 899 | F13: 3 | G13: =IF(ISNUMBER(F13),IF(F13=0,0,E13*IF(C13=0,1,C13)/F13),IF(F13="неделя",E13*IF(C13=0,1,C13)*52,IF(F13="месяц",E13*IF(C13=0,1,C13)*12,E13*IF(C13=0,1,C13)))) | H13: =IF(G13=0,0,G13/12)
A14: 10 | B14: Одеяло | C14: 1 | D14: https://www.detmir.ru/search/results/?qt=%D0%BE%D0%B4%D0%B5%D1%8F%D0%BB%D0%BE | E14: 1500 | F14: 3 | G14: =IF(ISNUMBER(F14),IF(F14=0,0,E14*IF(C14=0,1,C14)/F14),IF(F14="неделя",E14*IF(C14=0,1,C14)*52,IF(F14="месяц",E14*IF(C14=0,1,C14)*12,E14*IF(C14=0,1,C14)))) | H14: =IF(G14=0,0,G14/12)
A15: 11 | B15: Плед / покрывало | C15: 1 | D15: https://www.detmir.ru/search/results/?qt=%D0%BF%D0%BB%D0%B5%D0%B4 | E15: 1999 | F15: 3 | G15: =IF(ISNUMBER(F15),IF(F15=0,0,E15*IF(C15=0,1,C15)/F15),IF(F15="неделя",E15*IF(C15=0,1,C15)*52,IF(F15="месяц",E15*IF(C15=0,1,C15)*12,E15*IF(C15=0,1,C15)))) | H15: =IF(G15=0,0,G15/12)
A16: 12 | B16: Подушка | C16: 1 | D16: https://www.detmir.ru/search/results/?qt=%D0%BF%D0%BE%D0%B4%D1%83%D1%88%D0%BA%D0%B0 | E16: 800 | F16: 3 | G16: =IF(ISNUMBER(F16),IF(F16=0,0,E16*IF(C16=0,1,C16)/F16),IF(F16="неделя",E16*IF(C16=0,1,C16)*52,IF(F16="месяц",E16*IF(C16=0,1,C16)*12,E16*IF(C16=0,1,C16)))) | H16: =IF(G16=0,0,G16/12)
... A23: 19 | B23: Штора | C23: 2 | D23: https://leroymerlin.ru/catalogue/shtory/ | E23: 1200 | F23: 5 | G23: =IF(ISNUMBER(F23),IF(F23=0,0,E23*IF(C23=0,1,C23)/F23),IF(F23="неделя",E23*IF(C23=0,1,C23)*52,IF(F23="месяц",E23*IF(C23=0,1,C23)*12,E23*IF(C23=0,1,C23)))) | H23: =IF(G23=0,0,G23/12)
A25: Итого: Комната | G25: =G5+G6+G7+G8+G9+G10+G11+G12+G13+G14+G15+G16+G17+G18+G19+G20+G21+G22+G23 | H25: =IF(G25=0,0,G25/12)

Sheet Оборудование покупки
A1: Оборудование
A2: Покупки — ссылка на товар и срок службы. Частое — период. Платежи — без ссылки.
A4: № | B4: Наименование | C4: Количество | D4: Ссылка | E4: Стоимость | F4: Срок службы (лет) | G4: В год, ₽ | H4: В месяц, ₽
A5: 1 | B5: Клавиатура | C5: 1 | D5: https://www.dns-shop.ru/catalog/17a8a40216404e77/klaviatury/ | E5: 1499 | F5: 4 | G5: =IF(ISNUMBER(F5),IF(F5=0,0,E5*IF(C5=0,1,C5)/F5),IF(F5="неделя",E5*IF(C5=0,1,C5)*52,IF(F5="месяц",E5*IF(C5=0,1,C5)*12,E5*IF(C5=0,1,C5)))) | H5: =IF(G5=0,0,G5/12)
A6: 2 | B6: Коврик для мыши | C6: 1 | D6: https://www.dns-shop.ru/catalog/17a9f9e316404e77/kovriki-dlya-myshi/ | E6: 299 | F6: 2 | G6: =IF(ISNUMBER(F6),IF(F6=0,0,E6*IF(C6=0,1,C6)/F6),IF(F6="неделя",E6*IF(C6=0,1,C6)*52,IF(F6="месяц",E6*IF(C6=0,1,C6)*12,E6*IF(C6=0,1,C6)))) | H6: =IF(G6=0,0,G6/12)
A7: 3 | B7: Колонки | C7: 1 | D7: https://www.dns-shop.ru/catalog/17a8914916404e77/kompyuternaya-akustika/ | E7: 1499 | F7: 4 | G7: =IF(ISNUMBER(F7),IF(F7=0,0,E7*IF(C7=0,1,C7)/F7),IF(F7="неделя",E7*IF(C7=0,1,C7)*52,IF(F7="месяц",E7*IF(C7=0,1,C7)*12,E7*IF(C7=0,1,C7)))) | H7: =IF(G7=0,0,G7/12)
A8: 4 | B8: Микрофон | C8: 1 | D8: https://www.dns-shop.ru/catalog/17a89bdd16404e77/mikrofoni/ | E8: 1299 | F8: 4 | G8: =IF(ISNUMBER(F8),IF(F8=0,0,E8*IF(C8=0,1,C8)/F8),IF(F8="неделя",E8*IF(C8=0,1,C8)*52,IF(F8="месяц",E8*IF(C8=0,1,C8)*12,E8*IF(C8=0,1,C8)))) | H8: =IF(G8=0,0,G8/12)
A9: 5 | B9: Монитор | C9: 1 | D9: https://www.dns-shop.ru/catalog/17a8943716404e77/monitory/ | E9: 8999 | F9: 4 | G9: =IF(ISNUMBER(F9),IF(F9=0,0,E9*IF(C9=0,1,C9)/F9),IF(F9="неделя",E9*IF(C9=0,1,C9)*52,IF(F9="месяц",E9*IF(C9=0,1,C9)*12,E9*IF(C9=0,1,C9)))) | H9: =IF(G9=0,0,G9/12)
A10: 6 | B10: Мышь | C10: 1 | D10: https://www.dns-shop.ru/catalog/17a8a4d816404e77/myshi/ | E10: 799 | F10: 4 | G10: =IF(ISNUMBER(F10),IF(F10=0,0,E10*IF(C10=0,1,C10)/F10),IF(F10="неделя",E10*IF(C10=0,1,C10)*52,IF(F10="месяц",E10*IF(C10=0,1,C10)*12,E10*IF(C10=0,1,C10)))) | H10: =IF(G10=0,0,G10/12)
A11: 7 | B11: Наушники | C11: 1 | D11: https://www.detmir.ru/search/results/?qt=%D0%BD%D0%B0%D1%83%D1%88%D0%BD%D0%B8%D0%BA%D0%B8 | E11: 1999 | F11: 4 | G11: =IF(ISNUMBER(F11),IF(F11=0,0,E11*IF(C11=0,1,C11)/F11),IF(F11="неделя",E11*IF(C11=0,1,C11)*52,IF(F11="месяц",E11*IF(C11=0,1,C11)*12,E11*IF(C11=0,1,C11)))) | H11: =IF(G11=0,0,G11/12)
A12: 8 | B12: Системный блок | C12: 1 | D12: https://www.avito.ru/ | E12: 23000 | F12: 4 | G12: =IF(ISNUMBER(F12),IF(F12=0,0,E12*IF(C12=0,1,C12)/F12),IF(F12="неделя",E12*IF(C12=0,1,C12)*52,IF(F12="месяц",E12*IF(C12=0,1,C12)*12,E12*IF(C12=0,1,C12)))) | H12: =IF(G12=0,0,G12/12)
A13: 9 | B13: Смартфон | C13: 1 | D13: https://www.avito.ru/ | E13: 5000 | F13: 1 | G13: =IF(ISNUMBER(F13),IF(F13=0,0,E13*IF(C13=0,1,C13)/F13),IF(F13="неделя",E13*IF(C13=0,1,C13)*52,IF(F13="месяц",E13*IF(C13=0,1,C13)*12,E13*IF(C13=0,1,C13)))) | H13: =IF(G13=0,0,G13/12)
A15: Итого: Оборудование | G15: =G5+G6+G7+G8+G9+G10+G11+G12+G13 | H15: =IF(G15=0,0,G15/12)

Sheet Обувь покупки
A1: Обувь
A2: Покупки — ссылка на товар и срок службы. Частое — период. Платежи — без ссылки.
A4: № | B4: Наименование | C4: Количество | D4: Ссылка | E4: Стоимость | F4: Срок службы (лет) | G4: В год, ₽ | H4: В месяц, ₽
A5: 1 | B5: Ботинки зимние | C5: 1 | D5: https://www.detmir.ru/catalog/index/name/botinki_m/sezon_oio-zima/ | E5: 3999 | F5: 1 | G5: =IF(ISNUMBER(F5),IF(F5=0,0,E5*IF(C5=0,1,C5)/F5),IF(F5="неделя",E5*IF(C5=0,1,C5)*52,IF(F5="месяц",E5*IF(C5=0,1,C5)*12,E5*IF(C5=0,1,C5)))) | H5: =IF(G5=0,0,G5/12)
A6: 2 | B6: Ботинки осенние утеплённые | C6: 1 | D6: https://www.detmir.ru/catalog/index/name/botinki_m/sezon_oio-demisezon/ | E6: 2999 | F6: 1 | G6: =IF(ISNUMBER(F6),IF(F6=0,0,E6*IF(C6=0,1,C6)/F6),IF(F6="неделя",E6*IF(C6=0,1,C6)*52,IF(F6="месяц",E6*IF(C6=0,1,C6)*12,E6*IF(C6=0,1,C6)))) | H6: =IF(G6=0,0,G6/12)
A7: 3 | B7: Кроссовки | C7: 1 | D7: https://www.detmir.ru/product/index/id/7076432/ | E7: 2499 | F7: 1 | G7: =IF(ISNUMBER(F7),IF(F7=0,0,E7*IF(C7=0,1,C7)/F7),IF(F7="неделя",E7*IF(C7=0,1,C7)*52,IF(F7="месяц",E7*IF(C7=0,1,C7)*12,E7*IF(C7=0,1,C7)))) | H7: =IF(G7=0,0,G7/12)
A8: 4 | B8: Сандалии летние | C8: 1 | D8: https://www.detmir.ru/catalog/index/name/shoes_for_boys/brand/4112/ | E8: 999 | F8: 1 | G8: =IF(ISNUMBER(F8),IF(F8=0,0,E8*IF(C8=0,1,C8)/F8),IF(F8="неделя",E8*IF(C8=0,1,C8)*52,IF(F8="месяц",E8*IF(C8=0,1,C8)*12,E8*IF(C8=0,1,C8)))) | H8: =IF(G8=0,0,G8/12)
A9: 5 | B9: Сланцы летние | C9: 1 | D9: https://www.detmir.ru/search/results/?qt=%D1%81%D0%BB%D0%B0%D0%BD%D1%86%D1%8B | E9: 499 | F9: 1 | G9: =IF(ISNUMBER(F9),IF(F9=0,0,E9*IF(C9=0,1,C9)/F9),IF(F9="неделя",E9*IF(C9=0,1,C9)*52,IF(F9="месяц",E9*IF(C9=0,1,C9)*12,E9*IF(C9=0,1,C9)))) | H9: =IF(G9=0,0,G9/12)
A10: 6 | B10: Тапочки домашние | C10: 1 | D10: https://www.detmir.ru/search/results/?qt=%D1%82%D0%B0%D0%BF%D0%BE%D1%87%D0%BA%D0%B8 | E10: 599 | F10: 1 | G10: =IF(ISNUMBER(F10),IF(F10=0,0,E10*IF(C10=0,1,C10)/F10),IF(F10="неделя",E10*IF(C10=0,1,C10)*52,IF(F10="месяц",E10*IF(C10=0,1,C10)*12,E10*IF(C10=0,1,C10)))) | H10: =IF(G10=0,0,G10/12)
A11: 7 | B11: Туфли праздничные | C11: 1 | D11: https://www.detmir.ru/product/index/id/7077779/ | E11: 1599 | F11: 1 | G11: =IF(ISNUMBER(F11),IF(F11=0,0,E11*IF(C11=0,1,C11)/F11),IF(F11="неделя",E11*IF(C11=0,1,C11)*52,IF(F11="месяц",E11*IF(C11=0,1,C11)*12,E11*IF(C11=0,1,C11)))) | H11: =IF(G11=0,0,G11/12)
A13: Итого: Обувь | G13: =G5+G6+G7+G8+G9+G10+G11 | H13: =IF(G13=0,0,G13/12)

Sheet Одежда второго слоя покупки
A1: Одежда второго слоя
A2: Покупки — ссылка на товар и срок службы. Частое — период. Платежи — без ссылки.
A4: № | B4: Наименование | C4: Количество | D4: Ссылка | E4: Стоимость | F4: Срок службы (лет) | G4: В год, ₽ | H4: В месяц, ₽
A5: 1 | B5: Брюки праздничные | C5: 1 | D5: https://www.detmir.ru/product/index/id/7069209/ | E5: 1299 | F5: 1 | G5: =IF(ISNUMBER(F5),IF(F5=0,0,E5*IF(C5=0,1,C5)/F5),IF(F5="неделя",E5*IF(C5=0,1,C5)*52,IF(F5="месяц",E5*IF(C5=0,1,C5)*12,E5*IF(C5=0,1,C5)))) | H5: =IF(G5=0,0,G5/12)
A6: 2 | B6: Джинсы | C6: 2 | D6: https://www.detmir.ru/catalog/index/name/detskaya_odezhda/brand/4112/ | E6: 799 | F6: 2 | G6: =IF(ISNUMBER(F6),IF(F6=0,0,E6*IF(C6=0,1,C6)/F6),IF(F6="неделя",E6*IF(C6=0,1,C6)*52,IF(F6="месяц",E6*IF(C6=0,1,C6)*12,E6*IF(C6=0,1,C6)))) | H6: =IF(G6=0,0,G6/12)
A7: 3 | B7: Домашний костюм | C7: 2 | D7: https://www.detmir.ru/search/results/?qt=%D0%B4%D0%BE%D0%BC%D0%B0%D1%88%D0%BD%D0%B8%D0%B9%20%D0%BA%D0%BE%D1%81%D1%82%D1%8E%D0%BC | E7: 1499 | F7: 2 | G7: =IF(ISNUMBER(F7),IF(F7=0,0,E7*IF(C7=0,1,C7)/F7),IF(F7="неделя",E7*IF(C7=0,1,C7)*52,IF(F7="месяц",E7*IF(C7=0,1,C7)*12,E7*IF(C7=0,1,C7)))) | H7: =IF(G7=0,0,G7/12)
A8: 4 | B8: Пиджак праздничный | C8: 1 | D8: https://www.detmir.ru/product/index/id/6643629/ | E8: 2399 | F8: 1 | G8: =IF(ISNUMBER(F8),IF(F8=0,0,E8*IF(C8=0,1,C8)/F8),IF(F8="неделя",E8*IF(C8=0,1,C8)*52,IF(F8="месяц",E8*IF(C8=0,1,C8)*12,E8*IF(C8=0,1,C8)))) | H8: =IF(G8=0,0,G8/12)
A9: 5 | B9: Рубашка праздничная | C9: 1 | D9: https://orby.ru/c/shkolnaya-forma-dlya-malchikov/ | E9: 2000 | F9: 1 | G9: =IF(ISNUMBER(F9),IF(F9=0,0,E9*IF(C9=0,1,C9)/F9),IF(F9="неделя",E9*IF(C9=0,1,C9)*52,IF(F9="месяц",E9*IF(C9=0,1,C9)*12,E9*IF(C9=0,1,C9)))) | H9: =IF(G9=0,0,G9/12)
A10: 6 | B10: Свитер | C10: 2 | D10: https://www.detmir.ru/search/results/?qt=%D1%81%D0%B2%D0%B8%D1%82%D0%B5%D1%80 | E10: 1199 | F10: 2 | G10: =IF(ISNUMBER(F10),IF(F10=0,0,E10*IF(C10=0,1,C10)/F10),IF(F10="неделя",E10*IF(C10=0,1,C10)*52,IF(F10="месяц",E10*IF(C10=0,1,C10)*12,E10*IF(C10=0,1,C10)))) | H10: =IF(G10=0,0,G10/12)
A11: 7 | B11: Футболка | C11: 2 | D11: https://www.wildberries.ru/brands/playtoday | E11: 599 | F11: 1 | G11: =IF(ISNUMBER(F11),IF(F11=0,0,E11*IF(C11=0,1,C11)/F11),IF(F11="неделя",E11*IF(C11=0,1,C11)*52,IF(F11="месяц",E11*IF(C11=0,1,C11)*12,E11*IF(C11=0,1,C11)))) | H11: =IF(G11=0,0,G11/12)
A12: 8 | B12: Худи | C12: 2 | D12: https://www.wildberries.ru/brands/playtoday | E12: 1799 | F12: 2 | G12: =IF(ISNUMBER(F12),IF(F12=0,0,E12*IF(C12=0,1,C12)/F12),IF(F12="неделя",E12*IF(C12=0,1,C12)*52,IF(F12="месяц",E12*IF(C12=0,1,C12)*12,E12*IF(C12=0,1,C12)))) | H12: =IF(G12=0,0,G12/12)
A13: 9 | B13: Шорты летние | C13: 2 | D13: https://www.wildberries.ru/brands/playtoday | E13: 899 | F13: 1 | G13: =IF(ISNUMBER(F13),IF(F13=0,0,E13*IF(C13=0,1,C13)/F13),IF(F13="неделя",E13*IF(C13=0,1,C13)*52,IF(F13="месяц",E13*IF(C13=0,1,C13)*12,E13*IF(C13=0,1,C13)))) | H13: =IF(G13=0,0,G13/12)
A15: Итого: Одежда второго слоя | G15: =G5+G6+G7+G8+G9+G10+G11+G12+G13 | H15: =IF(G15=0,0,G15/12)

Sheet Предметы личного пользования по
A1: Предметы личного пользования
A2: Покупки — ссылка на товар и срок службы. Частое — период. Платежи — без ссылки.
A4: № | B4: Наименование | C4: Количество | D4: Ссылка | E4: Стоимость | F4: Срок службы (лет) | G4: В год, ₽ | H4: В месяц, ₽
A5: 1 | B5: Вилка | C5: 1 | D5: https://www.detmir.ru/search/results/?qt=%D0%B2%D0%B8%D0%BB%D0%BA%D0%B0%20%D0%B4%D0%B5%D1%82%D1%81%D0%BA%D0%B0%D1%8F | E5: 49 | F5: 3 | G5: =IF(ISNUMBER(F5),IF(F5=0,0,E5*IF(C5=0,1,C5)/F5),IF(F5="неделя",E5*IF(C5=0,1,C5)*52,IF(F5="месяц",E5*IF(C5=0,1,C5)*12,E5*IF(C5=0,1,C5)))) | H5: =IF(G5=0,0,G5/12)
A6: 2 | B6: Влажные салфетки | C6: 12 | D6: https://magnit.ru/catalog?q=%D0%B2%D0%BB%D0%B0%D0%B6%D0%BD%D1%8B%D0%B5%20%D1%81%D0%B0%D0%BB%D1%84%D0%B5%D1%82%D0%BA%D0%B8 | E6: 89 | F6: 1 | G6: =IF(ISNUMBER(F6),IF(F6=0,0,E6*IF(C6=0,1,C6)/F6),IF(F6="неделя",E6*IF(C6=0,1,C6)*52,IF(F6="месяц",E6*IF(C6=0,1,C6)*12,E6*IF(C6=0,1,C6)))) | H6: =IF(G6=0,0,G6/12)
A7: 3 | B7: Зубная паста R.O.C.S. | C7: 6 | D7: https://www.okeydostavka.ru/webapp/wcs/stores/servlet/SearchDisplay?searchTerm=R.O.C.S. | E7: 399 | F7: 1 | G7: =IF(ISNUMBER(F7),IF(F7=0,0,E7*IF(C7=0,1,C7)/F7),IF(F7="неделя",E7*IF(C7=0,1,C7)*52,IF(F7="месяц",E7*IF(C7=0,1,C7)*12,E7*IF(C7=0,1,C7)))) | H7: =IF(G7=0,0,G7/12)
A8: 4 | B8: Зубная щётка | C8: 2 | D8: https://www.detmir.ru/search/results/?qt=%D0%B7%D1%83%D0%B1%D0%BD%D0%B0%D1%8F%20%D1%89%D0%B5%D1%82%D0%BA%D0%B0%20%D0%B4%D0%B5%D1%82%D1%81%D0%BA%D0%B0%D1%8F | E8: 149 | F8: 1 | G8: =IF(ISNUMBER(F8),IF(F8=0,0,E8*IF(C8=0,1,C8)/F8),IF(F8="неделя",E8*IF(C8=0,1,C8)*52,IF(F8="месяц",E8*IF(C8=0,1,C8)*12,E8*IF(C8=0,1,C8)))) | H8: =IF(G8=0,0,G8/12)
A9: 5 | B9: Ложка столовая | C9: 1 | D9: https://www.detmir.ru/search/results/?qt=%D0%BB%D0%BE%D0%B6%D0%BA%D0%B0%20%D0%B4%D0%B5%D1%82%D1%81%D0%BA%D0%B0%D1%8F | E9: 49 | F9: 3 | G9: =IF(ISNUMBER(F9),IF(F9=0,0,E9*IF(C9=0,1,C9)/F9),IF(F9="неделя",E9*IF(C9=0,1,C9)*52,IF(F9="месяц",E9*IF(C9=0,1,C9)*12,E9*IF(C9=0,1,C9)))) | H9: =IF(G9=0,0,G9/12)
A10: 6 | B10: Ложка чайная | C10: 1 | D10: https://www.detmir.ru/search/results/?qt=%D0%BB%D0%BE%D0%B6%D0%BA%D0%B0%20%D1%87%D0%B0%D0%B9%D0%BD%D0%B0%D1%8F%20%D0%B4%D0%B5%D1%82%D1%81%D0%BA%D0%B0%D1%8F | E10: 39 | F10: 3 | G10: =IF(ISNUMBER(F10),IF(F10=0,0,E10*IF(C10=0,1,C10)/F10),IF(F10="неделя",E10*IF(C10=0,1,C10)*52,IF(F10="месяц",E10*IF(C10=0,1,C10)*12,E10*IF(C10=0,1,C10)))) | H10: =IF(G10=0,0,G10/12)
A11: 7 | B11: Молочко для тела | C11: 1 | D11: https://magnit.ru/catalog?q=%D0%BC%D0%BE%D0%BB%D0%BE%D1%87%D0%BA%D0%BE%20%D0%B4%D0%BB%D1%8F%20%D1%82%D0%B5%D0%BB%D0%B0%20%D0%B4%D0%B5%D1%82%D1%81%D0%BA%D0%BE%D0%B5 | E11: 299 | F11: 1 | G11: =IF(ISNUMBER(F11),IF(F11=0,0,E11*IF(C11=0,1,C11)/F11),IF(F11="неделя",E11*IF(C11=0,1,C11)*52,IF(F11="месяц",E11*IF(C11=0,1,C11)*12,E11*IF(C11=0,1,C11)))) | H11: =IF(G11=0,0,G11/12)
A12: 8 | B12: Мочалка | C12: 1 | D12: https://www.detmir.ru/search/results/?qt=%D0%BC%D0%BE%D1%87%D0%B0%D0%BB%D0%BA%D0%B0 | E12: 199 | F12: 1 | G12: =IF(ISNUMBER(F12),IF(F12=0,0,E12*IF(C12=0,1,C12)/F12),IF(F12="неделя",E12*IF(C12=0,1,C12)*52,IF(F12="месяц",E12*IF(C12=0,1,C12)*12,E12*IF(C12=0,1,C12)))) | H12: =IF(G12=0,0,G12/12)
A13: 9 | B13: Полотенце банное | C13: 1 | D13: https://www.detmir.ru/search/results/?qt=%D0%BF%D0%BE%D0%BB%D0%BE%D1%82%D0%B5%D0%BD%D1%86%D0%B5%20%D0%B1%D0%B0%D0%BD%D0%BD%D0%BE%D0%B5 | E13: 699 | F13: 1 | G13: =IF(ISNUMBER(F13),IF(F13=0,0,E13*IF(C13=0,1,C13)/F13),IF(F13="неделя",E13*IF(C13=0,1,C13)*52,IF(F13="месяц",E13*IF(C13=0,1,C13)*12,E13*IF(C13=0,1,C13)))) | H13: =IF(G13=0,0,G13/12)
A14: 10 | B14: Полотенце для лица | C14: 2 | D14: https://www.detmir.ru/search/results/?qt=%D0%BF%D0%BE%D0%BB%D0%BE%D1%82%D0%B5%D0%BD%D1%86%D0%B5%20%D0%B4%D0%BB%D1%8F%20%D0%BB%D0%B8%D1%86%D0%B0 | E14: 349 | F14: 1 | G14: =IF(ISNUMBER(F14),IF(F14=0,0,E14*IF(C14=0,1,C14)/F14),IF(F14="неделя",E14*IF(C14=0,1,C14)*52,IF(F14="месяц",E14*IF(C14=0,1,C14)*12,E14*IF(C14=0,1,C14)))) | H14: =IF(G14=0,0,G14/12)
A15: 11 | B15: Тарелка глубокая | C15: 1 | D15: https://www.detmir.ru/search/results/?qt=%D1%82%D0%B0%D1%80%D0%B5%D0%BB%D0%BA%D0%B0%20%D0%B4%D0%B5%D1%82%D1%81%D0%BA%D0%B0%D1%8F | E15: 149 | F15: 3 | G15: =IF(ISNUMBER(F15),IF(F15=0,0,E15*IF(C15=0,1,C15)/F15),IF(F15="неделя",E15*IF(C15=0,1,C15)*52,IF(F15="месяц",E15*IF(C15=0,1,C15)*12,E15*IF(C15=0,1,C15)))) | H15: =IF(G15=0,0,G15/12)
A16: 12 | B16: Тарелка плоская | C16: 1 | D16: https://www.detmir.ru/search/results/?qt=%D1%82%D0%B0%D1%80%D0%B5%D0%BB%D0%BA%D0%B0%20%D0%B4%D0%B5%D1%82%D1%81%D0%BA%D0%B0%D1%8F | E16: 149 | F16: 3 | G16: =IF(ISNUMBER(F16),IF(F16=0,0,E16*IF(C16=0,1,C16)/F16),IF(F16="неделя",E16*IF(C16=0,1,C16)*52,IF(F16="месяц",E16*IF(C16=0,1,C16)*12,E16*IF(C16=0,1,C16)))) | H16: =IF(G16=0,0,G16/12)
... A20: 16 | B20: Шейкер / бутылка | C20: 1 | D20: https://www.detmir.ru/search/results/?qt=%D0%B1%D1%83%D1%82%D1%8B%D0%BB%D0%BA%D0%B0 | E20: 499 | F20: 2 | G20: =IF(ISNUMBER(F20),IF(F20=0,0,E20*IF(C20=0,1,C20)/F20),IF(F20="неделя",E20*IF(C20=0,1,C20)*52,IF(F20="месяц",E20*IF(C20=0,1,C20)*12,E20*IF(C20=0,1,C20)))) | H20: =IF(G20=0,0,G20/12)
A22: Итого: Предметы личного пользования | G22: =G5+G6+G7+G8+G9+G10+G11+G12+G13+G14+G15+G16+G17+G18+G19+G20 | H22: =IF(G22=0,0,G22/12)

Sheet Продукты питания покупки
A1: Продукты питания
A2: Покупки — ссылка на товар и срок службы. Частое — период. Платежи — без ссылки.
A4: № | B4: Наименование | C4: Количество | D4: Ссылка | E4: Стоимость | F4: Период | G4: В год, ₽ | H4: В месяц, ₽
A5: 1 | B5: Продукты на ребёнка | C5: 1 | D5: https://magnit.ru/ | E5: 20000 | F5: месяц | G5: =IF(ISNUMBER(F5),IF(F5=0,0,E5*IF(C5=0,1,C5)/F5),IF(F5="неделя",E5*IF(C5=0,1,C5)*52,IF(F5="месяц",E5*IF(C5=0,1,C5)*12,E5*IF(C5=0,1,C5)))) | H5: =IF(G5=0,0,G5/12)
A7: Итого: Продукты питания | G7: =G5 | H7: =IF(G7=0,0,G7/12)

Sheet Спорт и досуг покупки
A1: Спорт и досуг
A2: Покупки — ссылка на товар и срок службы. Частое — период. Платежи — без ссылки.
A4: № | B4: Наименование | C4: Количество | D4: Ссылка | E4: Стоимость | F4: Срок службы (лет) | G4: В год, ₽ | H4: В месяц, ₽
A5: 1 | B5: Борцовка самбо | C5: 1 | D5: https://rocky-shop.ru/ekipirovka-dlya-edinoborstv/kurtka-dlya-sambo-green-hill-junior-rostovki-160-190-sm-10032.html | E5: 3690 | F5: 2 | G5: =IF(ISNUMBER(F5),IF(F5=0,0,E5*IF(C5=0,1,C5)/F5),IF(F5="неделя",E5*IF(C5=0,1,C5)*52,IF(F5="месяц",E5*IF(C5=0,1,C5)*12,E5*IF(C5=0,1,C5)))) | H5: =IF(G5=0,0,G5/12)
A6: 2 | B6: Бустер автомобильный | C6: 1 | D6: https://www.detmir.ru/search/results/?qt=%D0%B1%D1%83%D1%81%D1%82%D0%B5%D1%80%20%D0%B0%D0%B2%D1%82%D0%BE%D0%BC%D0%BE%D0%B1%D0%B8%D0%BB%D1%8C%D0%BD%D1%8B%D0%B9 | E6: 1999 | F6: 7 | G6: =IF(ISNUMBER(F6),IF(F6=0,0,E6*IF(C6=0,1,C6)/F6),IF(F6="неделя",E6*IF(C6=0,1,C6)*52,IF(F6="месяц",E6*IF(C6=0,1,C6)*12,E6*IF(C6=0,1,C6)))) | H6: =IF(G6=0,0,G6/12)
A7: 3 | B7: Велосипед Stern 24" | C7: 1 | D7: https://market.yandex.ru/search?text=%D0%B2%D0%B5%D0%BB%D0%BE%D1%81%D0%B8%D0%BF%D0%B5%D0%B4%20Stern%2024 | E7: 27999 | F7: 5 | G7: =IF(ISNUMBER(F7),IF(F7=0,0,E7*IF(C7=0,1,C7)/F7),IF(F7="неделя",E7*IF(C7=0,1,C7)*52,IF(F7="месяц",E7*IF(C7=0,1,C7)*12,E7*IF(C7=0,1,C7)))) | H7: =IF(G7=0,0,G7/12)
A8: 4 | B8: Гантель | C8: 2 | D8: https://www.detmir.ru/search/results/?qt=%D0%B3%D0%B0%D0%BD%D1%82%D0%B5%D0%BB%D0%B8%20%D0%B4%D0%B5%D1%82%D1%81%D0%BA%D0%B8%D0%B5 | E8: 365 | F8: 3 | G8: =IF(ISNUMBER(F8),IF(F8=0,0,E8*IF(C8=0,1,C8)/F8),IF(F8="неделя",E8*IF(C8=0,1,C8)*52,IF(F8="месяц",E8*IF(C8=0,1,C8)*12,E8*IF(C8=0,1,C8)))) | H8: =IF(G8=0,0,G8/12)
A9: 5 | B9: Защита голени | C9: 1 | D9: https://karate.ru/shop/catalog/407-perchatki-mma-sinie-kozhzamenitel-combat-sambo-green-hill/ | E9: 2190 | F9: 2 | G9: =IF(ISNUMBER(F9),IF(F9=0,0,E9*IF(C9=0,1,C9)/F9),IF(F9="неделя",E9*IF(C9=0,1,C9)*52,IF(F9="месяц",E9*IF(C9=0,1,C9)*12,E9*IF(C9=0,1,C9)))) | H9: =IF(G9=0,0,G9/12)
A10: 6 | B10: Коньки | C10: 1 | D10: https://www.detmir.ru/search/results/?qt=%D0%BA%D0%BE%D0%BD%D1%8C%D0%BA%D0%B8 | E10: 2999 | F10: 1 | G10: =IF(ISNUMBER(F10),IF(F10=0,0,E10*IF(C10=0,1,C10)/F10),IF(F10="неделя",E10*IF(C10=0,1,C10)*52,IF(F10="месяц",E10*IF(C10=0,1,C10)*12,E10*IF(C10=0,1,C10)))) | H10: =IF(G10=0,0,G10/12)
A11: 7 | B11: Ласты | C11: 1 | D11: https://www.detmir.ru/search/results/?qt=%D0%BB%D0%B0%D1%81%D1%82%D1%8B%20%D0%B4%D0%B5%D1%82%D1%81%D0%BA%D0%B8%D0%B5 | E11: 999 | F11: 2 | G11: =IF(ISNUMBER(F11),IF(F11=0,0,E11*IF(C11=0,1,C11)/F11),IF(F11="неделя",E11*IF(C11=0,1,C11)*52,IF(F11="месяц",E11*IF(C11=0,1,C11)*12,E11*IF(C11=0,1,C11)))) | H11: =IF(G11=0,0,G11/12)
A12: 8 | B12: Мяч футбольный | C12: 1 | D12: https://www.detmir.ru/search/results/?qt=%D0%BC%D1%8F%D1%87%20%D1%84%D1%83%D1%82%D0%B1%D0%BE%D0%BB%D1%8C%D0%BD%D1%8B%D0%B9 | E12: 799 | F12: 2 | G12: =IF(ISNUMBER(F12),IF(F12=0,0,E12*IF(C12=0,1,C12)/F12),IF(F12="неделя",E12*IF(C12=0,1,C12)*52,IF(F12="месяц",E12*IF(C12=0,1,C12)*12,E12*IF(C12=0,1,C12)))) | H12: =IF(G12=0,0,G12/12)
A13: 9 | B13: Надувной круг | C13: 1 | D13: https://www.detmir.ru/search/results/?qt=%D0%BD%D0%B0%D0%B4%D1%83%D0%B2%D0%BD%D0%BE%D0%B9%20%D0%BA%D1%80%D1%83%D0%B3 | E13: 599 | F13: 2 | G13: =IF(ISNUMBER(F13),IF(F13=0,0,E13*IF(C13=0,1,C13)/F13),IF(F13="неделя",E13*IF(C13=0,1,C13)*52,IF(F13="месяц",E13*IF(C13=0,1,C13)*12,E13*IF(C13=0,1,C13)))) | H13: =IF(G13=0,0,G13/12)
A14: 10 | B14: Перчатки для самбо | C14: 1 | D14: https://dantesport.ru/product_info.php?products_id=1207 | E14: 2990 | F14: 2 | G14: =IF(ISNUMBER(F14),IF(F14=0,0,E14*IF(C14=0,1,C14)/F14),IF(F14="неделя",E14*IF(C14=0,1,C14)*52,IF(F14="месяц",E14*IF(C14=0,1,C14)*12,E14*IF(C14=0,1,C14)))) | H14: =IF(G14=0,0,G14/12)
A15: 11 | B15: Плавки | C15: 1 | D15: https://www.detmir.ru/catalog/index/name/plavki/ | E15: 599 | F15: 1 | G15: =IF(ISNUMBER(F15),IF(F15=0,0,E15*IF(C15=0,1,C15)/F15),IF(F15="неделя",E15*IF(C15=0,1,C15)*52,IF(F15="месяц",E15*IF(C15=0,1,C15)*12,E15*IF(C15=0,1,C15)))) | H15: =IF(G15=0,0,G15/12)
A16: 12 | B16: Полотенце для плавания | C16: 1 | D16: https://www.detmir.ru/search/results/?qt=%D0%BF%D0%BE%D0%BB%D0%BE%D1%82%D0%B5%D0%BD%D1%86%D0%B5%20%D0%BF%D0%BB%D0%B0%D0%B2%D0%B0%D0%BD%D0%B8%D0%B5 | E16: 499 | F16: 1 | G16: =IF(ISNUMBER(F16),IF(F16=0,0,E16*IF(C16=0,1,C16)/F16),IF(F16="неделя",E16*IF(C16=0,1,C16)*52,IF(F16="месяц",E16*IF(C16=0,1,C16)*12,E16*IF(C16=0,1,C16)))) | H16: =IF(G16=0,0,G16/12)
... A19: 15 | B19: Шорты для самбо | C19: 1 | D19: https://rocky-shop.ru/ekipirovka-dlya-edinoborstv/detskie-bortscovki-dlya-sambo-green-hill-triumf-odobreny-fias-27458.html | E19: 1990 | F19: 2 | G19: =IF(ISNUMBER(F19),IF(F19=0,0,E19*IF(C19=0,1,C19)/F19),IF(F19="неделя",E19*IF(C19=0,1,C19)*52,IF(F19="месяц",E19*IF(C19=0,1,C19)*12,E19*IF(C19=0,1,C19)))) | H19: =IF(G19=0,0,G19/12)
A21: Итого: Спорт и досуг | G21: =G5+G6+G7+G8+G9+G10+G11+G12+G13+G14+G15+G16+G17+G18+G19 | H21: =IF(G21=0,0,G21/12)

Sheet Школа и образование покупки
A1: Школа и образование
A2: Покупки — ссылка на товар и срок службы. Частое — период. Платежи — без ссылки.
A4: № | B4: Наименование | C4: Количество | D4: Ссылка | E4: Стоимость | F4: Срок службы (лет) | G4: В год, ₽ | H4: В месяц, ₽
A5: 1 | B5: Брюки школьные | C5: 2 | D5: https://www.wildberries.ru/catalog/13454614/detail.aspx | E5: 2000 | F5: 2 | G5: =IF(ISNUMBER(F5),IF(F5=0,0,E5*IF(C5=0,1,C5)/F5),IF(F5="неделя",E5*IF(C5=0,1,C5)*52,IF(F5="месяц",E5*IF(C5=0,1,C5)*12,E5*IF(C5=0,1,C5)))) | H5: =IF(G5=0,0,G5/12)
A6: 2 | B6: Джемпер школьный | C6: 1 | D6: https://www.detmir.ru/product/index/id/7065088/ | E6: 1399 | F6: 2 | G6: =IF(ISNUMBER(F6),IF(F6=0,0,E6*IF(C6=0,1,C6)/F6),IF(F6="неделя",E6*IF(C6=0,1,C6)*52,IF(F6="месяц",E6*IF(C6=0,1,C6)*12,E6*IF(C6=0,1,C6)))) | H6: =IF(G6=0,0,G6/12)
A7: 3 | B7: Жилет школьный | C7: 1 | D7: https://www.detmir.ru/product/index/id/7065103/ | E7: 999 | F7: 2 | G7: =IF(ISNUMBER(F7),IF(F7=0,0,E7*IF(C7=0,1,C7)/F7),IF(F7="неделя",E7*IF(C7=0,1,C7)*52,IF(F7="месяц",E7*IF(C7=0,1,C7)*12,E7*IF(C7=0,1,C7)))) | H7: =IF(G7=0,0,G7/12)
A8: 4 | B8: Рубашка школьная | C8: 2 | D8: https://orby.ru/c/shkolnaya-forma-dlya-malchikov/ | E8: 2000 | F8: 1 | G8: =IF(ISNUMBER(F8),IF(F8=0,0,E8*IF(C8=0,1,C8)/F8),IF(F8="неделя",E8*IF(C8=0,1,C8)*52,IF(F8="месяц",E8*IF(C8=0,1,C8)*12,E8*IF(C8=0,1,C8)))) | H8: =IF(G8=0,0,G8/12)
A9: 5 | B9: Сменная обувь | C9: 1 | D9: https://www.sportmaster.ru/catalog/deti/obuv/krossovki_kedy/ | E9: 1800 | F9: 1 | G9: =IF(ISNUMBER(F9),IF(F9=0,0,E9*IF(C9=0,1,C9)/F9),IF(F9="неделя",E9*IF(C9=0,1,C9)*52,IF(F9="месяц",E9*IF(C9=0,1,C9)*12,E9*IF(C9=0,1,C9)))) | H9: =IF(G9=0,0,G9/12)
A10: 6 | B10: Галстук | C10: 1 | D10: https://www.detmir.ru/catalog/index/name/neckties/ | E10: 299 | F10: 2 | G10: =IF(ISNUMBER(F10),IF(F10=0,0,E10*IF(C10=0,1,C10)/F10),IF(F10="неделя",E10*IF(C10=0,1,C10)*52,IF(F10="месяц",E10*IF(C10=0,1,C10)*12,E10*IF(C10=0,1,C10)))) | H10: =IF(G10=0,0,G10/12)
A11: 7 | B11: Ремень | C11: 1 | D11: https://www.detmir.ru/catalog/index/name/straps/pol-malchik/ | E11: 399 | F11: 2 | G11: =IF(ISNUMBER(F11),IF(F11=0,0,E11*IF(C11=0,1,C11)/F11),IF(F11="неделя",E11*IF(C11=0,1,C11)*52,IF(F11="месяц",E11*IF(C11=0,1,C11)*12,E11*IF(C11=0,1,C11)))) | H11: =IF(G11=0,0,G11/12)
A12: 8 | B12: Рюкзак школьный | C12: 1 | D12: https://www.detmir.ru/product/index/id/6391235/ | E12: 3499 | F12: 3 | G12: =IF(ISNUMBER(F12),IF(F12=0,0,E12*IF(C12=0,1,C12)/F12),IF(F12="неделя",E12*IF(C12=0,1,C12)*52,IF(F12="месяц",E12*IF(C12=0,1,C12)*12,E12*IF(C12=0,1,C12)))) | H12: =IF(G12=0,0,G12/12)
A13: 9 | B13: Сумка для обуви | C13: 1 | D13: https://www.detmir.ru/product/index/id/6622893/ | E13: 269 | F13: 2 | G13: =IF(ISNUMBER(F13),IF(F13=0,0,E13*IF(C13=0,1,C13)/F13),IF(F13="неделя",E13*IF(C13=0,1,C13)*52,IF(F13="месяц",E13*IF(C13=0,1,C13)*12,E13*IF(C13=0,1,C13)))) | H13: =IF(G13=0,0,G13/12)
A14: 10 | B14: Сумка для формы | C14: 1 | D14: https://www.detmir.ru/product/index/id/6037286/ | E14: 319 | F14: 2 | G14: =IF(ISNUMBER(F14),IF(F14=0,0,E14*IF(C14=0,1,C14)/F14),IF(F14="неделя",E14*IF(C14=0,1,C14)*52,IF(F14="месяц",E14*IF(C14=0,1,C14)*12,E14*IF(C14=0,1,C14)))) | H14: =IF(G14=0,0,G14/12)
A15: 11 | B15: Спортивная форма школьная | C15: 1 | D15: https://www.detmir.ru/product/index/id/7069266/ | E15: 1999 | F15: 2 | G15: =IF(ISNUMBER(F15),IF(F15=0,0,E15*IF(C15=0,1,C15)/F15),IF(F15="неделя",E15*IF(C15=0,1,C15)*52,IF(F15="месяц",E15*IF(C15=0,1,C15)*12,E15*IF(C15=0,1,C15)))) | H15: =IF(G15=0,0,G15/12)
A16: 12 | B16: Альбом для рисования | C16: 1 | D16: https://www.detmir.ru/search/results/?qt=%D0%B0%D0%BB%D1%8C%D0%B1%D0%BE%D0%BC | E16: 89 | F16: 1 | G16: =IF(ISNUMBER(F16),IF(F16=0,0,E16*IF(C16=0,1,C16)/F16),IF(F16="неделя",E16*IF(C16=0,1,C16)*52,IF(F16="месяц",E16*IF(C16=0,1,C16)*12,E16*IF(C16=0,1,C16)))) | H16: =IF(G16=0,0,G16/12)
... A46: 42 | B46: Цветная бумага | C46: 1 | D46: https://www.detmir.ru/search/results/?qt=%D1%86%D0%B2%D0%B5%D1%82%D0%BD%D0%B0%D1%8F%20%D0%B1%D1%83%D0%BC%D0%B0%D0%B3%D0%B0 | E46: 69 | F46: 1 | G46: =IF(ISNUMBER(F46),IF(F46=0,0,E46*IF(C46=0,1,C46)/F46),IF(F46="неделя",E46*IF(C46=0,1,C46)*52,IF(F46="месяц",E46*IF(C46=0,1,C46)*12,E46*IF(C46=0,1,C46)))) | H46: =IF(G46=0,0,G46/12)
A47: 43 | B47: Курс английского, Language Secret | C47: 12 | E47: 3440 | F47: 1 | G47: =IF(ISNUMBER(F47),IF(F47=0,0,E47*IF(C47=0,1,C47)/F47),IF(F47="неделя",E47*IF(C47=0,1,C47)*52,IF(F47="месяц",E47*IF(C47=0,1,C47)*12,E47*IF(C47=0,1,C47)))) | H47: =IF(G47=0,0,G47/12)
A48: 44 | B48: Питание в школе | C48: 170 | E48: 100 | F48: 1 | G48: =IF(ISNUMBER(F48),IF(F48=0,0,E48*IF(C48=0,1,C48)/F48),IF(F48="неделя",E48*IF(C48=0,1,C48)*52,IF(F48="месяц",E48*IF(C48=0,1,C48)*12,E48*IF(C48=0,1,C48)))) | H48: =IF(G48=0,0,G48/12)
A49: 45 | B49: Платный курс (школа) | C49: 12 | E49: 300 | F49: 1 | G49: =IF(ISNUMBER(F49),IF(F49=0,0,E49*IF(C49=0,1,C49)/F49),IF(F49="неделя",E49*IF(C49=0,1,C49)*52,IF(F49="месяц",E49*IF(C49=0,1,C49)*12,E49*IF(C49=0,1,C49)))) | H49: =IF(G49=0,0,G49/12)
A50: 46 | B50: Взносы в школу | C50: 1 | E50: 3000 | F50: 1 | G50: =IF(ISNUMBER(F50),IF(F50=0,0,E50*IF(C50=0,1,C50)/F50),IF(F50="неделя",E50*IF(C50=0,1,C50)*52,IF(F50="месяц",E50*IF(C50=0,1,C50)*12,E50*IF(C50=0,1,C50)))) | H50: =IF(G50=0,0,G50/12)
A52: Итого: Школа и образование | G52: =G5+G6+G7+G8+G9+G10+G11+G12+G13+G14+G15+G16+G17+G18+G19+G20+G21+G22+G23+G24+G25+G26+G27+G28+G29+G30+G31+G32+G33+G34+G35+G36+G37+G38+G39+G40+G41+G42+G43+G44+G45+G46+G47+G48+G49+G50 | H52: =IF(G52=0,0,G52/12)

Sheet Лекарства
A1: Лекарства
A2: Покупки — ссылка на товар и срок службы. Частое — период. Платежи — без ссылки.
A4: № | B4: Наименование | C4: Количество | D4: Ссылка | E4: Стоимость | F4: Период | G4: В год, ₽ | H4: В месяц, ₽
A5: 1 | B5: Долфин | C5: 1 | D5: https://www.eapteka.ru/goods/id215357/ | E5: 548 | F5: год | G5: =IF(ISNUMBER(F5),IF(F5=0,0,E5*IF(C5=0,1,C5)/F5),IF(F5="неделя",E5*IF(C5=0,1,C5)*52,IF(F5="месяц",E5*IF(C5=0,1,C5)*12,E5*IF(C5=0,1,C5)))) | H5: =IF(G5=0,0,G5/12)
A6: 2 | B6: Йод | C6: 1 | D6: https://www.eapteka.ru/search/?q=%D0%B9%D0%BE%D0%B4 | E6: 59 | F6: год | G6: =IF(ISNUMBER(F6),IF(F6=0,0,E6*IF(C6=0,1,C6)/F6),IF(F6="неделя",E6*IF(C6=0,1,C6)*52,IF(F6="месяц",E6*IF(C6=0,1,C6)*12,E6*IF(C6=0,1,C6)))) | H6: =IF(G6=0,0,G6/12)
A7: 3 | B7: Макмирор | C7: 9 | D7: https://apteka.magnit.ru/product/7000001484-makmiror_tabletki_200mg_20sht | E7: 1470 | F7: год | G7: =IF(ISNUMBER(F7),IF(F7=0,0,E7*IF(C7=0,1,C7)/F7),IF(F7="неделя",E7*IF(C7=0,1,C7)*52,IF(F7="месяц",E7*IF(C7=0,1,C7)*12,E7*IF(C7=0,1,C7)))) | H7: =IF(G7=0,0,G7/12)
A8: 4 | B8: Називин, 1 флакон | C8: 1 | D8: https://www.eapteka.ru/search/?q=%D0%BD%D0%B0%D0%B7%D0%B8%D0%B2%D0%B8%D0%BD | E8: 340 | F8: год | G8: =IF(ISNUMBER(F8),IF(F8=0,0,E8*IF(C8=0,1,C8)/F8),IF(F8="неделя",E8*IF(C8=0,1,C8)*52,IF(F8="месяц",E8*IF(C8=0,1,C8)*12,E8*IF(C8=0,1,C8)))) | H8: =IF(G8=0,0,G8/12)
A9: 5 | B9: Перекись водорода | C9: 1 | D9: https://www.eapteka.ru/search/?q=%D0%BF%D0%B5%D1%80%D0%B5%D0%BA%D0%B8%D1%81%D1%8C%20%D0%B2%D0%BE%D0%B4%D0%BE%D1%80%D0%BE%D0%B4%D0%B0 | E9: 45 | F9: год | G9: =IF(ISNUMBER(F9),IF(F9=0,0,E9*IF(C9=0,1,C9)/F9),IF(F9="неделя",E9*IF(C9=0,1,C9)*52,IF(F9="месяц",E9*IF(C9=0,1,C9)*12,E9*IF(C9=0,1,C9)))) | H9: =IF(G9=0,0,G9/12)
A10: 6 | B10: Пирантел жидкий | C10: 2 | D10: https://www.eapteka.ru/search/?q=%D0%BF%D0%B8%D1%80%D0%B0%D0%BD%D1%82%D0%B5%D0%BB%20%D1%81%D1%83%D1%81%D0%BF%D0%B5%D0%BD%D0%B7%D0%B8%D1%8F | E10: 140 | F10: год | G10: =IF(ISNUMBER(F10),IF(F10=0,0,E10*IF(C10=0,1,C10)/F10),IF(F10="неделя",E10*IF(C10=0,1,C10)*52,IF(F10="месяц",E10*IF(C10=0,1,C10)*12,E10*IF(C10=0,1,C10)))) | H10: =IF(G10=0,0,G10/12)
A11: 7 | B11: Пластыри | C11: 1 | D11: https://www.eapteka.ru/search/?q=%D0%BF%D0%BB%D0%B0%D1%81%D1%82%D1%8B%D1%80%D1%8C | E11: 99 | F11: год | G11: =IF(ISNUMBER(F11),IF(F11=0,0,E11*IF(C11=0,1,C11)/F11),IF(F11="неделя",E11*IF(C11=0,1,C11)*52,IF(F11="месяц",E11*IF(C11=0,1,C11)*12,E11*IF(C11=0,1,C11)))) | H11: =IF(G11=0,0,G11/12)
A12: 8 | B12: Ушные капли | C12: 1 | D12: https://www.eapteka.ru/search/?q=%D1%83%D1%88%D0%BD%D1%8B%D0%B5%20%D0%BA%D0%B0%D0%BF%D0%BB%D0%B8 | E12: 300 | F12: год | G12: =IF(ISNUMBER(F12),IF(F12=0,0,E12*IF(C12=0,1,C12)/F12),IF(F12="неделя",E12*IF(C12=0,1,C12)*52,IF(F12="месяц",E12*IF(C12=0,1,C12)*12,E12*IF(C12=0,1,C12)))) | H12: =IF(G12=0,0,G12/12)
A14: Итого: Лекарства | G14: =G5+G6+G7+G8+G9+G10+G11+G12 | H14: =IF(G14=0,0,G14/12)

Sheet Медицинские услуги
A1: Медицинские услуги
A2: Покупки — ссылка на товар и срок службы. Частое — период. Платежи — без ссылки.
A4: № | B4: Наименование | C4: Количество | D4: Ссылка | E4: Стоимость | F4: Период | G4: В год, ₽ | H4: В месяц, ₽
A5: 1 | B5: Лечение зуба | C5: 1 | E5: 6000 | F5: год | G5: =IF(ISNUMBER(F5),IF(F5=0,0,E5*IF(C5=0,1,C5)/F5),IF(F5="неделя",E5*IF(C5=0,1,C5)*52,IF(F5="месяц",E5*IF(C5=0,1,C5)*12,E5*IF(C5=0,1,C5)))) | H5: =IF(G5=0,0,G5/12)
A7: Итого: Медицинские услуги | G7: =G5 | H7: =IF(G7=0,0,G7/12)

Sheet Карманные расходы
A1: Карманные
A2: Покупки — ссылка на товар и срок службы. Частое — период. Платежи — без ссылки.
A4: № | B4: Наименование | C4: Количество | D4: Стоимость | E4: Период | F4: В год, ₽ | G4: В месяц, ₽
A5: 1 | B5: Карманные расходы | C5: 1 | D5: 1000 | E5: неделя | F5: =IF(ISNUMBER(E5),IF(E5=0,0,D5*IF(C5=0,1,C5)/E5),IF(E5="неделя",D5*IF(C5=0,1,C5)*52,IF(E5="месяц",D5*IF(C5=0,1,C5)*12,D5*IF(C5=0,1,C5)))) | G5: =IF(F5=0,0,F5/12)
A7: Итого: Карманные | F7: =F5 | G7: =IF(F7=0,0,F7/12)

Sheet Оборудование расходы
A1: Оборудование
A2: Покупки — ссылка на товар и срок службы. Частое — период. Платежи — без ссылки.
A4: № | B4: Наименование | C4: Количество | D4: Стоимость | E4: Период | F4: В год, ₽ | G4: В месяц, ₽
A5: 1 | B5: Оплата мобильного | C5: 1 | D5: 300 | E5: месяц | F5: =IF(ISNUMBER(E5),IF(E5=0,0,D5*IF(C5=0,1,C5)/E5),IF(E5="неделя",D5*IF(C5=0,1,C5)*52,IF(E5="месяц",D5*IF(C5=0,1,C5)*12,D5*IF(C5=0,1,C5)))) | G5: =IF(F5=0,0,F5/12)
A7: Итого: Оборудование | F7: =F5 | G7: =IF(F7=0,0,F7/12)

Sheet Праздники расходы
A1: Праздники
A2: Покупки — ссылка на товар и срок службы. Частое — период. Платежи — без ссылки.
A4: № | B4: Наименование | C4: Количество | D4: Стоимость | E4: Срок службы (лет) | F4: В год, ₽ | G4: В месяц, ₽
A5: 1 | B5: Букет учителю | C5: 1 | D5: 2000 | E5: 1 | F5: =IF(ISNUMBER(E5),IF(E5=0,0,D5*IF(C5=0,1,C5)/E5),IF(E5="неделя",D5*IF(C5=0,1,C5)*52,IF(E5="месяц",D5*IF(C5=0,1,C5)*12,D5*IF(C5=0,1,C5)))) | G5: =IF(F5=0,0,F5/12)
A6: 2 | B6: Выпускной | C6: 1 | D6: 10000 | E6: 5 | F6: =IF(ISNUMBER(E6),IF(E6=0,0,D6*IF(C6=0,1,C6)/E6),IF(E6="неделя",D6*IF(C6=0,1,C6)*52,IF(E6="месяц",D6*IF(C6=0,1,C6)*12,D6*IF(C6=0,1,C6)))) | G6: =IF(F6=0,0,F6/12)
A7: 3 | B7: День рождения: подарок | C7: 1 | D7: 5000 | E7: 1 | F7: =IF(ISNUMBER(E7),IF(E7=0,0,D7*IF(C7=0,1,C7)/E7),IF(E7="неделя",D7*IF(C7=0,1,C7)*52,IF(E7="месяц",D7*IF(C7=0,1,C7)*12,D7*IF(C7=0,1,C7)))) | G7: =IF(F7=0,0,F7/12)
A8: 4 | B8: День рождения: стол | C8: 1 | D8: 5000 | E8: 1 | F8: =IF(ISNUMBER(E8),IF(E8=0,0,D8*IF(C8=0,1,C8)/E8),IF(E8="неделя",D8*IF(C8=0,1,C8)*52,IF(E8="месяц",D8*IF(C8=0,1,C8)*12,D8*IF(C8=0,1,C8)))) | G8: =IF(F8=0,0,F8/12)
A9: 5 | B9: Новый год: подарок ребёнку | C9: 1 | D9: 5000 | E9: 1 | F9: =IF(ISNUMBER(E9),IF(E9=0,0,D9*IF(C9=0,1,C9)/E9),IF(E9="неделя",D9*IF(C9=0,1,C9)*52,IF(E9="месяц",D9*IF(C9=0,1,C9)*12,D9*IF(C9=0,1,C9)))) | G9: =IF(F9=0,0,F9/12)
A10: 6 | B10: Подарок на 23 февраля | C10: 1 | D10: 2000 | E10: 1 | F10: =IF(ISNUMBER(E10),IF(E10=0,0,D10*IF(C10=0,1,C10)/E10),IF(E10="неделя",D10*IF(C10=0,1,C10)*52,IF(E10="месяц",D10*IF(C10=0,1,C10)*12,D10*IF(C10=0,1,C10)))) | G10: =IF(F10=0,0,F10/12)
A11: 7 | B11: Поездки и мероприятия школы | C11: 12 | D11: 500 | E11: 1 | F11: =IF(ISNUMBER(E11),IF(E11=0,0,D11*IF(C11=0,1,C11)/E11),IF(E11="неделя",D11*IF(C11=0,1,C11)*52,IF(E11="месяц",D11*IF(C11=0,1,C11)*12,D11*IF(C11=0,1,C11)))) | G11: =IF(F11=0,0,F11/12)
A12: 8 | B12: Хотелочки | C12: 12 | D12: 2000 | E12: 1 | F12: =IF(ISNUMBER(E12),IF(E12=0,0,D12*IF(C12=0,1,C12)/E12),IF(E12="неделя",D12*IF(C12=0,1,C12)*52,IF(E12="месяц",D12*IF(C12=0,1,C12)*12,D12*IF(C12=0,1,C12)))) | G12: =IF(F12=0,0,F12/12)
A14: Итого: Праздники | F14: =F5+F6+F7+F8+F9+F10+F11+F12 | G14: =IF(F14=0,0,F14/12)

Sheet Хобби и развлечения расходы
A1: Хобби и развлечения
A2: Покупки — ссылка на товар и срок службы. Частое — период. Платежи — без ссылки.
A4: № | B4: Наименование | C4: Количество | D4: Стоимость | E4: Период | F4: В год, ₽ | G4: В месяц, ₽
A5: 1 | B5: Абонемент Олимпия Спорт | C5: 1 | D5: 36000 | E5: год | F5: =IF(ISNUMBER(E5),IF(E5=0,0,D5*IF(C5=0,1,C5)/E5),IF(E5="неделя",D5*IF(C5=0,1,C5)*52,IF(E5="месяц",D5*IF(C5=0,1,C5)*12,D5*IF(C5=0,1,C5)))) | G5: =IF(F5=0,0,F5/12)
A6: 2 | B6: Бургер Кинг / кафе | C6: 1 | D6: 1100 | E6: неделя | F6: =IF(ISNUMBER(E6),IF(E6=0,0,D6*IF(C6=0,1,C6)/E6),IF(E6="неделя",D6*IF(C6=0,1,C6)*52,IF(E6="месяц",D6*IF(C6=0,1,C6)*12,D6*IF(C6=0,1,C6)))) | G6: =IF(F6=0,0,F6/12)
A7: 3 | B7: Зоопарк | C7: 1 | D7: 375 | E7: год | F7: =IF(ISNUMBER(E7),IF(E7=0,0,D7*IF(C7=0,1,C7)/E7),IF(E7="неделя",D7*IF(C7=0,1,C7)*52,IF(E7="месяц",D7*IF(C7=0,1,C7)*12,D7*IF(C7=0,1,C7)))) | G7: =IF(F7=0,0,F7/12)
A8: 4 | B8: Кино | C8: 1 | D8: 570 | E8: месяц | F8: =IF(ISNUMBER(E8),IF(E8=0,0,D8*IF(C8=0,1,C8)/E8),IF(E8="неделя",D8*IF(C8=0,1,C8)*52,IF(E8="месяц",D8*IF(C8=0,1,C8)*12,D8*IF(C8=0,1,C8)))) | G8: =IF(F8=0,0,F8/12)
A9: 5 | B9: Поход в цирк | C9: 1 | D9: 2250 | E9: год | F9: =IF(ISNUMBER(E9),IF(E9=0,0,D9*IF(C9=0,1,C9)/E9),IF(E9="неделя",D9*IF(C9=0,1,C9)*52,IF(E9="месяц",D9*IF(C9=0,1,C9)*12,D9*IF(C9=0,1,C9)))) | G9: =IF(F9=0,0,F9/12)
A10: 6 | B10: Секция самбо | C10: 1 | D10: 4000 | E10: месяц | F10: =IF(ISNUMBER(E10),IF(E10=0,0,D10*IF(C10=0,1,C10)/E10),IF(E10="неделя",D10*IF(C10=0,1,C10)*52,IF(E10="месяц",D10*IF(C10=0,1,C10)*12,D10*IF(C10=0,1,C10)))) | G10: =IF(F10=0,0,F10/12)
A12: Итого: Хобби и развлечения | F12: =F5+F6+F7+F8+F9+F10 | G12: =IF(F12=0,0,F12/12)

Sheet Бытовая косметика покупки
A1: Бытовая косметика
A2: Покупки — ссылка на товар и срок службы. Частое — период. Платежи — без ссылки.
A4: № | B4: Наименование | C4: Количество | D4: Ссылка | E4: Стоимость | F4: Период | G4: В год, ₽ | H4: В месяц, ₽
A5: 1 | B5: Ariel Color 6 кг | C5: 6 | D5: https://magnit.ru/catalog?q=ariel%20color%206 | E5: 1399 | F5: год | G5: =IF(ISNUMBER(F5),IF(F5=0,0,E5*IF(C5=0,1,C5)/F5),IF(F5="неделя",E5*IF(C5=0,1,C5)*52,IF(F5="месяц",E5*IF(C5=0,1,C5)*12,E5*IF(C5=0,1,C5)))) | H5: =IF(G5=0,0,G5/12)
A6: 2 | B6: Lenor ополаскиватель | C6: 6 | D6: https://magnit.ru/catalog?q=lenor | E6: 349 | F6: год | G6: =IF(ISNUMBER(F6),IF(F6=0,0,E6*IF(C6=0,1,C6)/F6),IF(F6="неделя",E6*IF(C6=0,1,C6)*52,IF(F6="месяц",E6*IF(C6=0,1,C6)*12,E6*IF(C6=0,1,C6)))) | H6: =IF(G6=0,0,G6/12)
A7: 3 | B7: Ватные диски | C7: 1 | D7: https://magnit.ru/catalog?q=%D0%B2%D0%B0%D1%82%D0%BD%D1%8B%D0%B5%20%D0%B4%D0%B8%D1%81%D0%BA%D0%B8 | E7: 99 | F7: месяц | G7: =IF(ISNUMBER(F7),IF(F7=0,0,E7*IF(C7=0,1,C7)/F7),IF(F7="неделя",E7*IF(C7=0,1,C7)*52,IF(F7="месяц",E7*IF(C7=0,1,C7)*12,E7*IF(C7=0,1,C7)))) | H7: =IF(G7=0,0,G7/12)
A8: 4 | B8: Ватные палочки | C8: 1 | D8: https://magnit.ru/catalog?q=%D0%B2%D0%B0%D1%82%D0%BD%D1%8B%D0%B5%20%D0%BF%D0%B0%D0%BB%D0%BE%D1%87%D0%BA%D0%B8 | E8: 89 | F8: месяц | G8: =IF(ISNUMBER(F8),IF(F8=0,0,E8*IF(C8=0,1,C8)/F8),IF(F8="неделя",E8*IF(C8=0,1,C8)*52,IF(F8="месяц",E8*IF(C8=0,1,C8)*12,E8*IF(C8=0,1,C8)))) | H8: =IF(G8=0,0,G8/12)
A9: 5 | B9: Мыло туалетное | C9: 1 | D9: https://magnit.ru/catalog?q=%D0%BC%D1%8B%D0%BB%D0%BE%20%D1%82%D1%83%D0%B0%D0%BB%D0%B5%D1%82%D0%BD%D0%BE%D0%B5 | E9: 120 | F9: месяц | G9: =IF(ISNUMBER(F9),IF(F9=0,0,E9*IF(C9=0,1,C9)/F9),IF(F9="неделя",E9*IF(C9=0,1,C9)*52,IF(F9="месяц",E9*IF(C9=0,1,C9)*12,E9*IF(C9=0,1,C9)))) | H9: =IF(G9=0,0,G9/12)
A11: Итого семья | G11: =G5+G6+G7+G8+G9 | H11: =IF(G11=0,0,G11/12)
A12: Итого на ребёнка (÷3) | G12: =G11/3 | H12: =H11/3

Sheet Бытовая посуда покупки
A1: Бытовая посуда
A2: Покупки — ссылка на товар и срок службы. Частое — период. Платежи — без ссылки.
A4: № | B4: Наименование | C4: Количество | D4: Ссылка | E4: Стоимость | F4: Срок / период | G4: В год, ₽ | H4: В месяц, ₽
A5: 1 | B5: Графин для воды | C5: 1 | D5: https://leroymerlin.ru/search/?q=%D0%B3%D1%80%D0%B0%D1%84%D0%B8%D0%BD%20%D0%B4%D0%BB%D1%8F%20%D0%B2%D0%BE%D0%B4%D1%8B | E5: 999 | F5: 5 | G5: =IF(ISNUMBER(F5),IF(F5=0,0,E5*IF(C5=0,1,C5)/F5),IF(F5="неделя",E5*IF(C5=0,1,C5)*52,IF(F5="месяц",E5*IF(C5=0,1,C5)*12,E5*IF(C5=0,1,C5)))) | H5: =IF(G5=0,0,G5/12)
A6: 2 | B6: Кассета для фильтра Барьер | C6: 1 | D6: https://barrier.ru/ | E6: 400 | F6: месяц | G6: =IF(ISNUMBER(F6),IF(F6=0,0,E6*IF(C6=0,1,C6)/F6),IF(F6="неделя",E6*IF(C6=0,1,C6)*52,IF(F6="месяц",E6*IF(C6=0,1,C6)*12,E6*IF(C6=0,1,C6)))) | H6: =IF(G6=0,0,G6/12)
A7: 3 | B7: Контейнер для круп | C7: 10 | D7: https://leroymerlin.ru/search/?q=%D0%BA%D0%BE%D0%BD%D1%82%D0%B5%D0%B9%D0%BD%D0%B5%D1%80%20%D0%B4%D0%BB%D1%8F%20%D0%BA%D1%80%D1%83%D0%BF | E7: 199 | F7: 5 | G7: =IF(ISNUMBER(F7),IF(F7=0,0,E7*IF(C7=0,1,C7)/F7),IF(F7="неделя",E7*IF(C7=0,1,C7)*52,IF(F7="месяц",E7*IF(C7=0,1,C7)*12,E7*IF(C7=0,1,C7)))) | H7: =IF(G7=0,0,G7/12)
A8: 4 | B8: Набор кастрюль металлический, 4 шт. | C8: 1 | D8: https://www.dns-shop.ru/search/?q=%D0%BD%D0%B0%D0%B1%D0%BE%D1%80%20%D0%BA%D0%B0%D1%81%D1%82%D1%80%D1%8E%D0%BB%D1%8C%20%D0%BD%D0%B5%D1%80%D0%B6%D0%B0%D0%B2%D0%B5%D1%8E%D1%89%D0%B0%D1%8F | E8: 4999 | F8: 10 | G8: =IF(ISNUMBER(F8),IF(F8=0,0,E8*IF(C8=0,1,C8)/F8),IF(F8="неделя",E8*IF(C8=0,1,C8)*52,IF(F8="месяц",E8*IF(C8=0,1,C8)*12,E8*IF(C8=0,1,C8)))) | H8: =IF(G8=0,0,G8/12)
A9: 5 | B9: Набор кастрюль, 2 шт. | C9: 1 | D9: https://www.dns-shop.ru/search/?q=%D0%BD%D0%B0%D0%B1%D0%BE%D1%80%20%D0%BA%D0%B0%D1%81%D1%82%D1%80%D1%8E%D0%BB%D1%8C | E9: 2499 | F9: 10 | G9: =IF(ISNUMBER(F9),IF(F9=0,0,E9*IF(C9=0,1,C9)/F9),IF(F9="неделя",E9*IF(C9=0,1,C9)*52,IF(F9="месяц",E9*IF(C9=0,1,C9)*12,E9*IF(C9=0,1,C9)))) | H9: =IF(G9=0,0,G9/12)
A10: 6 | B10: Нож столовый | C10: 2 | D10: https://leroymerlin.ru/search/?q=%D0%BD%D0%BE%D0%B6%20%D1%81%D1%82%D0%BE%D0%BB%D0%BE%D0%B2%D1%8B%D0%B9 | E10: 149 | F10: 5 | G10: =IF(ISNUMBER(F10),IF(F10=0,0,E10*IF(C10=0,1,C10)/F10),IF(F10="неделя",E10*IF(C10=0,1,C10)*52,IF(F10="месяц",E10*IF(C10=0,1,C10)*12,E10*IF(C10=0,1,C10)))) | H10: =IF(G10=0,0,G10/12)
A11: 7 | B11: Разделочная доска | C11: 1 | D11: https://leroymerlin.ru/search/?q=%D0%B4%D0%BE%D1%81%D0%BA%D0%B0%20%D1%80%D0%B0%D0%B7%D0%B4%D0%B5%D0%BB%D0%BE%D1%87%D0%BD%D0%B0%D1%8F | E11: 599 | F11: 3 | G11: =IF(ISNUMBER(F11),IF(F11=0,0,E11*IF(C11=0,1,C11)/F11),IF(F11="неделя",E11*IF(C11=0,1,C11)*52,IF(F11="месяц",E11*IF(C11=0,1,C11)*12,E11*IF(C11=0,1,C11)))) | H11: =IF(G11=0,0,G11/12)
A12: 8 | B12: Салатник | C12: 2 | D12: https://leroymerlin.ru/search/?q=%D1%81%D0%B0%D0%BB%D0%B0%D1%82%D0%BD%D0%B8%D0%BA | E12: 399 | F12: 5 | G12: =IF(ISNUMBER(F12),IF(F12=0,0,E12*IF(C12=0,1,C12)/F12),IF(F12="неделя",E12*IF(C12=0,1,C12)*52,IF(F12="месяц",E12*IF(C12=0,1,C12)*12,E12*IF(C12=0,1,C12)))) | H12: =IF(G12=0,0,G12/12)
A13: 9 | B13: Сковорода большая | C13: 1 | D13: https://www.dns-shop.ru/search/?q=%D1%81%D0%BA%D0%BE%D0%B2%D0%BE%D1%80%D0%BE%D0%B4%D0%B0 | E13: 3000 | F13: 5 | G13: =IF(ISNUMBER(F13),IF(F13=0,0,E13*IF(C13=0,1,C13)/F13),IF(F13="неделя",E13*IF(C13=0,1,C13)*52,IF(F13="месяц",E13*IF(C13=0,1,C13)*12,E13*IF(C13=0,1,C13)))) | H13: =IF(G13=0,0,G13/12)
A14: 10 | B14: Столовая ложка | C14: 6 | D14: https://leroymerlin.ru/search/?q=%D0%BB%D0%BE%D0%B6%D0%BA%D0%B0%20%D1%81%D1%82%D0%BE%D0%BB%D0%BE%D0%B2%D0%B0%D1%8F | E14: 59 | F14: 5 | G14: =IF(ISNUMBER(F14),IF(F14=0,0,E14*IF(C14=0,1,C14)/F14),IF(F14="неделя",E14*IF(C14=0,1,C14)*52,IF(F14="месяц",E14*IF(C14=0,1,C14)*12,E14*IF(C14=0,1,C14)))) | H14: =IF(G14=0,0,G14/12)
A15: 11 | B15: Тарелка глубокая | C15: 6 | D15: https://leroymerlin.ru/search/?q=%D1%82%D0%B0%D1%80%D0%B5%D0%BB%D0%BA%D0%B0%20%D0%B3%D0%BB%D1%83%D0%B1%D0%BE%D0%BA%D0%B0%D1%8F | E15: 249 | F15: 5 | G15: =IF(ISNUMBER(F15),IF(F15=0,0,E15*IF(C15=0,1,C15)/F15),IF(F15="неделя",E15*IF(C15=0,1,C15)*52,IF(F15="месяц",E15*IF(C15=0,1,C15)*12,E15*IF(C15=0,1,C15)))) | H15: =IF(G15=0,0,G15/12)
A16: 12 | B16: Тарелка мелкая | C16: 6 | D16: https://leroymerlin.ru/search/?q=%D1%82%D0%B0%D1%80%D0%B5%D0%BB%D0%BA%D0%B0%20%D0%BC%D0%B5%D0%BB%D0%BA%D0%B0%D1%8F | E16: 199 | F16: 5 | G16: =IF(ISNUMBER(F16),IF(F16=0,0,E16*IF(C16=0,1,C16)/F16),IF(F16="неделя",E16*IF(C16=0,1,C16)*52,IF(F16="месяц",E16*IF(C16=0,1,C16)*12,E16*IF(C16=0,1,C16)))) | H16: =IF(G16=0,0,G16/12)
A17: 13 | B17: Тёрка | C17: 1 | D17: https://leroymerlin.ru/search/?q=%D1%82%D0%B5%D1%80%D0%BA%D0%B0 | E17: 399 | F17: 5 | G17: =IF(ISNUMBER(F17),IF(F17=0,0,E17*IF(C17=0,1,C17)/F17),IF(F17="неделя",E17*IF(C17=0,1,C17)*52,IF(F17="месяц",E17*IF(C17=0,1,C17)*12,E17*IF(C17=0,1,C17)))) | H17: =IF(G17=0,0,G17/12)
A18: 14 | B18: Чайная ложка | C18: 6 | D18: https://leroymerlin.ru/search/?q=%D0%BB%D0%BE%D0%B6%D0%BA%D0%B0%20%D1%87%D0%B0%D0%B9%D0%BD%D0%B0%D1%8F | E18: 49 | F18: 5 | G18: =IF(ISNUMBER(F18),IF(F18=0,0,E18*IF(C18=0,1,C18)/F18),IF(F18="неделя",E18*IF(C18=0,1,C18)*52,IF(F18="месяц",E18*IF(C18=0,1,C18)*12,E18*IF(C18=0,1,C18)))) | H18: =IF(G18=0,0,G18/12)
... A20: 16 | B20: Чашка | C20: 6 | D20: https://leroymerlin.ru/search/?q=%D1%87%D0%B0%D1%88%D0%BA%D0%B0 | E20: 199 | F20: 5 | G20: =IF(ISNUMBER(F20),IF(F20=0,0,E20*IF(C20=0,1,C20)/F20),IF(F20="неделя",E20*IF(C20=0,1,C20)*52,IF(F20="месяц",E20*IF(C20=0,1,C20)*12,E20*IF(C20=0,1,C20)))) | H20: =IF(G20=0,0,G20/12)
A22: Итого семья | G22: =G5+G6+G7+G8+G9+G10+G11+G12+G13+G14+G15+G16+G17+G18+G19+G20 | H22: =IF(G22=0,0,G22/12)
A23: Итого на ребёнка (÷3) | G23: =G22/3 | H23: =H22/3

Sheet Бытовая техника покупки
A1: Бытовая техника
A2: Покупки — ссылка на товар и срок службы. Частое — период. Платежи — без ссылки.
A4: № | B4: Наименование | C4: Количество | D4: Ссылка | E4: Стоимость | F4: Срок службы (лет) | G4: В год, ₽ | H4: В месяц, ₽
A5: 1 | B5: Колонка Sony | C5: 1 | D5: https://www.dns-shop.ru/search/?q=%D0%BA%D0%BE%D0%BB%D0%BE%D0%BD%D0%BA%D0%B0%20sony | E5: 2000 | F5: 5 | G5: =IF(ISNUMBER(F5),IF(F5=0,0,E5*IF(C5=0,1,C5)/F5),IF(F5="неделя",E5*IF(C5=0,1,C5)*52,IF(F5="месяц",E5*IF(C5=0,1,C5)*12,E5*IF(C5=0,1,C5)))) | H5: =IF(G5=0,0,G5/12)
A6: 2 | B6: Микроволновка | C6: 1 | D6: https://www.dns-shop.ru/search/?q=%D0%BC%D0%B8%D0%BA%D1%80%D0%BE%D0%B2%D0%BE%D0%BB%D0%BD%D0%BE%D0%B2%D0%BA%D0%B0 | E6: 6999 | F6: 8 | G6: =IF(ISNUMBER(F6),IF(F6=0,0,E6*IF(C6=0,1,C6)/F6),IF(F6="неделя",E6*IF(C6=0,1,C6)*52,IF(F6="месяц",E6*IF(C6=0,1,C6)*12,E6*IF(C6=0,1,C6)))) | H6: =IF(G6=0,0,G6/12)
A7: 3 | B7: Мультиварка | C7: 1 | D7: https://www.dns-shop.ru/search/?q=%D0%BC%D1%83%D0%BB%D1%8C%D1%82%D0%B8%D0%B2%D0%B0%D1%80%D0%BA%D0%B0 | E7: 6999 | F7: 7 | G7: =IF(ISNUMBER(F7),IF(F7=0,0,E7*IF(C7=0,1,C7)/F7),IF(F7="неделя",E7*IF(C7=0,1,C7)*52,IF(F7="месяц",E7*IF(C7=0,1,C7)*12,E7*IF(C7=0,1,C7)))) | H7: =IF(G7=0,0,G7/12)
A8: 4 | B8: Мясорубка | C8: 1 | D8: https://www.dns-shop.ru/search/?q=%D0%BC%D1%8F%D1%81%D0%BE%D1%80%D1%83%D0%B1%D0%BA%D0%B0 | E8: 3999 | F8: 8 | G8: =IF(ISNUMBER(F8),IF(F8=0,0,E8*IF(C8=0,1,C8)/F8),IF(F8="неделя",E8*IF(C8=0,1,C8)*52,IF(F8="месяц",E8*IF(C8=0,1,C8)*12,E8*IF(C8=0,1,C8)))) | H8: =IF(G8=0,0,G8/12)
A9: 5 | B9: Пароварка | C9: 1 | D9: https://www.dns-shop.ru/search/?q=%D0%BF%D0%B0%D1%80%D0%BE%D0%B2%D0%B0%D1%80%D0%BA%D0%B0 | E9: 4499 | F9: 7 | G9: =IF(ISNUMBER(F9),IF(F9=0,0,E9*IF(C9=0,1,C9)/F9),IF(F9="неделя",E9*IF(C9=0,1,C9)*52,IF(F9="месяц",E9*IF(C9=0,1,C9)*12,E9*IF(C9=0,1,C9)))) | H9: =IF(G9=0,0,G9/12)
A10: 6 | B10: Плита газовая | C10: 1 | D10: https://www.dns-shop.ru/search/?q=%D0%BF%D0%BB%D0%B8%D1%82%D0%B0%20%D0%B3%D0%B0%D0%B7%D0%BE%D0%B2%D0%B0%D1%8F | E10: 24999 | F10: 10 | G10: =IF(ISNUMBER(F10),IF(F10=0,0,E10*IF(C10=0,1,C10)/F10),IF(F10="неделя",E10*IF(C10=0,1,C10)*52,IF(F10="месяц",E10*IF(C10=0,1,C10)*12,E10*IF(C10=0,1,C10)))) | H10: =IF(G10=0,0,G10/12)
A11: 7 | B11: Соковыжималка | C11: 1 | D11: https://www.dns-shop.ru/search/?q=%D1%81%D0%BE%D0%BA%D0%BE%D0%B2%D1%8B%D0%B6%D0%B8%D0%BC%D0%B0%D0%BB%D0%BA%D0%B0 | E11: 4999 | F11: 7 | G11: =IF(ISNUMBER(F11),IF(F11=0,0,E11*IF(C11=0,1,C11)/F11),IF(F11="неделя",E11*IF(C11=0,1,C11)*52,IF(F11="месяц",E11*IF(C11=0,1,C11)*12,E11*IF(C11=0,1,C11)))) | H11: =IF(G11=0,0,G11/12)
A12: 8 | B12: Стиральная машина Bosch | C12: 1 | D12: https://www.dns-shop.ru/search/?q=%D1%81%D1%82%D0%B8%D1%80%D0%B0%D0%BB%D1%8C%D0%BD%D0%B0%D1%8F%20%D0%BC%D0%B0%D1%88%D0%B8%D0%BD%D0%B0%20Bosch | E12: 45000 | F12: 8 | G12: =IF(ISNUMBER(F12),IF(F12=0,0,E12*IF(C12=0,1,C12)/F12),IF(F12="неделя",E12*IF(C12=0,1,C12)*52,IF(F12="месяц",E12*IF(C12=0,1,C12)*12,E12*IF(C12=0,1,C12)))) | H12: =IF(G12=0,0,G12/12)
A13: 9 | B13: Телевизор маленький | C13: 1 | D13: https://www.dns-shop.ru/search/?q=%D1%82%D0%B5%D0%BB%D0%B5%D0%B2%D0%B8%D0%B7%D0%BE%D1%80 | E13: 10000 | F13: 7 | G13: =IF(ISNUMBER(F13),IF(F13=0,0,E13*IF(C13=0,1,C13)/F13),IF(F13="неделя",E13*IF(C13=0,1,C13)*52,IF(F13="месяц",E13*IF(C13=0,1,C13)*12,E13*IF(C13=0,1,C13)))) | H13: =IF(G13=0,0,G13/12)
