Workbook
Name FamilySize: '02_Параметры'!$C$6
Name WeeksYear: '02_Параметры'!$C$12
Name MonthsYear: '02_Параметры'!$C$11

Sheet 00_Читать
A1: СЧЁТИКС · калькулятор содержания ребёнка
A2: Сколько стоит содержать одного ребёнка в семье. Обновлено 13 августа 2026.
A4: ИЗ ЧЕГО СОСТОИТ ПРОДУКТ — три файла
A5: Файл | B5: Что это и где живёт
A6: Калькулятор_содержания_ребёнка.xlsx | B6: ЭТА КНИГА. Логика, параметры, каталог, методика. Жёлтое можно менять.
A7: web/calc.html | B7: КАЛЬКУЛЯТОР. Автономный HTML, стили и данные вшиты. Собирается, руками не править.
A8: web/каркас.html + blocks_data.json | B8: ИСТОЧНИК. Вёрстка и цифры. После правки: python3 web/собрать.py
A10: КАК УСТРОЕНА КНИГА — 10 листов
A11: Лист | B11: Назначение
A12: 00_Читать | B12: Этот лист — карта проекта
A13: 01_Глоссарий | B13: Термины: амортизация, доля, минимум, период
A14: 02_Параметры | B14: Члены семьи и константы. ID в колонке A. FamilySize — именованный диапазон
A15: 03_Каталоги | B15: Все позиции одной таблицей. Без строк «Итого» — итог на 05_Сводка через SUMIF
A16: 04_Блоки | B16: Блоки, разделы, упаковки, привязка к частям экрана
A17: 05_Сводка | B17: Суммы по блокам и частям. Формулы SUMIF по каталогу
A18: 06_Методика | B18: Как из цены получается год и месяц. Цепочка расчёта
A19: 07_Тексты | B19: Надписи калькулятора. Колонка «Где» — поверхность
A20: 08_Палитра | B20: Цвета формы. Те же токены, что у калькулятора фотографа
A21: 09_Интерфейс | B21: Какие блоки на экране и в каком порядке
A23: ЦВЕТА ЯЧЕЕК
A24: Цвет | B24: Значение
A25: Жёлтое | B25: Ввод. Цену, количество, срок, период можно менять.
A26: Зелёное | B26: Считается формулой. Не затирать.
A27: Серое | B27: Константа или справочное. Обычно не трогают.

Sheet 01_Глоссарий
A1: 01 · ГЛОССАРИЙ — понятия расчёта
A2: Одни и те же слова на экране, в книге и в методике.
A4: A · МАРКЕРЫ ТИПОВ
A5: Наименование | B5: ID | C5: Тип | D5: Описание
A6: Константа | B6: const | C6: meta | D6: Аксиома. Пользователь не меняет. 12 месяцев, 52 недели.
A7: Значение по умолчанию | B7: default | C7: meta | D7: Предзаполнено, можно изменить. Состав семьи, цены.
A8: Формула | B8: calc | C8: meta | D8: Вычисляется из других величин. Ввод недоступен.
A9: Переключатель | B9: switch | C9: meta | D9: Список: неделя / месяц / год. Меняет ветку расчёта.
A10: B · ДЕНЬГИ И ВРЕМЯ
A11: Наименование | B11: ID | C11: Тип | D11: Описание
A12: Срок службы | B12: years | C12: default | D12: Сколько лет вещь служит. Если заполнено — период не используется.
A13: Период | B13: period | C13: switch | D13: неделя / месяц / год. Сколько раз в год платят, если нет срока службы.
A14: Амортизация | B14: amort | C14: calc | D14: Цена × количество ÷ срок службы. Раскладываем покупку на годы.
A15: Платёж | B15: pay | C15: calc | D15: Цена × количество × (52 | 12 | 1) в зависимости от периода.
A16: Семья в год | B16: family_year | C16: calc | D16: Полная сумма на всю семью за год, до деления.
A17: Доля ребёнка | B17: child_year | C17: calc | D17: Семья в год ÷ членов семьи. Для индивидуальных split = 1.
A18: В месяц | B18: child_month | C18: calc | D18: Год ÷ 12. Чтобы сравнивать разовое и регулярное.
A19: Минимум | B19: direct | C19: calc | D19: Только индивидуальные траты. Без жилья, машины, общего быта.
A20: Полное содержание | B20: grand | C20: calc | D20: Минимум плюс доля в общих расходах семьи.
A21: Членов семьи | B21: family_size | C21: default | D21: На сколько делим общее. По умолчанию 3.
A22: Упаковка | B22: pack | C22: meta | D22: direct / housing / transport / household / trips. Минимум = только direct.

Sheet 02_Параметры
A1: 02 · ПАРАМЕТРЫ — каждая величина объявлена один раз
A2: Жёлтое — ввод. Зелёное — считается. Серое — константа. Формулы пишем через ID.
A4: 1 · СЕМЬЯ
A5: ID | B5: Название | C5: Значение | D5: Ед. | E5: Формула / как получено | F5: Тип | G5: Комментарий
A6: family_size | B6: Членов семьи | C6: 3 | D6: чел | E6: на сколько делим общее | F6: default | G6: Именованный диапазон FamilySize. Каталог ссылается на него.
A8: 2 · КАЛЕНДАРЬ
A9: ID | B9: Название | C9: Значение | D9: Ед. | E9: Формула / как получено | F9: Тип | G9: Комментарий
A10: days_year | B10: Дней в году | C10: 365 | D10: дн | F10: const | G10: календарный год
A11: months | B11: Месяцев в году | C11: 12 | D11: мес | F11: const | G11: перевод года в месяц
A12: weeks_year | B12: Недель в году | C12: 52 | D12: нед | E12: округлено, не 365/7 | F12: const | G12: еженедельные покупки
A13: currency | B13: Валюта | C13: RUB | F13: const | G13: все суммы в рублях

Sheet 03_Каталоги
A1: 03 · КАТАЛОГИ — все позиции одной таблицей
A2: Без строк «Итого». Итог — на 05_Сводка формулой SUMIF. Жёлтое меняйте. Период: неделя / месяц / год.
A4: Блок | B4: Наименование | C4: Кол-во | D4: Цена, ₽ | E4: Срок, лет | F4: Период | G4: Делим на | H4: Ссылка | I4: Тип | J4: Платежей/год | K4: Семья в год, ₽ | L4: Ребёнок в год, ₽ | M4: Ребёнок в месяц, ₽
A5: acc | B5: Бейсболка | C5: 2 | D5: 399 | E5: 2 | G5: 1 | H5: https://www.detmir.ru/search/results/?qt=%D0%B1%D0%B5%D0%B9%D1%81%D0%B1%D0%BE%D0%BB%D0%BA%D0%B0 | I5: amort | J5: =IF(F5="год",1,IF(F5="месяц",MonthsYear,IF(F5="неделя",WeeksYear,0))) | K5: =IF(N(E5)>0,C5*D5/E5,C5*D5*J5) | L5: =IF(G5=0,0,K5/G5) | M5: =IF(L5=0,0,L5/MonthsYear)
A6: acc | B6: Зонт или дождевик | C6: 1 | D6: 699 | E6: 2 | G6: 1 | H6: https://www.detmir.ru/search/results/?qt=%D0%B4%D0%BE%D0%B6%D0%B4%D0%B5%D0%B2%D0%B8%D0%BA%20%D0%B4%D0%B5%D1%82%D1%81%D0%BA%D0%B8%D0%B9 | I6: amort | J6: =IF(F6="год",1,IF(F6="месяц",MonthsYear,IF(F6="неделя",WeeksYear,0))) | K6: =IF(N(E6)>0,C6*D6/E6,C6*D6*J6) | L6: =IF(G6=0,0,K6/G6) | M6: =IF(L6=0,0,L6/MonthsYear)
A7: acc | B7: Перчатки зимние | C7: 1 | D7: 599 | E7: 2 | G7: 1 | H7: https://www.detmir.ru/search/results/?qt=%D0%BF%D0%B5%D1%80%D1%87%D0%B0%D1%82%D0%BA%D0%B8%20%D0%B7%D0%B8%D0%BC%D0%BD%D0%B8%D0%B5 | I7: amort | J7: =IF(F7="год",1,IF(F7="месяц",MonthsYear,IF(F7="неделя",WeeksYear,0))) | K7: =IF(N(E7)>0,C7*D7/E7,C7*D7*J7) | L7: =IF(G7=0,0,K7/G7) | M7: =IF(L7=0,0,L7/MonthsYear)
A8: acc | B8: Перчатки осенние | C8: 1 | D8: 399 | E8: 2 | G8: 1 | H8: https://www.detmir.ru/search/results/?qt=%D0%BF%D0%B5%D1%80%D1%87%D0%B0%D1%82%D0%BA%D0%B8 | I8: amort | J8: =IF(F8="год",1,IF(F8="месяц",MonthsYear,IF(F8="неделя",WeeksYear,0))) | K8: =IF(N(E8)>0,C8*D8/E8,C8*D8*J8) | L8: =IF(G8=0,0,K8/G8) | M8: =IF(L8=0,0,L8/MonthsYear)
A9: acc | B9: Солнечные очки | C9: 1 | D9: 799 | E9: 2 | G9: 1 | H9: https://www.detmir.ru/search/results/?qt=PlayToday%20%D0%BE%D1%87%D0%BA%D0%B8 | I9: amort | J9: =IF(F9="год",1,IF(F9="месяц",MonthsYear,IF(F9="неделя",WeeksYear,0))) | K9: =IF(N(E9)>0,C9*D9/E9,C9*D9*J9) | L9: =IF(G9=0,0,K9/G9) | M9: =IF(L9=0,0,L9/MonthsYear)
A10: acc | B10: Сумка для коньков | C10: 1 | D10: 1100 | E10: 3 | G10: 1 | H10: https://www.detmir.ru/search/results/?qt=%D1%81%D1%83%D0%BC%D0%BA%D0%B0%20%D0%B4%D0%BB%D1%8F%20%D0%BA%D0%BE%D0%BD%D1%8C%D0%BA%D0%BE%D0%B2 | I10: amort | J10: =IF(F10="год",1,IF(F10="месяц",MonthsYear,IF(F10="неделя",WeeksYear,0))) | K10: =IF(N(E10)>0,C10*D10/E10,C10*D10*J10) | L10: =IF(G10=0,0,K10/G10) | M10: =IF(L10=0,0,L10/MonthsYear)
A11: acc | B11: Шапка зимняя | C11: 1 | D11: 699 | E11: 2 | G11: 1 | H11: https://www.detmir.ru/search/results/?qt=%D1%88%D0%B0%D0%BF%D0%BA%D0%B0%20%D0%B7%D0%B8%D0%BC%D0%BD%D1%8F%D1%8F | I11: amort | J11: =IF(F11="год",1,IF(F11="месяц",MonthsYear,IF(F11="неделя",WeeksYear,0))) | K11: =IF(N(E11)>0,C11*D11/E11,C11*D11*J11) | L11: =IF(G11=0,0,K11/G11) | M11: =IF(L11=0,0,L11/MonthsYear)
A12: acc | B12: Шапка осенняя | C12: 1 | D12: 499 | E12: 2 | G12: 1 | H12: https://www.detmir.ru/search/results/?qt=%D1%88%D0%B0%D0%BF%D0%BA%D0%B0%20%D0%BE%D1%81%D0%B5%D0%BD%D0%BD%D1%8F%D1%8F | I12: amort | J12: =IF(F12="год",1,IF(F12="месяц",MonthsYear,IF(F12="неделя",WeeksYear,0))) | K12: =IF(N(E12)>0,C12*D12/E12,C12*D12*J12) | L12: =IF(G12=0,0,K12/G12) | M12: =IF(L12=0,0,L12/MonthsYear)
A13: acc | B13: Шарф | C13: 1 | D13: 399 | E13: 2 | G13: 1 | H13: https://www.detmir.ru/search/results/?qt=%D1%88%D0%B0%D1%80%D1%84 | I13: amort | J13: =IF(F13="год",1,IF(F13="месяц",MonthsYear,IF(F13="неделя",WeeksYear,0))) | K13: =IF(N(E13)>0,C13*D13/E13,C13*D13*J13) | L13: =IF(G13=0,0,K13/G13) | M13: =IF(L13=0,0,L13/MonthsYear)
A14: underwear | B14: Майка | C14: 5 | D14: 399 | E14: 1 | G14: 1 | H14: https://www.detmir.ru/product/index/id/6733145/ | I14: amort | J14: =IF(F14="год",1,IF(F14="месяц",MonthsYear,IF(F14="неделя",WeeksYear,0))) | K14: =IF(N(E14)>0,C14*D14/E14,C14*D14*J14) | L14: =IF(G14=0,0,K14/G14) | M14: =IF(L14=0,0,L14/MonthsYear)
A15: underwear | B15: Носки обычные, набор 5 пар | C15: 1 | D15: 399 | E15: 1 | G15: 1 | H15: https://www.detmir.ru/product/index/id/6550049/ | I15: amort | J15: =IF(F15="год",1,IF(F15="месяц",MonthsYear,IF(F15="неделя",WeeksYear,0))) | K15: =IF(N(E15)>0,C15*D15/E15,C15*D15*J15) | L15: =IF(G15=0,0,K15/G15) | M15: =IF(L15=0,0,L15/MonthsYear)
A16: underwear | B16: Носки утеплённые | C16: 2 | D16: 399 | E16: 1 | G16: 1 | H16: https://www.detmir.ru/search/results/?qt=%D0%BD%D0%BE%D1%81%D0%BA%D0%B8%20%D0%B7%D0%B8%D0%BC%D0%BD%D0%B8%D0%B5%20%D0%B4%D0%B5%D1%82%D1%81%D0%BA%D0%B8%D0%B5 | I16: amort | J16: =IF(F16="год",1,IF(F16="месяц",MonthsYear,IF(F16="неделя",WeeksYear,0))) | K16: =IF(N(E16)>0,C16*D16/E16,C16*D16*J16) | L16: =IF(G16=0,0,K16/G16) | M16: =IF(L16=0,0,L16/MonthsYear)
... A78: personal_buy | B78: Шейкер / бутылка | C78: 1 | D78: 499 | E78: 2 | G78: 1 | H78: https://www.detmir.ru/search/results/?qt=%D0%B1%D1%83%D1%82%D1%8B%D0%BB%D0%BA%D0%B0 | I78: amort | J78: =IF(F78="год",1,IF(F78="месяц",MonthsYear,IF(F78="неделя",WeeksYear,0))) | K78: =IF(N(E78)>0,C78*D78/E78,C78*D78*J78) | L78: =IF(G78=0,0,K78/G78) | M78: =IF(L78=0,0,L78/MonthsYear)
A79: food | B79: Продукты на ребёнка | C79: 1 | D79: 20000 | F79: месяц | G79: 1 | H79: https://magnit.ru/ | I79: pay | J79: =IF(F79="год",1,IF(F79="месяц",MonthsYear,IF(F79="неделя",WeeksYear,0))) | K79: =IF(N(E79)>0,C79*D79/E79,C79*D79*J79) | L79: =IF(G79=0,0,K79/G79) | M79: =IF(L79=0,0,L79/MonthsYear)
A80: sport_buy | B80: Бустер автомобильный | C80: 1 | D80: 1999 | E80: 7 | G80: 1 | H80: https://www.detmir.ru/search/results/?qt=%D0%B1%D1%83%D1%81%D1%82%D0%B5%D1%80%20%D0%B0%D0%B2%D1%82%D0%BE%D0%BC%D0%BE%D0%B1%D0%B8%D0%BB%D1%8C%D0%BD%D1%8B%D0%B9 | I80: amort | J80: =IF(F80="год",1,IF(F80="месяц",MonthsYear,IF(F80="неделя",WeeksYear,0))) | K80: =IF(N(E80)>0,C80*D80/E80,C80*D80*J80) | L80: =IF(G80=0,0,K80/G80) | M80: =IF(L80=0,0,L80/MonthsYear)
A81: sport_buy | B81: Велосипед Stern 24" | C81: 1 | D81: 27999 | E81: 5 | G81: 1 | H81: https://market.yandex.ru/search?text=%D0%B2%D0%B5%D0%BB%D0%BE%D1%81%D0%B8%D0%BF%D0%B5%D0%B4%20Stern%2024 | I81: amort | J81: =IF(F81="год",1,IF(F81="месяц",MonthsYear,IF(F81="неделя",WeeksYear,0))) | K81: =IF(N(E81)>0,C81*D81/E81,C81*D81*J81) | L81: =IF(G81=0,0,K81/G81) | M81: =IF(L81=0,0,L81/MonthsYear)
A82: sport_buy | B82: Гантель | C82: 2 | D82: 365 | E82: 3 | G82: 1 | H82: https://www.detmir.ru/search/results/?qt=%D0%B3%D0%B0%D0%BD%D1%82%D0%B5%D0%BB%D0%B8%20%D0%B4%D0%B5%D1%82%D1%81%D0%BA%D0%B8%D0%B5 | I82: amort | J82: =IF(F82="год",1,IF(F82="месяц",MonthsYear,IF(F82="неделя",WeeksYear,0))) | K82: =IF(N(E82)>0,C82*D82/E82,C82*D82*J82) | L82: =IF(G82=0,0,K82/G82) | M82: =IF(L82=0,0,L82/MonthsYear)
A83: sport_buy | B83: Коньки | C83: 1 | D83: 2999 | E83: 1 | G83: 1 | H83: https://www.detmir.ru/search/results/?qt=%D0%BA%D0%BE%D0%BD%D1%8C%D0%BA%D0%B8 | I83: amort | J83: =IF(F83="год",1,IF(F83="месяц",MonthsYear,IF(F83="неделя",WeeksYear,0))) | K83: =IF(N(E83)>0,C83*D83/E83,C83*D83*J83) | L83: =IF(G83=0,0,K83/G83) | M83: =IF(L83=0,0,L83/MonthsYear)
A84: sport_buy | B84: Мяч футбольный | C84: 1 | D84: 799 | E84: 2 | G84: 1 | H84: https://www.detmir.ru/search/results/?qt=%D0%BC%D1%8F%D1%87%20%D1%84%D1%83%D1%82%D0%B1%D0%BE%D0%BB%D1%8C%D0%BD%D1%8B%D0%B9 | I84: amort | J84: =IF(F84="год",1,IF(F84="месяц",MonthsYear,IF(F84="неделя",WeeksYear,0))) | K84: =IF(N(E84)>0,C84*D84/E84,C84*D84*J84) | L84: =IF(G84=0,0,K84/G84) | M84: =IF(L84=0,0,L84/MonthsYear)
A85: sport_buy | B85: Надувной круг | C85: 1 | D85: 599 | E85: 2 | G85: 1 | H85: https://www.detmir.ru/search/results/?qt=%D0%BD%D0%B0%D0%B4%D1%83%D0%B2%D0%BD%D0%BE%D0%B9%20%D0%BA%D1%80%D1%83%D0%B3 | I85: amort | J85: =IF(F85="год",1,IF(F85="месяц",MonthsYear,IF(F85="неделя",WeeksYear,0))) | K85: =IF(N(E85)>0,C85*D85/E85,C85*D85*J85) | L85: =IF(G85=0,0,K85/G85) | M85: =IF(L85=0,0,L85/MonthsYear)
A86: sport_buy | B86: Скакалка | C86: 1 | D86: 399 | E86: 3 | G86: 1 | H86: https://www.detmir.ru/search/results/?qt=%D1%81%D0%BA%D0%B0%D0%BA%D0%B0%D0%BB%D0%BA%D0%B0 | I86: amort | J86: =IF(F86="год",1,IF(F86="месяц",MonthsYear,IF(F86="неделя",WeeksYear,0))) | K86: =IF(N(E86)>0,C86*D86/E86,C86*D86*J86) | L86: =IF(G86=0,0,K86/G86) | M86: =IF(L86=0,0,L86/MonthsYear)
A87: sport_buy | B87: Стул для кемпинга | C87: 1 | D87: 999 | E87: 5 | G87: 1 | H87: https://leroymerlin.ru/search/?q=%D1%81%D1%82%D1%83%D0%BB%20%D0%BA%D0%B5%D0%BC%D0%BF%D0%B8%D0%BD%D0%B3 | I87: amort | J87: =IF(F87="год",1,IF(F87="месяц",MonthsYear,IF(F87="неделя",WeeksYear,0))) | K87: =IF(N(E87)>0,C87*D87/E87,C87*D87*J87) | L87: =IF(G87=0,0,K87/G87) | M87: =IF(L87=0,0,L87/MonthsYear)
A88: school_ward | B88: Брюки школьные | C88: 2 | D88: 2000 | E88: 2 | G88: 1 | H88: https://www.wildberries.ru/catalog/13454614/detail.aspx | I88: amort | J88: =IF(F88="год",1,IF(F88="месяц",MonthsYear,IF(F88="неделя",WeeksYear,0))) | K88: =IF(N(E88)>0,C88*D88/E88,C88*D88*J88) | L88: =IF(G88=0,0,K88/G88) | M88: =IF(L88=0,0,L88/MonthsYear)
A89: school_ward | B89: Джемпер школьный | C89: 1 | D89: 1399 | E89: 2 | G89: 1 | H89: https://www.detmir.ru/product/index/id/7065088/ | I89: amort | J89: =IF(F89="год",1,IF(F89="месяц",MonthsYear,IF(F89="неделя",WeeksYear,0))) | K89: =IF(N(E89)>0,C89*D89/E89,C89*D89*J89) | L89: =IF(G89=0,0,K89/G89) | M89: =IF(L89=0,0,L89/MonthsYear)
A90: school_ward | B90: Жилет школьный | C90: 1 | D90: 999 | E90: 2 | G90: 1 | H90: https://www.detmir.ru/product/index/id/7065103/ | I90: amort | J90: =IF(F90="год",1,IF(F90="месяц",MonthsYear,IF(F90="неделя",WeeksYear,0))) | K90: =IF(N(E90)>0,C90*D90/E90,C90*D90*J90) | L90: =IF(G90=0,0,K90/G90) | M90: =IF(L90=0,0,L90/MonthsYear)
A91: school_ward | B91: Пиджак | C91: 1 | D91: 2399 | E91: 1 | G91: 1 | H91: https://www.detmir.ru/product/index/id/6643629/ | I91: amort | J91: =IF(F91="год",1,IF(F91="месяц",MonthsYear,IF(F91="неделя",WeeksYear,0))) | K91: =IF(N(E91)>0,C91*D91/E91,C91*D91*J91) | L91: =IF(G91=0,0,K91/G91) | M91: =IF(L91=0,0,L91/MonthsYear)
... A132: school_stuff | B132: Цветная бумага | C132: 1 | D132: 69 | E132: 1 | G132: 1 | H132: https://www.detmir.ru/search/results/?qt=%D1%86%D0%B2%D0%B5%D1%82%D0%BD%D0%B0%D1%8F%20%D0%B1%D1%83%D0%BC%D0%B0%D0%B3%D0%B0 | I132: amort | J132: =IF(F132="год",1,IF(F132="месяц",MonthsYear,IF(F132="неделя",WeeksYear,0))) | K132: =IF(N(E132)>0,C132*D132/E132,C132*D132*J132) | L132: =IF(G132=0,0,K132/G132) | M132: =IF(L132=0,0,L132/MonthsYear)
A133: school_reg | B133: Питание в школе | C133: 1 | D133: 17000 | F133: год | G133: 1 | I133: pay | J133: =IF(F133="год",1,IF(F133="месяц",MonthsYear,IF(F133="неделя",WeeksYear,0))) | K133: =IF(N(E133)>0,C133*D133/E133,C133*D133*J133) | L133: =IF(G133=0,0,K133/G133) | M133: =IF(L133=0,0,L133/MonthsYear)
A134: school_reg | B134: Платный курс (школа) | C134: 1 | D134: 300 | F134: месяц | G134: 1 | I134: pay | J134: =IF(F134="год",1,IF(F134="месяц",MonthsYear,IF(F134="неделя",WeeksYear,0))) | K134: =IF(N(E134)>0,C134*D134/E134,C134*D134*J134) | L134: =IF(G134=0,0,K134/G134) | M134: =IF(L134=0,0,L134/MonthsYear)
A135: school_reg | B135: Взносы в школу | C135: 1 | D135: 3000 | F135: год | G135: 1 | I135: pay | J135: =IF(F135="год",1,IF(F135="месяц",MonthsYear,IF(F135="неделя",WeeksYear,0))) | K135: =IF(N(E135)>0,C135*D135/E135,C135*D135*J135) | L135: =IF(G135=0,0,K135/G135) | M135: =IF(L135=0,0,L135/MonthsYear)
A136: school_add | B136: Букет учителю | C136: 1 | D136: 2000 | E136: 1 | G136: 1 | H136: https://www.detmir.ru/search/results/?qt=%D0%B1%D1%83%D0%BA%D0%B5%D1%82 | I136: pay | J136: =IF(F136="год",1,IF(F136="месяц",MonthsYear,IF(F136="неделя",WeeksYear,0))) | K136: =IF(N(E136)>0,C136*D136/E136,C136*D136*J136) | L136: =IF(G136=0,0,K136/G136) | M136: =IF(L136=0,0,L136/MonthsYear)
A137: school_add | B137: Выпускной | C137: 1 | D137: 10000 | E137: 5 | G137: 1 | I137: pay | J137: =IF(F137="год",1,IF(F137="месяц",MonthsYear,IF(F137="неделя",WeeksYear,0))) | K137: =IF(N(E137)>0,C137*D137/E137,C137*D137*J137) | L137: =IF(G137=0,0,K137/G137) | M137: =IF(L137=0,0,L137/MonthsYear)
A138: school_add | B138: Поездки и мероприятия школы | C138: 12 | D138: 500 | E138: 1 | G138: 1 | I138: pay | J138: =IF(F138="год",1,IF(F138="месяц",MonthsYear,IF(F138="неделя",WeeksYear,0))) | K138: =IF(N(E138)>0,C138*D138/E138,C138*D138*J138) | L138: =IF(G138=0,0,K138/G138) | M138: =IF(L138=0,0,L138/MonthsYear)
A139: extra_buy | B139: Борцовка самбо | C139: 1 | D139: 3690 | E139: 2 | G139: 1 | H139: https://rocky-shop.ru/ekipirovka-dlya-edinoborstv/kurtka-dlya-sambo-green-hill-junior-rostovki-160-190-sm-10032.html | I139: amort | J139: =IF(F139="год",1,IF(F139="месяц",MonthsYear,IF(F139="неделя",WeeksYear,0))) | K139: =IF(N(E139)>0,C139*D139/E139,C139*D139*J139) | L139: =IF(G139=0,0,K139/G139) | M139: =IF(L139=0,0,L139/MonthsYear)
A140: extra_buy | B140: Защита голени | C140: 1 | D140: 2190 | E140: 2 | G140: 1 | H140: https://karate.ru/shop/catalog/407-perchatki-mma-sinie-kozhzamenitel-combat-sambo-green-hill/ | I140: amort | J140: =IF(F140="год",1,IF(F140="месяц",MonthsYear,IF(F140="неделя",WeeksYear,0))) | K140: =IF(N(E140)>0,C140*D140/E140,C140*D140*J140) | L140: =IF(G140=0,0,K140/G140) | M140: =IF(L140=0,0,L140/MonthsYear)
A141: extra_buy | B141: Ласты | C141: 1 | D141: 999 | E141: 2 | G141: 1 | H141: https://www.detmir.ru/search/results/?qt=%D0%BB%D0%B0%D1%81%D1%82%D1%8B%20%D0%B4%D0%B5%D1%82%D1%81%D0%BA%D0%B8%D0%B5 | I141: amort | J141: =IF(F141="год",1,IF(F141="месяц",MonthsYear,IF(F141="неделя",WeeksYear,0))) | K141: =IF(N(E141)>0,C141*D141/E141,C141*D141*J141) | L141: =IF(G141=0,0,K141/G141) | M141: =IF(L141=0,0,L141/MonthsYear)
A142: extra_buy | B142: Перчатки для самбо | C142: 1 | D142: 2990 | E142: 2 | G142: 1 | H142: https://dantesport.ru/product_info.php?products_id=1207 | I142: amort | J142: =IF(F142="год",1,IF(F142="месяц",MonthsYear,IF(F142="неделя",WeeksYear,0))) | K142: =IF(N(E142)>0,C142*D142/E142,C142*D142*J142) | L142: =IF(G142=0,0,K142/G142) | M142: =IF(L142=0,0,L142/MonthsYear)
...

Sheet 04_Блоки
A1: 04 · БЛОКИ — состав экрана
A2: Один блок = одна таблица в калькуляторе. pack=direct входит в минимум.
A4: ID | B4: Название | C4: Раздел | D4: Упаковка | E4: Часть | F4: Школа | G4: Ссылки | H4: Тип строк
A5: acc | B5: Аксессуары | C5: child_buy | D5: direct | E5: wear | G5: да | H5: amort
A6: underwear | B6: Бельё | C6: child_buy | D6: direct | E6: wear | G6: да | H6: amort
A7: outer | B7: Верхняя одежда | C7: child_buy | D7: direct | E7: wear | G7: да | H7: amort
A8: room | B8: Комната | C8: child_buy | D8: direct | E8: home_setup | G8: да | H8: amort
A9: equip | B9: Оборудование | C9: child_buy | D9: direct | E9: home_setup | G9: да | H9: amort
A10: shoes | B10: Обувь | C10: child_buy | D10: direct | E10: wear | G10: да | H10: amort
A11: layer2 | B11: Одежда второго слоя | C11: child_buy | D11: direct | E11: wear | G11: да | H11: amort
A12: personal_buy | B12: Предметы личного пользования | C12: child_buy | D12: direct | E12: other | G12: да | H12: amort
A13: food | B13: Продукты питания | C13: child_buy | D13: direct | E13: other | G13: да | H13: pay
A14: sport_buy | B14: Спорт | C14: child_buy | D14: direct | E14: leisure | G14: да | H14: amort
A15: school_ward | B15: Школа: гардероб | C15: school | D15: direct | E15: school | F15: да | G15: да | H15: amort
A16: school_stuff | B16: Школа: принадлежности | C16: school | D16: direct | E16: school | F16: да | G16: да | H16: amort
A17: school_reg | B17: Школа: регулярные платежи | C17: school | D17: direct | E17: school | F17: да | H17: pay
A18: school_add | B18: Школа: дополнительные расходы | C18: school | D18: direct | E18: school | F18: да | H18: pay
A19: extra_buy | B19: Дополнительное образование: обеспечение | C19: school | D19: direct | E19: school | G19: да | H19: amort
A20: extra_pay | B20: Дополнительное образование: платежи | C20: school | D20: direct | E20: school | G20: да | H20: pay
A21: health_pharm | B21: Лекарства | C21: health | D21: direct | E21: health | G21: да | H21: pay
A22: health_serv | B22: Медицинские услуги | C22: health | D22: direct | E22: health | G22: да | H22: pay
A23: pocket | B23: Карманные | C23: child_pay | D23: direct | E23: other | H23: pay
A24: equip_pay | B24: Связь | C24: child_pay | D24: direct | E24: other | H24: pay
A25: holidays_pay | B25: Праздники | C25: child_pay | D25: direct | E25: leisure | H25: amort
A26: sport_pay | B26: Хобби и развлечения | C26: child_pay | D26: direct | E26: leisure | H26: pay
A27: household_cosmetics | B27: Бытовая косметика | C27: shared_buy | D27: household | E27: shared | G27: да | H27: pay
A28: household_dishes | B28: Бытовая посуда | C28: shared_buy | D28: household | E28: shared | G28: да | H28: amort
A29: household_tech | B29: Бытовая техника | C29: shared_buy | D29: household | E29: shared | G29: да | H29: amort
A30: home_comfort | B30: Мебель и хозяйство | C30: shared_buy | D30: household | E30: shared | G30: да | H30: amort
A31: holidays_buy | B31: Праздники | C31: shared_buy | D31: household | E31: shared | G31: да | H31: amort
A32: home_pay | B32: Содержание жилья | C32: shared_pay | D32: housing | E32: shared | H32: pay
A33: leisure_shared | B33: Отдых и досуг | C33: shared_pay | D33: trips | E33: shared | H33: pay
A34: transport_pay | B34: Транспорт | C34: shared_pay | D34: transport | E34: shared | H34: pay

Sheet 05_Сводка
A1: 05 · СВОДКА — один ребёнок
A2: Все суммы — формулы SUMIF по 03_Каталоги. Правите жёлтое в каталоге, сводка обновится.
A4: БЛОКИ
A5: Блок | B5: ID | C5: Упаковка | D5: Ребёнок в год, ₽ | E5: Ребёнок в месяц, ₽
A6: Аксессуары | B6: acc | C6: direct | D6: =SUMIF('03_Каталоги'!$A$5:$A$230,B6,'03_Каталоги'!$L$5:$L$230) | E6: =IF(D6=0,0,D6/MonthsYear)
A7: Бельё | B7: underwear | C7: direct | D7: =SUMIF('03_Каталоги'!$A$5:$A$230,B7,'03_Каталоги'!$L$5:$L$230) | E7: =IF(D7=0,0,D7/MonthsYear)
A8: Верхняя одежда | B8: outer | C8: direct | D8: =SUMIF('03_Каталоги'!$A$5:$A$230,B8,'03_Каталоги'!$L$5:$L$230) | E8: =IF(D8=0,0,D8/MonthsYear)
A9: Комната | B9: room | C9: direct | D9: =SUMIF('03_Каталоги'!$A$5:$A$230,B9,'03_Каталоги'!$L$5:$L$230) | E9: =IF(D9=0,0,D9/MonthsYear)
A10: Оборудование | B10: equip | C10: direct | D10: =SUMIF('03_Каталоги'!$A$5:$A$230,B10,'03_Каталоги'!$L$5:$L$230) | E10: =IF(D10=0,0,D10/MonthsYear)
A11: Обувь | B11: shoes | C11: direct | D11: =SUMIF('03_Каталоги'!$A$5:$A$230,B11,'03_Каталоги'!$L$5:$L$230) | E11: =IF(D11=0,0,D11/MonthsYear)
A12: Одежда второго слоя | B12: layer2 | C12: direct | D12: =SUMIF('03_Каталоги'!$A$5:$A$230,B12,'03_Каталоги'!$L$5:$L$230) | E12: =IF(D12=0,0,D12/MonthsYear)
A13: Предметы личного пользования | B13: personal_buy | C13: direct | D13: =SUMIF('03_Каталоги'!$A$5:$A$230,B13,'03_Каталоги'!$L$5:$L$230) | E13: =IF(D13=0,0,D13/MonthsYear)
A14: Продукты питания | B14: food | C14: direct | D14: =SUMIF('03_Каталоги'!$A$5:$A$230,B14,'03_Каталоги'!$L$5:$L$230) | E14: =IF(D14=0,0,D14/MonthsYear)
A15: Спорт | B15: sport_buy | C15: direct | D15: =SUMIF('03_Каталоги'!$A$5:$A$230,B15,'03_Каталоги'!$L$5:$L$230) | E15: =IF(D15=0,0,D15/MonthsYear)
A16: Школа: гардероб | B16: school_ward | C16: direct | D16: =SUMIF('03_Каталоги'!$A$5:$A$230,B16,'03_Каталоги'!$L$5:$L$230) | E16: =IF(D16=0,0,D16/MonthsYear)
A17: Школа: принадлежности | B17: school_stuff | C17: direct | D17: =SUMIF('03_Каталоги'!$A$5:$A$230,B17,'03_Каталоги'!$L$5:$L$230) | E17: =IF(D17=0,0,D17/MonthsYear)
... A35: Транспорт | B35: transport_pay | C35: transport | D35: =SUMIF('03_Каталоги'!$A$5:$A$230,B35,'03_Каталоги'!$L$5:$L$230) | E35: =IF(D35=0,0,D35/MonthsYear)
A36: ПОЛНОЕ СОДЕРЖАНИЕ | D36: =SUM(D6:D35) | E36: =SUM(E6:E35)
A38: ЧАСТИ ЭКРАНА
A39: Часть | B39: ID | C39: Состав | D39: Ребёнок в год, ₽ | E39: Ребёнок в месяц, ₽
A40: Образование и школа | B40: school | C40: school_ward; school_stuff; school_reg; school_add; extra_buy; extra_pay | D40: =SUMIF('03_Каталоги'!$A$5:$A$230,"school_ward",'03_Каталоги'!$L$5:$L$230)+SUMIF('03_Каталоги'!$A$5:$A$230,"school_stuff",'03_Каталоги'!$L$5:$L$230)+SUMIF('03_Каталоги'!$A$5:$A$230,"school_reg",'03_Каталоги'!$L$5:$L$230)+SUMIF('03_Каталоги'!$A$5:$A$230,"school_add",'03_Каталоги'!$L$5:$L$230)+SUMIF('03_Каталоги'!$A$5:$A$230,"extra_buy",'03_Каталоги'!$L$5:$L$230)+SUMIF('03_Каталоги'!$A$5:$A$230,"extra_pay",'03_Каталоги'!$L$5:$L$230) | E40: =IF(D40=0,0,D40/MonthsYear)
A41: Гардероб | B41: wear | C41: underwear; layer2; outer; shoes; acc | D41: =SUMIF('03_Каталоги'!$A$5:$A$230,"underwear",'03_Каталоги'!$L$5:$L$230)+SUMIF('03_Каталоги'!$A$5:$A$230,"layer2",'03_Каталоги'!$L$5:$L$230)+SUMIF('03_Каталоги'!$A$5:$A$230,"outer",'03_Каталоги'!$L$5:$L$230)+SUMIF('03_Каталоги'!$A$5:$A$230,"shoes",'03_Каталоги'!$L$5:$L$230)+SUMIF('03_Каталоги'!$A$5:$A$230,"acc",'03_Каталоги'!$L$5:$L$230) | E41: =IF(D41=0,0,D41/MonthsYear)
A42: Обустройство жилья | B42: home_setup | C42: room; equip | D42: =SUMIF('03_Каталоги'!$A$5:$A$230,"room",'03_Каталоги'!$L$5:$L$230)+SUMIF('03_Каталоги'!$A$5:$A$230,"equip",'03_Каталоги'!$L$5:$L$230) | E42: =IF(D42=0,0,D42/MonthsYear)
A43: Здоровье | B43: health | C43: health_pharm; health_serv | D43: =SUMIF('03_Каталоги'!$A$5:$A$230,"health_pharm",'03_Каталоги'!$L$5:$L$230)+SUMIF('03_Каталоги'!$A$5:$A$230,"health_serv",'03_Каталоги'!$L$5:$L$230) | E43: =IF(D43=0,0,D43/MonthsYear)
A44: Отдых и досуг | B44: leisure | C44: sport_buy; sport_pay; holidays_pay | D44: =SUMIF('03_Каталоги'!$A$5:$A$230,"sport_buy",'03_Каталоги'!$L$5:$L$230)+SUMIF('03_Каталоги'!$A$5:$A$230,"sport_pay",'03_Каталоги'!$L$5:$L$230)+SUMIF('03_Каталоги'!$A$5:$A$230,"holidays_pay",'03_Каталоги'!$L$5:$L$230) | E44: =IF(D44=0,0,D44/MonthsYear)
A45: Другие расходы | B45: other | C45: food; personal_buy; pocket; equip_pay | D45: =SUMIF('03_Каталоги'!$A$5:$A$230,"food",'03_Каталоги'!$L$5:$L$230)+SUMIF('03_Каталоги'!$A$5:$A$230,"personal_buy",'03_Каталоги'!$L$5:$L$230)+SUMIF('03_Каталоги'!$A$5:$A$230,"pocket",'03_Каталоги'!$L$5:$L$230)+SUMIF('03_Каталоги'!$A$5:$A$230,"equip_pay",'03_Каталоги'!$L$5:$L$230) | E45: =IF(D45=0,0,D45/MonthsYear)
A46: Общие расходы | B46: shared | C46: household_cosmetics; household_dishes; household_tech; home_comfort; holidays_buy; home_pay; leisure_shared; transport_pay | D46: =SUMIF('03_Каталоги'!$A$5:$A$230,"household_cosmetics",'03_Каталоги'!$L$5:$L$230)+SUMIF('03_Каталоги'!$A$5:$A$230,"household_dishes",'03_Каталоги'!$L$5:$L$230)+SUMIF('03_Каталоги'!$A$5:$A$230,"household_tech",'03_Каталоги'!$L$5:$L$230)+SUMIF('03_Каталоги'!$A$5:$A$230,"home_comfort",'03_Каталоги'!$L$5:$L$230)+SUMIF('03_Каталоги'!$A$5:$A$230,"holidays_buy",'03_Каталоги'!$L$5:$L$230)+SUMIF('03_Каталоги'!$A$5:$A$230,"home_pay",'03_Каталоги'!$L$5:$L$230)+SUMIF('03_Каталоги'!$A$5:$A$230,"leisure_shared",'03_Каталоги'!$L$5:$L$230)+SUMIF('03_Каталоги'!$A$5:$A$230,"transport_pay",'03_Каталоги'!$L$5:$L$230) | E46: =IF(D46=0,0,D46/MonthsYear)
A48: ПРОВЕРКИ
A49: Минимум (pack = direct) | D49: =SUMIF(C6:C35,"direct",D6:D35) | E49: =D49/MonthsYear
A50: Школа за год (флаг school, без кружков) | D50: =SUMIF('03_Каталоги'!$A$5:$A$230,"school_ward",'03_Каталоги'!$L$5:$L$230)+SUMIF('03_Каталоги'!$A$5:$A$230,"school_stuff",'03_Каталоги'!$L$5:$L$230)+SUMIF('03_Каталоги'!$A$5:$A$230,"school_reg",'03_Каталоги'!$L$5:$L$230)+SUMIF('03_Каталоги'!$A$5:$A$230,"school_add",'03_Каталоги'!$L$5:$L$230) | E50: =D50/MonthsYear

Sheet 06_Методика
A1: 06 · МЕТОДИКА — как из цены получается месяц
A2: Одна цепочка. Те же правила в HTML и в формулах каталога.
A4: ШАГИ
A5: Шаг | B5: Что делаем | C5: Формула
A6: 1. Покупка или платёж | B6: Смотрим, заполнен ли срок службы в годах. | C6: years > 0 ?
A7: 2a. Амортизация | B7: Вещь служит несколько лет — раскладываем стоимость. | C7: цена × кол-во ÷ лет
A8: 2b. Платёж | B8: Нет срока — берём период. | C8: неделя × 52, месяц × 12, год × 1
A9: 3. Семья в год | B9: Пока без деления. Это колонка K каталога. | C9: family_year
A10: 4. Доля ребёнка | B10: Индивидуальное не делим. Общее — на FamilySize. | C10: family_year ÷ split
A11: 5. В месяц | B11: Чтобы сравнивать разовое и регулярное. | C11: год ÷ 12
A12: 6. Минимум | B12: Складываем блоки с pack = direct. | C12: SUMIF pack=direct
A13: 7. Полное | B13: Все блоки, включая жильё, транспорт, быт, поездки. | C13: SUM всех child_year
A14: 8. Школа | B14: Только блоки с флагом school. Без кружков и секций. | C14: school_ward + stuff + reg + add
A16: ЧТО НЕ ВХОДИТ
A17: Чужое | B17: Вещи, продукты и одежда только для других членов семьи.
A18: Долги | B18: Платежи по кредитам в расчёт не берутся.

Sheet 07_Тексты
A1: 07 · ТЕКСТЫ — надписи калькулятора
A2: Колонка «Где» — поверхность. Есть автофильтр.
A4: ID | B4: Где | C4: Текст | D4: Комментарий
A5: h1_01 | B5: форма | C5: Сколько стоит содержать ребёнка | D5: заголовок
A6: bt_01 | B6: форма | C6: счетикс | D6: слово знака
A7: bt_02 | B7: форма | C7: твоя юнит-экономика | D7: подпись знака
A8: sub_01 | B8: форма | C8: Калькулятор считает прямые траты на ребёнка и его долю в общих расходах семьи. Цифры можно менять — итог пересчитается сразу. | D8: лид
A9: rlb_01 | B9: форма | C9: Полное содержание одного ребёнка | D9: подпись hero
A10: h2_01 | B10: форма | C10: Куда уходят деньги | D10: карточка 01
A11: hint_01 | B11: форма | C11: Расходы на ребёнка в месяц. Нажмите «+», чтобы раскрыть группу, или название — чтобы перейти к строкам. | D11: подсказка диаграммы
A12: h2_02 | B12: форма | C12: Как мы считаем | D12: карточка 02
A13: how_01 | B13: форма | C13: В расчёте учитываются все расходы на содержание ребёнка — и те, что идут только на него, и его доля в общих тратах семьи. | D13: ввод методики

Sheet 08_Палитра
A1: 08 · ПАЛИТРА — единая со Счётикс
A2: Те же токены, что у калькулятора фотографа. Менять цвет — здесь и в каркасе одновременно.
A4: Токен CSS | B4: HEX | C4: Образец | D4: Где применяется
A5: Нейтральные · текст и линии
A6: --c-ink | B6: #1A1A1A | D6: основной текст
A7: --c-ink2 | B7: #374151 | D7: заголовки таблиц
A8: --c-ink3 | B8: #4B5563 | D8: вторичный текст
A9: --c-gr | B9: #6B7280 | D9: подписи
A10: --c-gr2 | B10: #9CA3AF | D10: мелкие подписи
A11: --c-gr3 | B11: #B6BCC4 | D11: самый светлый текст
A12: --c-ln | B12: #E5E7EB | D12: линии и границы
A13: --c-ln2 | B13: #F0F2F5 | D13: светлые разделители
A14: Нейтральные · фоны
A15: --c-bg | B15: #F5F6F8 | D15: фон страницы
A16: --c-surf | B16: #FAFBFC | D16: фон подложек
A17: --c-white | B17: #FFFFFF | D17: фон карточек
A18: Зелёный · бренд Счётикс
A19: --c-g-50 | B19: #F5FBF7 | D19: самый светлый зелёный фон
A20: --c-g-100 | B20: #EAF6EE | D20: фон зелёных плашек
A21: --c-g-200 | B21: #D8EEDF | D21: рамки
A22: --c-g-300 | B22: #A9DDB8 | D22: сегменты
A23: --c-g-350 | B23: #6FD183 | D23: градиент полоски
A24: --c-g-400 | B24: #4FC26A | D24: градиенты
A25: --c-g-500 | B25: #21A038 | D25: основной зелёный бренда
A26: --c-g-600 | B26: #1B9331 | D26: кнопки
A27: --c-g-700 | B27: #158026 | D27: акцентные цифры
A28: --c-g-800 | B28: #0B6B22 | D28: тёмный градиент hero
A29: --c-g-900 | B29: #14532D | D29: текст на зелёном
A30: Красный · удаление, сброс
A31: --c-r-50 | B31: #FFF6F6 | D31: фон
A32: --c-r-500 | B32: #EF4444 | D32: ошибка
A33: --c-r-700 | B33: #B91C1C | D33: кнопка сброса
A34: Янтарный · ввод в книге
A35: --c-a-50 | B35: #FFFBEF | D35: фон
A36: --c-a-100 | B36: #FEF3D6 | D36: жёлтое = ввод (Excel)
A37: Синий · вторые полоски
A38: --c-b-400 | B38: #5CA8E0 | D38: полоска группы
A39: --c-b-500 | B39: #3B82F6 | D39: акцент

Sheet 09_Интерфейс
A1: 09 · ИНТЕРФЕЙС — что на экране и в каком порядке
A2: Карточки сверху вниз. 01 и 02 — всегда открыты. Части 03+ сворачиваются.
A4: КАРТОЧКИ
A5: № | B5: Карточка | C5: Содержание | D5: Поведение
A6: 01 | B6: Куда уходят деньги | C6: Полоски по группам диаграммы | D6: плюс раскрывает состав группы
A7: 02 | B7: Как мы считаем | C7: Методика, членов семьи, печать и сброс | D7: спойлеры + параметр FamilySize
A8: ЧАСТИ — с 03
A9: № | B9: Часть | C9: Блоки | D9: Заметка
A10: 03 | B10: Образование и школа | C10: school_ward, school_stuff, school_reg, school_add, extra_buy, extra_pay
A11: 04 | B11: Гардероб | C11: underwear, layer2, outer, shoes, acc
A12: 05 | B12: Обустройство жилья | C12: room, equip | D12: Комната ребёнка и техника, которой он пользуется.
A13: 06 | B13: Здоровье | C13: health_pharm, health_serv | D13: Лекарства и медицинские услуги индивидуально для ребёнка.
A14: 07 | B14: Отдых и досуг | C14: sport_buy, sport_pay, holidays_pay
A15: 08 | B15: Другие расходы | C15: food, personal_buy, pocket, equip_pay
A16: 09 | B16: Общие расходы | C16: household_cosmetics, household_dishes, household_tech, home_comfort, holidays_buy, home_pay, leisure_shared, transport_pay | D16: Вещи и платежи на семью. Доля ребёнка — одна треть.
A18: ГРУППЫ ДИАГРАММЫ
A19: ID | B19: Подпись | C19: Блоки
A20: school | B20: Образование и школа | C20: school_ward, school_stuff, school_reg, school_add, extra_buy, extra_pay
A21: wear | B21: Гардероб | C21: underwear, layer2, outer, shoes, acc
A22: home_setup | B22: Обустройство жилья | C22: room, equip
A23: health | B23: Здоровье | C23: health_pharm, health_serv
A24: leisure | B24: Отдых и досуг | C24: sport_buy, sport_pay, holidays_pay
A25: shared | B25: Доля в общих расходах | C25: household_cosmetics, household_dishes, household_tech, home_comfort, holidays_buy, home_pay, leisure_shared, transport_pay
